[2025-07-30 08:08:19,655: INFO: main]: >>>>>> stage Data Ingestion stage started <<<<<<
[2025-07-30 08:08:19,657: INFO: common]: yaml file: config/config.yaml loaded successfully
[2025-07-30 08:08:19,658: INFO: common]: yaml file: params.yaml loaded successfully
[2025-07-30 08:08:19,659: INFO: common]: yaml file: schema.yaml loaded successfully
[2025-07-30 08:08:19,660: INFO: common]: created directory at: artifacts
[2025-07-30 08:08:19,660: INFO: common]: created directory at: artifacts/data_ingestion
[2025-07-30 08:08:19,660: INFO: data_ingestion]: File already exists of size: 23329
[2025-07-30 08:08:19,662: INFO: main]: >>>>>> stage Data Ingestion stage completed <<<<<<

x==========x
[2025-07-30 08:08:19,662: INFO: main]: >>>>>> stage Data Validation stage started <<<<<<
[2025-07-30 08:08:19,663: INFO: common]: yaml file: config/config.yaml loaded successfully
[2025-07-30 08:08:19,663: INFO: common]: yaml file: params.yaml loaded successfully
[2025-07-30 08:08:19,664: INFO: common]: yaml file: schema.yaml loaded successfully
[2025-07-30 08:08:19,664: INFO: common]: created directory at: artifacts
[2025-07-30 08:08:19,664: INFO: common]: created directory at: artifacts/data_validation
[2025-07-30 08:08:19,672: INFO: data_validation]: Data validation status: True
[2025-07-30 08:08:19,672: INFO: main]: >>>>>> stage Data Validation stage completed <<<<<<

x==========x
[2025-07-30 08:11:38,564: INFO: main]: >>>>>> stage Data Ingestion stage started <<<<<<
[2025-07-30 08:11:38,565: INFO: common]: yaml file: config/config.yaml loaded successfully
[2025-07-30 08:11:38,567: INFO: common]: yaml file: params.yaml loaded successfully
[2025-07-30 08:11:38,567: INFO: common]: yaml file: schema.yaml loaded successfully
[2025-07-30 08:11:38,568: INFO: common]: created directory at: artifacts
[2025-07-30 08:11:38,568: INFO: common]: created directory at: artifacts/data_ingestion
[2025-07-30 08:11:38,568: INFO: data_ingestion]: File already exists of size: 23329
[2025-07-30 08:11:38,569: INFO: main]: >>>>>> stage Data Ingestion stage completed <<<<<<

x==========x
[2025-07-30 08:11:38,569: INFO: main]: >>>>>> stage Data Validation stage started <<<<<<
[2025-07-30 08:11:38,570: INFO: common]: yaml file: config/config.yaml loaded successfully
[2025-07-30 08:11:38,570: INFO: common]: yaml file: params.yaml loaded successfully
[2025-07-30 08:11:38,571: INFO: common]: yaml file: schema.yaml loaded successfully
[2025-07-30 08:11:38,571: INFO: common]: created directory at: artifacts
[2025-07-30 08:11:38,571: INFO: common]: created directory at: artifacts/data_validation
[2025-07-30 08:11:38,576: INFO: data_validation]: Data validation status: True
[2025-07-30 08:11:38,577: INFO: main]: >>>>>> stage Data Validation stage completed <<<<<<

x==========x
[2025-07-30 08:11:38,577: INFO: main]: >>>>>> stage Data Transformation stage started <<<<<<
[2025-07-30 08:11:38,577: INFO: common]: yaml file: config/config.yaml loaded successfully
[2025-07-30 08:11:38,578: INFO: common]: yaml file: params.yaml loaded successfully
[2025-07-30 08:11:38,578: INFO: common]: yaml file: schema.yaml loaded successfully
[2025-07-30 08:11:38,578: INFO: common]: created directory at: artifacts
[2025-07-30 08:11:38,579: INFO: common]: created directory at: artifacts/data_transformation
[2025-07-30 08:11:38,579: ERROR: stage_03_data_transformation]: "'ConfigBox' object has no attribute 'data_path'"
Traceback (most recent call last):
  File "box/box.py", line 594, in box.box.Box.__getitem__
KeyError: 'data_path'

The above exception was the direct cause of the following exception:

Traceback (most recent call last):
  File "box/box.py", line 633, in box.box.Box.__getattr__
  File "box/box.py", line 621, in box.box.Box.__getitem__
box.exceptions.BoxKeyError: "'data_path'"

During handling of the above exception, another exception occurred:

Traceback (most recent call last):
  File "box/box.py", line 635, in box.box.Box.__getattr__
AttributeError: 'ConfigBox' object has no attribute 'data_path'

The above exception was the direct cause of the following exception:

Traceback (most recent call last):
  File "box/config_box.py", line 29, in box.config_box.ConfigBox.__getattr__
  File "box/box.py", line 649, in box.box.Box.__getattr__
box.exceptions.BoxKeyError: "'ConfigBox' object has no attribute 'data_path'"

During handling of the above exception, another exception occurred:

Traceback (most recent call last):
  File "box/box.py", line 594, in box.box.Box.__getitem__
KeyError: 'data_path'

The above exception was the direct cause of the following exception:

Traceback (most recent call last):
  File "box/box.py", line 633, in box.box.Box.__getattr__
  File "box/box.py", line 621, in box.box.Box.__getitem__
box.exceptions.BoxKeyError: "'data_path'"

During handling of the above exception, another exception occurred:

Traceback (most recent call last):
  File "box/box.py", line 635, in box.box.Box.__getattr__
AttributeError: 'ConfigBox' object has no attribute 'data_path'

The above exception was the direct cause of the following exception:

Traceback (most recent call last):
  File "/Users/saiaakash/Documents/mlops/DS_main/src/data_science/pipeline/stage_03_data_transformation.py", line 17, in main
    data_transformation_config = config.get_data_transformation_config()
  File "/Users/saiaakash/Documents/mlops/DS_main/src/data_science/config/configuration.py", line 56, in get_data_transformation_config
    data_path=config.data_path
  File "box/config_box.py", line 31, in box.config_box.ConfigBox.__getattr__
  File "box/box.py", line 649, in box.box.Box.__getattr__
box.exceptions.BoxKeyError: "'ConfigBox' object has no attribute 'data_path'"
[2025-07-30 08:11:38,579: ERROR: main]: "'ConfigBox' object has no attribute 'data_path'"
Traceback (most recent call last):
  File "box/box.py", line 594, in box.box.Box.__getitem__
KeyError: 'data_path'

The above exception was the direct cause of the following exception:

Traceback (most recent call last):
  File "box/box.py", line 633, in box.box.Box.__getattr__
  File "box/box.py", line 621, in box.box.Box.__getitem__
box.exceptions.BoxKeyError: "'data_path'"

During handling of the above exception, another exception occurred:

Traceback (most recent call last):
  File "box/box.py", line 635, in box.box.Box.__getattr__
AttributeError: 'ConfigBox' object has no attribute 'data_path'

The above exception was the direct cause of the following exception:

Traceback (most recent call last):
  File "box/config_box.py", line 29, in box.config_box.ConfigBox.__getattr__
  File "box/box.py", line 649, in box.box.Box.__getattr__
box.exceptions.BoxKeyError: "'ConfigBox' object has no attribute 'data_path'"

During handling of the above exception, another exception occurred:

Traceback (most recent call last):
  File "box/box.py", line 594, in box.box.Box.__getitem__
KeyError: 'data_path'

The above exception was the direct cause of the following exception:

Traceback (most recent call last):
  File "box/box.py", line 633, in box.box.Box.__getattr__
  File "box/box.py", line 621, in box.box.Box.__getitem__
box.exceptions.BoxKeyError: "'data_path'"

During handling of the above exception, another exception occurred:

Traceback (most recent call last):
  File "box/box.py", line 635, in box.box.Box.__getattr__
AttributeError: 'ConfigBox' object has no attribute 'data_path'

The above exception was the direct cause of the following exception:

Traceback (most recent call last):
  File "/Users/saiaakash/Documents/mlops/DS_main/main.py", line 12, in run_stage
    pipeline.main()
  File "/Users/saiaakash/Documents/mlops/DS_main/src/data_science/pipeline/stage_03_data_transformation.py", line 24, in main
    raise e
  File "/Users/saiaakash/Documents/mlops/DS_main/src/data_science/pipeline/stage_03_data_transformation.py", line 17, in main
    data_transformation_config = config.get_data_transformation_config()
  File "/Users/saiaakash/Documents/mlops/DS_main/src/data_science/config/configuration.py", line 56, in get_data_transformation_config
    data_path=config.data_path
  File "box/config_box.py", line 31, in box.config_box.ConfigBox.__getattr__
  File "box/box.py", line 649, in box.box.Box.__getattr__
box.exceptions.BoxKeyError: "'ConfigBox' object has no attribute 'data_path'"
[2025-07-30 08:14:09,408: INFO: main]: >>>>>> stage Data Ingestion stage started <<<<<<
[2025-07-30 08:14:09,411: INFO: common]: yaml file: config/config.yaml loaded successfully
[2025-07-30 08:14:09,412: INFO: common]: yaml file: params.yaml loaded successfully
[2025-07-30 08:14:09,413: INFO: common]: yaml file: schema.yaml loaded successfully
[2025-07-30 08:14:09,413: INFO: common]: created directory at: artifacts
[2025-07-30 08:14:09,413: INFO: common]: created directory at: artifacts/data_ingestion
[2025-07-30 08:14:09,413: INFO: data_ingestion]: File already exists of size: 23329
[2025-07-30 08:14:09,415: INFO: main]: >>>>>> stage Data Ingestion stage completed <<<<<<

x==========x
[2025-07-30 08:14:09,415: INFO: main]: >>>>>> stage Data Validation stage started <<<<<<
[2025-07-30 08:14:09,416: INFO: common]: yaml file: config/config.yaml loaded successfully
[2025-07-30 08:14:09,416: INFO: common]: yaml file: params.yaml loaded successfully
[2025-07-30 08:14:09,417: INFO: common]: yaml file: schema.yaml loaded successfully
[2025-07-30 08:14:09,417: INFO: common]: created directory at: artifacts
[2025-07-30 08:14:09,417: INFO: common]: created directory at: artifacts/data_validation
[2025-07-30 08:14:09,425: INFO: data_validation]: Data validation status: True
[2025-07-30 08:14:09,426: INFO: main]: >>>>>> stage Data Validation stage completed <<<<<<

x==========x
[2025-07-30 08:14:09,426: INFO: main]: >>>>>> stage Data Transformation stage started <<<<<<
[2025-07-30 08:14:09,426: INFO: common]: yaml file: config/config.yaml loaded successfully
[2025-07-30 08:14:09,427: INFO: common]: yaml file: params.yaml loaded successfully
[2025-07-30 08:14:09,427: INFO: common]: yaml file: schema.yaml loaded successfully
[2025-07-30 08:14:09,428: INFO: common]: created directory at: artifacts
[2025-07-30 08:14:09,428: INFO: common]: created directory at: artifacts/data_transformation
[2025-07-30 08:14:09,428: ERROR: stage_03_data_transformation]: "'ConfigBox' object has no attribute 'data_path'"
Traceback (most recent call last):
  File "box/box.py", line 594, in box.box.Box.__getitem__
KeyError: 'data_path'

The above exception was the direct cause of the following exception:

Traceback (most recent call last):
  File "box/box.py", line 633, in box.box.Box.__getattr__
  File "box/box.py", line 621, in box.box.Box.__getitem__
box.exceptions.BoxKeyError: "'data_path'"

During handling of the above exception, another exception occurred:

Traceback (most recent call last):
  File "box/box.py", line 635, in box.box.Box.__getattr__
AttributeError: 'ConfigBox' object has no attribute 'data_path'

The above exception was the direct cause of the following exception:

Traceback (most recent call last):
  File "box/config_box.py", line 29, in box.config_box.ConfigBox.__getattr__
  File "box/box.py", line 649, in box.box.Box.__getattr__
box.exceptions.BoxKeyError: "'ConfigBox' object has no attribute 'data_path'"

During handling of the above exception, another exception occurred:

Traceback (most recent call last):
  File "box/box.py", line 594, in box.box.Box.__getitem__
KeyError: 'data_path'

The above exception was the direct cause of the following exception:

Traceback (most recent call last):
  File "box/box.py", line 633, in box.box.Box.__getattr__
  File "box/box.py", line 621, in box.box.Box.__getitem__
box.exceptions.BoxKeyError: "'data_path'"

During handling of the above exception, another exception occurred:

Traceback (most recent call last):
  File "box/box.py", line 635, in box.box.Box.__getattr__
AttributeError: 'ConfigBox' object has no attribute 'data_path'

The above exception was the direct cause of the following exception:

Traceback (most recent call last):
  File "/Users/saiaakash/Documents/mlops/DS_main/src/data_science/pipeline/stage_03_data_transformation.py", line 17, in main
    data_transformation_config = config.get_data_transformation_config()
  File "/Users/saiaakash/Documents/mlops/DS_main/src/data_science/config/configuration.py", line 56, in get_data_transformation_config
    data_path=config.data_path
  File "box/config_box.py", line 31, in box.config_box.ConfigBox.__getattr__
  File "box/box.py", line 649, in box.box.Box.__getattr__
box.exceptions.BoxKeyError: "'ConfigBox' object has no attribute 'data_path'"
[2025-07-30 08:14:09,428: ERROR: main]: "'ConfigBox' object has no attribute 'data_path'"
Traceback (most recent call last):
  File "box/box.py", line 594, in box.box.Box.__getitem__
KeyError: 'data_path'

The above exception was the direct cause of the following exception:

Traceback (most recent call last):
  File "box/box.py", line 633, in box.box.Box.__getattr__
  File "box/box.py", line 621, in box.box.Box.__getitem__
box.exceptions.BoxKeyError: "'data_path'"

During handling of the above exception, another exception occurred:

Traceback (most recent call last):
  File "box/box.py", line 635, in box.box.Box.__getattr__
AttributeError: 'ConfigBox' object has no attribute 'data_path'

The above exception was the direct cause of the following exception:

Traceback (most recent call last):
  File "box/config_box.py", line 29, in box.config_box.ConfigBox.__getattr__
  File "box/box.py", line 649, in box.box.Box.__getattr__
box.exceptions.BoxKeyError: "'ConfigBox' object has no attribute 'data_path'"

During handling of the above exception, another exception occurred:

Traceback (most recent call last):
  File "box/box.py", line 594, in box.box.Box.__getitem__
KeyError: 'data_path'

The above exception was the direct cause of the following exception:

Traceback (most recent call last):
  File "box/box.py", line 633, in box.box.Box.__getattr__
  File "box/box.py", line 621, in box.box.Box.__getitem__
box.exceptions.BoxKeyError: "'data_path'"

During handling of the above exception, another exception occurred:

Traceback (most recent call last):
  File "box/box.py", line 635, in box.box.Box.__getattr__
AttributeError: 'ConfigBox' object has no attribute 'data_path'

The above exception was the direct cause of the following exception:

Traceback (most recent call last):
  File "/Users/saiaakash/Documents/mlops/DS_main/main.py", line 12, in run_stage
    pipeline.main()
  File "/Users/saiaakash/Documents/mlops/DS_main/src/data_science/pipeline/stage_03_data_transformation.py", line 24, in main
    raise e
  File "/Users/saiaakash/Documents/mlops/DS_main/src/data_science/pipeline/stage_03_data_transformation.py", line 17, in main
    data_transformation_config = config.get_data_transformation_config()
  File "/Users/saiaakash/Documents/mlops/DS_main/src/data_science/config/configuration.py", line 56, in get_data_transformation_config
    data_path=config.data_path
  File "box/config_box.py", line 31, in box.config_box.ConfigBox.__getattr__
  File "box/box.py", line 649, in box.box.Box.__getattr__
box.exceptions.BoxKeyError: "'ConfigBox' object has no attribute 'data_path'"
[2025-07-30 08:14:30,381: INFO: main]: >>>>>> stage Data Ingestion stage started <<<<<<
[2025-07-30 08:14:30,382: INFO: common]: yaml file: config/config.yaml loaded successfully
[2025-07-30 08:14:30,384: INFO: common]: yaml file: params.yaml loaded successfully
[2025-07-30 08:14:30,385: INFO: common]: yaml file: schema.yaml loaded successfully
[2025-07-30 08:14:30,385: INFO: common]: created directory at: artifacts
[2025-07-30 08:14:30,385: INFO: common]: created directory at: artifacts/data_ingestion
[2025-07-30 08:14:30,385: INFO: data_ingestion]: File already exists of size: 23329
[2025-07-30 08:14:30,386: INFO: main]: >>>>>> stage Data Ingestion stage completed <<<<<<

x==========x
[2025-07-30 08:14:30,386: INFO: main]: >>>>>> stage Data Validation stage started <<<<<<
[2025-07-30 08:14:30,387: INFO: common]: yaml file: config/config.yaml loaded successfully
[2025-07-30 08:14:30,387: INFO: common]: yaml file: params.yaml loaded successfully
[2025-07-30 08:14:30,388: INFO: common]: yaml file: schema.yaml loaded successfully
[2025-07-30 08:14:30,388: INFO: common]: created directory at: artifacts
[2025-07-30 08:14:30,388: INFO: common]: created directory at: artifacts/data_validation
[2025-07-30 08:14:30,393: INFO: data_validation]: Data validation status: True
[2025-07-30 08:14:30,393: INFO: main]: >>>>>> stage Data Validation stage completed <<<<<<

x==========x
[2025-07-30 08:14:30,393: INFO: main]: >>>>>> stage Data Transformation stage started <<<<<<
[2025-07-30 08:14:30,394: INFO: common]: yaml file: config/config.yaml loaded successfully
[2025-07-30 08:14:30,394: INFO: common]: yaml file: params.yaml loaded successfully
[2025-07-30 08:14:30,395: INFO: common]: yaml file: schema.yaml loaded successfully
[2025-07-30 08:14:30,395: INFO: common]: created directory at: artifacts
[2025-07-30 08:14:30,395: INFO: common]: created directory at: artifacts/data_transformation
[2025-07-30 08:14:30,395: ERROR: stage_03_data_transformation]: "'ConfigBox' object has no attribute 'data_path'"
Traceback (most recent call last):
  File "box/box.py", line 594, in box.box.Box.__getitem__
KeyError: 'data_path'

The above exception was the direct cause of the following exception:

Traceback (most recent call last):
  File "box/box.py", line 633, in box.box.Box.__getattr__
  File "box/box.py", line 621, in box.box.Box.__getitem__
box.exceptions.BoxKeyError: "'data_path'"

During handling of the above exception, another exception occurred:

Traceback (most recent call last):
  File "box/box.py", line 635, in box.box.Box.__getattr__
AttributeError: 'ConfigBox' object has no attribute 'data_path'

The above exception was the direct cause of the following exception:

Traceback (most recent call last):
  File "box/config_box.py", line 29, in box.config_box.ConfigBox.__getattr__
  File "box/box.py", line 649, in box.box.Box.__getattr__
box.exceptions.BoxKeyError: "'ConfigBox' object has no attribute 'data_path'"

During handling of the above exception, another exception occurred:

Traceback (most recent call last):
  File "box/box.py", line 594, in box.box.Box.__getitem__
KeyError: 'data_path'

The above exception was the direct cause of the following exception:

Traceback (most recent call last):
  File "box/box.py", line 633, in box.box.Box.__getattr__
  File "box/box.py", line 621, in box.box.Box.__getitem__
box.exceptions.BoxKeyError: "'data_path'"

During handling of the above exception, another exception occurred:

Traceback (most recent call last):
  File "box/box.py", line 635, in box.box.Box.__getattr__
AttributeError: 'ConfigBox' object has no attribute 'data_path'

The above exception was the direct cause of the following exception:

Traceback (most recent call last):
  File "/Users/saiaakash/Documents/mlops/DS_main/src/data_science/pipeline/stage_03_data_transformation.py", line 17, in main
    data_transformation_config = config.get_data_transformation_config()
  File "/Users/saiaakash/Documents/mlops/DS_main/src/data_science/config/configuration.py", line 56, in get_data_transformation_config
    data_path=config.data_path
  File "box/config_box.py", line 31, in box.config_box.ConfigBox.__getattr__
  File "box/box.py", line 649, in box.box.Box.__getattr__
box.exceptions.BoxKeyError: "'ConfigBox' object has no attribute 'data_path'"
[2025-07-30 08:14:30,395: ERROR: main]: "'ConfigBox' object has no attribute 'data_path'"
Traceback (most recent call last):
  File "box/box.py", line 594, in box.box.Box.__getitem__
KeyError: 'data_path'

The above exception was the direct cause of the following exception:

Traceback (most recent call last):
  File "box/box.py", line 633, in box.box.Box.__getattr__
  File "box/box.py", line 621, in box.box.Box.__getitem__
box.exceptions.BoxKeyError: "'data_path'"

During handling of the above exception, another exception occurred:

Traceback (most recent call last):
  File "box/box.py", line 635, in box.box.Box.__getattr__
AttributeError: 'ConfigBox' object has no attribute 'data_path'

The above exception was the direct cause of the following exception:

Traceback (most recent call last):
  File "box/config_box.py", line 29, in box.config_box.ConfigBox.__getattr__
  File "box/box.py", line 649, in box.box.Box.__getattr__
box.exceptions.BoxKeyError: "'ConfigBox' object has no attribute 'data_path'"

During handling of the above exception, another exception occurred:

Traceback (most recent call last):
  File "box/box.py", line 594, in box.box.Box.__getitem__
KeyError: 'data_path'

The above exception was the direct cause of the following exception:

Traceback (most recent call last):
  File "box/box.py", line 633, in box.box.Box.__getattr__
  File "box/box.py", line 621, in box.box.Box.__getitem__
box.exceptions.BoxKeyError: "'data_path'"

During handling of the above exception, another exception occurred:

Traceback (most recent call last):
  File "box/box.py", line 635, in box.box.Box.__getattr__
AttributeError: 'ConfigBox' object has no attribute 'data_path'

The above exception was the direct cause of the following exception:

Traceback (most recent call last):
  File "/Users/saiaakash/Documents/mlops/DS_main/main.py", line 12, in run_stage
    pipeline.main()
  File "/Users/saiaakash/Documents/mlops/DS_main/src/data_science/pipeline/stage_03_data_transformation.py", line 24, in main
    raise e
  File "/Users/saiaakash/Documents/mlops/DS_main/src/data_science/pipeline/stage_03_data_transformation.py", line 17, in main
    data_transformation_config = config.get_data_transformation_config()
  File "/Users/saiaakash/Documents/mlops/DS_main/src/data_science/config/configuration.py", line 56, in get_data_transformation_config
    data_path=config.data_path
  File "box/config_box.py", line 31, in box.config_box.ConfigBox.__getattr__
  File "box/box.py", line 649, in box.box.Box.__getattr__
box.exceptions.BoxKeyError: "'ConfigBox' object has no attribute 'data_path'"
[2025-07-30 08:15:15,233: INFO: main]: >>>>>> stage Data Ingestion stage started <<<<<<
[2025-07-30 08:15:15,235: INFO: common]: yaml file: config/config.yaml loaded successfully
[2025-07-30 08:15:15,236: INFO: common]: yaml file: params.yaml loaded successfully
[2025-07-30 08:15:15,236: INFO: common]: yaml file: schema.yaml loaded successfully
[2025-07-30 08:15:15,236: INFO: common]: created directory at: artifacts
[2025-07-30 08:15:15,237: INFO: common]: created directory at: artifacts/data_ingestion
[2025-07-30 08:15:15,237: INFO: data_ingestion]: File already exists of size: 23329
[2025-07-30 08:15:15,238: INFO: main]: >>>>>> stage Data Ingestion stage completed <<<<<<

x==========x
[2025-07-30 08:15:15,238: INFO: main]: >>>>>> stage Data Validation stage started <<<<<<
[2025-07-30 08:15:15,238: INFO: common]: yaml file: config/config.yaml loaded successfully
[2025-07-30 08:15:15,239: INFO: common]: yaml file: params.yaml loaded successfully
[2025-07-30 08:15:15,240: INFO: common]: yaml file: schema.yaml loaded successfully
[2025-07-30 08:15:15,240: INFO: common]: created directory at: artifacts
[2025-07-30 08:15:15,240: INFO: common]: created directory at: artifacts/data_validation
[2025-07-30 08:15:15,244: INFO: data_validation]: Data validation status: True
[2025-07-30 08:15:15,244: INFO: main]: >>>>>> stage Data Validation stage completed <<<<<<

x==========x
[2025-07-30 08:15:15,244: INFO: main]: >>>>>> stage Data Transformation stage started <<<<<<
[2025-07-30 08:15:15,245: INFO: common]: yaml file: config/config.yaml loaded successfully
[2025-07-30 08:15:15,245: INFO: common]: yaml file: params.yaml loaded successfully
[2025-07-30 08:15:15,246: INFO: common]: yaml file: schema.yaml loaded successfully
[2025-07-30 08:15:15,246: INFO: common]: created directory at: artifacts
[2025-07-30 08:15:15,246: INFO: common]: created directory at: artifacts/data_transformation
[2025-07-30 08:15:15,246: ERROR: stage_03_data_transformation]: "'ConfigBox' object has no attribute 'data_path'"
Traceback (most recent call last):
  File "box/box.py", line 594, in box.box.Box.__getitem__
KeyError: 'data_path'

The above exception was the direct cause of the following exception:

Traceback (most recent call last):
  File "box/box.py", line 633, in box.box.Box.__getattr__
  File "box/box.py", line 621, in box.box.Box.__getitem__
box.exceptions.BoxKeyError: "'data_path'"

During handling of the above exception, another exception occurred:

Traceback (most recent call last):
  File "box/box.py", line 635, in box.box.Box.__getattr__
AttributeError: 'ConfigBox' object has no attribute 'data_path'

The above exception was the direct cause of the following exception:

Traceback (most recent call last):
  File "box/config_box.py", line 29, in box.config_box.ConfigBox.__getattr__
  File "box/box.py", line 649, in box.box.Box.__getattr__
box.exceptions.BoxKeyError: "'ConfigBox' object has no attribute 'data_path'"

During handling of the above exception, another exception occurred:

Traceback (most recent call last):
  File "box/box.py", line 594, in box.box.Box.__getitem__
KeyError: 'data_path'

The above exception was the direct cause of the following exception:

Traceback (most recent call last):
  File "box/box.py", line 633, in box.box.Box.__getattr__
  File "box/box.py", line 621, in box.box.Box.__getitem__
box.exceptions.BoxKeyError: "'data_path'"

During handling of the above exception, another exception occurred:

Traceback (most recent call last):
  File "box/box.py", line 635, in box.box.Box.__getattr__
AttributeError: 'ConfigBox' object has no attribute 'data_path'

The above exception was the direct cause of the following exception:

Traceback (most recent call last):
  File "/Users/saiaakash/Documents/mlops/DS_main/src/data_science/pipeline/stage_03_data_transformation.py", line 17, in main
    data_transformation_config = config.get_data_transformation_config()
  File "/Users/saiaakash/Documents/mlops/DS_main/src/data_science/config/configuration.py", line 56, in get_data_transformation_config
    data_path=config.data_path
  File "box/config_box.py", line 31, in box.config_box.ConfigBox.__getattr__
  File "box/box.py", line 649, in box.box.Box.__getattr__
box.exceptions.BoxKeyError: "'ConfigBox' object has no attribute 'data_path'"
[2025-07-30 08:15:15,247: ERROR: main]: "'ConfigBox' object has no attribute 'data_path'"
Traceback (most recent call last):
  File "box/box.py", line 594, in box.box.Box.__getitem__
KeyError: 'data_path'

The above exception was the direct cause of the following exception:

Traceback (most recent call last):
  File "box/box.py", line 633, in box.box.Box.__getattr__
  File "box/box.py", line 621, in box.box.Box.__getitem__
box.exceptions.BoxKeyError: "'data_path'"

During handling of the above exception, another exception occurred:

Traceback (most recent call last):
  File "box/box.py", line 635, in box.box.Box.__getattr__
AttributeError: 'ConfigBox' object has no attribute 'data_path'

The above exception was the direct cause of the following exception:

Traceback (most recent call last):
  File "box/config_box.py", line 29, in box.config_box.ConfigBox.__getattr__
  File "box/box.py", line 649, in box.box.Box.__getattr__
box.exceptions.BoxKeyError: "'ConfigBox' object has no attribute 'data_path'"

During handling of the above exception, another exception occurred:

Traceback (most recent call last):
  File "box/box.py", line 594, in box.box.Box.__getitem__
KeyError: 'data_path'

The above exception was the direct cause of the following exception:

Traceback (most recent call last):
  File "box/box.py", line 633, in box.box.Box.__getattr__
  File "box/box.py", line 621, in box.box.Box.__getitem__
box.exceptions.BoxKeyError: "'data_path'"

During handling of the above exception, another exception occurred:

Traceback (most recent call last):
  File "box/box.py", line 635, in box.box.Box.__getattr__
AttributeError: 'ConfigBox' object has no attribute 'data_path'

The above exception was the direct cause of the following exception:

Traceback (most recent call last):
  File "/Users/saiaakash/Documents/mlops/DS_main/main.py", line 12, in run_stage
    pipeline.main()
  File "/Users/saiaakash/Documents/mlops/DS_main/src/data_science/pipeline/stage_03_data_transformation.py", line 24, in main
    raise e
  File "/Users/saiaakash/Documents/mlops/DS_main/src/data_science/pipeline/stage_03_data_transformation.py", line 17, in main
    data_transformation_config = config.get_data_transformation_config()
  File "/Users/saiaakash/Documents/mlops/DS_main/src/data_science/config/configuration.py", line 56, in get_data_transformation_config
    data_path=config.data_path
  File "box/config_box.py", line 31, in box.config_box.ConfigBox.__getattr__
  File "box/box.py", line 649, in box.box.Box.__getattr__
box.exceptions.BoxKeyError: "'ConfigBox' object has no attribute 'data_path'"
[2025-07-30 08:17:33,621: INFO: main]: >>>>>> stage Data Ingestion stage started <<<<<<
[2025-07-30 08:17:33,623: INFO: common]: yaml file: config/config.yaml loaded successfully
[2025-07-30 08:17:33,624: INFO: common]: yaml file: params.yaml loaded successfully
[2025-07-30 08:17:33,625: INFO: common]: yaml file: schema.yaml loaded successfully
[2025-07-30 08:17:33,625: INFO: common]: created directory at: artifacts
[2025-07-30 08:17:33,625: INFO: common]: created directory at: artifacts/data_ingestion
[2025-07-30 08:17:33,625: INFO: data_ingestion]: File already exists of size: 23329
[2025-07-30 08:17:33,626: INFO: main]: >>>>>> stage Data Ingestion stage completed <<<<<<

x==========x
[2025-07-30 08:17:33,626: INFO: main]: >>>>>> stage Data Validation stage started <<<<<<
[2025-07-30 08:17:33,627: INFO: common]: yaml file: config/config.yaml loaded successfully
[2025-07-30 08:17:33,627: INFO: common]: yaml file: params.yaml loaded successfully
[2025-07-30 08:17:33,628: INFO: common]: yaml file: schema.yaml loaded successfully
[2025-07-30 08:17:33,628: INFO: common]: created directory at: artifacts
[2025-07-30 08:17:33,628: INFO: common]: created directory at: artifacts/data_validation
[2025-07-30 08:17:33,634: INFO: data_validation]: Data validation status: True
[2025-07-30 08:17:33,634: INFO: main]: >>>>>> stage Data Validation stage completed <<<<<<

x==========x
[2025-07-30 08:17:33,634: INFO: main]: >>>>>> stage Data Transformation stage started <<<<<<
[2025-07-30 08:17:33,635: INFO: common]: yaml file: config/config.yaml loaded successfully
[2025-07-30 08:17:33,635: INFO: common]: yaml file: params.yaml loaded successfully
[2025-07-30 08:17:33,636: INFO: common]: yaml file: schema.yaml loaded successfully
[2025-07-30 08:17:33,636: INFO: common]: created directory at: artifacts
[2025-07-30 08:17:33,636: INFO: common]: created directory at: artifacts/data_transformation
[2025-07-30 08:17:33,636: ERROR: stage_03_data_transformation]: "'ConfigBox' object has no attribute 'data_path'"
Traceback (most recent call last):
  File "box/box.py", line 594, in box.box.Box.__getitem__
KeyError: 'data_path'

The above exception was the direct cause of the following exception:

Traceback (most recent call last):
  File "box/box.py", line 633, in box.box.Box.__getattr__
  File "box/box.py", line 621, in box.box.Box.__getitem__
box.exceptions.BoxKeyError: "'data_path'"

During handling of the above exception, another exception occurred:

Traceback (most recent call last):
  File "box/box.py", line 635, in box.box.Box.__getattr__
AttributeError: 'ConfigBox' object has no attribute 'data_path'

The above exception was the direct cause of the following exception:

Traceback (most recent call last):
  File "box/config_box.py", line 29, in box.config_box.ConfigBox.__getattr__
  File "box/box.py", line 649, in box.box.Box.__getattr__
box.exceptions.BoxKeyError: "'ConfigBox' object has no attribute 'data_path'"

During handling of the above exception, another exception occurred:

Traceback (most recent call last):
  File "box/box.py", line 594, in box.box.Box.__getitem__
KeyError: 'data_path'

The above exception was the direct cause of the following exception:

Traceback (most recent call last):
  File "box/box.py", line 633, in box.box.Box.__getattr__
  File "box/box.py", line 621, in box.box.Box.__getitem__
box.exceptions.BoxKeyError: "'data_path'"

During handling of the above exception, another exception occurred:

Traceback (most recent call last):
  File "box/box.py", line 635, in box.box.Box.__getattr__
AttributeError: 'ConfigBox' object has no attribute 'data_path'

The above exception was the direct cause of the following exception:

Traceback (most recent call last):
  File "/Users/saiaakash/Documents/mlops/DS_main/src/data_science/pipeline/stage_03_data_transformation.py", line 17, in main
    data_transformation_config = config.get_data_transformation_config()
  File "/Users/saiaakash/Documents/mlops/DS_main/src/data_science/config/configuration.py", line 56, in get_data_transformation_config
    data_path=config.data_path
  File "box/config_box.py", line 31, in box.config_box.ConfigBox.__getattr__
  File "box/box.py", line 649, in box.box.Box.__getattr__
box.exceptions.BoxKeyError: "'ConfigBox' object has no attribute 'data_path'"
[2025-07-30 08:17:33,637: ERROR: main]: "'ConfigBox' object has no attribute 'data_path'"
Traceback (most recent call last):
  File "box/box.py", line 594, in box.box.Box.__getitem__
KeyError: 'data_path'

The above exception was the direct cause of the following exception:

Traceback (most recent call last):
  File "box/box.py", line 633, in box.box.Box.__getattr__
  File "box/box.py", line 621, in box.box.Box.__getitem__
box.exceptions.BoxKeyError: "'data_path'"

During handling of the above exception, another exception occurred:

Traceback (most recent call last):
  File "box/box.py", line 635, in box.box.Box.__getattr__
AttributeError: 'ConfigBox' object has no attribute 'data_path'

The above exception was the direct cause of the following exception:

Traceback (most recent call last):
  File "box/config_box.py", line 29, in box.config_box.ConfigBox.__getattr__
  File "box/box.py", line 649, in box.box.Box.__getattr__
box.exceptions.BoxKeyError: "'ConfigBox' object has no attribute 'data_path'"

During handling of the above exception, another exception occurred:

Traceback (most recent call last):
  File "box/box.py", line 594, in box.box.Box.__getitem__
KeyError: 'data_path'

The above exception was the direct cause of the following exception:

Traceback (most recent call last):
  File "box/box.py", line 633, in box.box.Box.__getattr__
  File "box/box.py", line 621, in box.box.Box.__getitem__
box.exceptions.BoxKeyError: "'data_path'"

During handling of the above exception, another exception occurred:

Traceback (most recent call last):
  File "box/box.py", line 635, in box.box.Box.__getattr__
AttributeError: 'ConfigBox' object has no attribute 'data_path'

The above exception was the direct cause of the following exception:

Traceback (most recent call last):
  File "/Users/saiaakash/Documents/mlops/DS_main/main.py", line 12, in run_stage
    pipeline.main()
  File "/Users/saiaakash/Documents/mlops/DS_main/src/data_science/pipeline/stage_03_data_transformation.py", line 24, in main
    raise e
  File "/Users/saiaakash/Documents/mlops/DS_main/src/data_science/pipeline/stage_03_data_transformation.py", line 17, in main
    data_transformation_config = config.get_data_transformation_config()
  File "/Users/saiaakash/Documents/mlops/DS_main/src/data_science/config/configuration.py", line 56, in get_data_transformation_config
    data_path=config.data_path
  File "box/config_box.py", line 31, in box.config_box.ConfigBox.__getattr__
  File "box/box.py", line 649, in box.box.Box.__getattr__
box.exceptions.BoxKeyError: "'ConfigBox' object has no attribute 'data_path'"
[2025-07-30 08:18:57,177: INFO: main]: >>>>>> stage Data Ingestion stage started <<<<<<
[2025-07-30 08:18:57,178: INFO: common]: yaml file: config/config.yaml loaded successfully
[2025-07-30 08:18:57,179: INFO: common]: yaml file: params.yaml loaded successfully
[2025-07-30 08:18:57,180: INFO: common]: yaml file: schema.yaml loaded successfully
[2025-07-30 08:18:57,180: INFO: common]: created directory at: artifacts
[2025-07-30 08:18:57,180: INFO: common]: created directory at: artifacts/data_ingestion
[2025-07-30 08:18:57,180: INFO: data_ingestion]: File already exists of size: 23329
[2025-07-30 08:18:57,181: INFO: main]: >>>>>> stage Data Ingestion stage completed <<<<<<

x==========x
[2025-07-30 08:18:57,182: INFO: main]: >>>>>> stage Data Validation stage started <<<<<<
[2025-07-30 08:18:57,182: INFO: common]: yaml file: config/config.yaml loaded successfully
[2025-07-30 08:18:57,183: INFO: common]: yaml file: params.yaml loaded successfully
[2025-07-30 08:18:57,183: INFO: common]: yaml file: schema.yaml loaded successfully
[2025-07-30 08:18:57,183: INFO: common]: created directory at: artifacts
[2025-07-30 08:18:57,184: INFO: common]: created directory at: artifacts/data_validation
[2025-07-30 08:18:57,189: INFO: data_validation]: Data validation status: True
[2025-07-30 08:18:57,189: INFO: main]: >>>>>> stage Data Validation stage completed <<<<<<

x==========x
[2025-07-30 08:18:57,189: INFO: main]: >>>>>> stage Data Transformation stage started <<<<<<
[2025-07-30 08:18:57,190: INFO: common]: yaml file: config/config.yaml loaded successfully
[2025-07-30 08:18:57,190: INFO: common]: yaml file: params.yaml loaded successfully
[2025-07-30 08:18:57,191: INFO: common]: yaml file: schema.yaml loaded successfully
[2025-07-30 08:18:57,191: INFO: common]: created directory at: artifacts
[2025-07-30 08:18:57,191: INFO: common]: created directory at: artifacts/data_transformation
[2025-07-30 08:18:57,191: ERROR: stage_03_data_transformation]: DataTransformationConfig.__init__() got an unexpected keyword argument 'data_file'
Traceback (most recent call last):
  File "/Users/saiaakash/Documents/mlops/DS_main/src/data_science/pipeline/stage_03_data_transformation.py", line 17, in main
    data_transformation_config = config.get_data_transformation_config()
  File "/Users/saiaakash/Documents/mlops/DS_main/src/data_science/config/configuration.py", line 54, in get_data_transformation_config
    data_transformation_config = DataTransformationConfig(
TypeError: DataTransformationConfig.__init__() got an unexpected keyword argument 'data_file'
[2025-07-30 08:18:57,191: ERROR: main]: DataTransformationConfig.__init__() got an unexpected keyword argument 'data_file'
Traceback (most recent call last):
  File "/Users/saiaakash/Documents/mlops/DS_main/main.py", line 12, in run_stage
    pipeline.main()
  File "/Users/saiaakash/Documents/mlops/DS_main/src/data_science/pipeline/stage_03_data_transformation.py", line 24, in main
    raise e
  File "/Users/saiaakash/Documents/mlops/DS_main/src/data_science/pipeline/stage_03_data_transformation.py", line 17, in main
    data_transformation_config = config.get_data_transformation_config()
  File "/Users/saiaakash/Documents/mlops/DS_main/src/data_science/config/configuration.py", line 54, in get_data_transformation_config
    data_transformation_config = DataTransformationConfig(
TypeError: DataTransformationConfig.__init__() got an unexpected keyword argument 'data_file'
[2025-07-30 08:26:00,011: INFO: main]: >>>>>> stage Data Ingestion stage started <<<<<<
[2025-07-30 08:26:00,012: INFO: common]: yaml file: config/config.yaml loaded successfully
[2025-07-30 08:26:00,013: INFO: common]: yaml file: params.yaml loaded successfully
[2025-07-30 08:26:00,014: INFO: common]: yaml file: schema.yaml loaded successfully
[2025-07-30 08:26:00,014: INFO: common]: created directory at: artifacts
[2025-07-30 08:26:00,014: INFO: common]: created directory at: artifacts/data_ingestion
[2025-07-30 08:26:00,014: INFO: data_ingestion]: File already exists of size: 23329
[2025-07-30 08:26:00,015: INFO: main]: >>>>>> stage Data Ingestion stage completed <<<<<<

x==========x
[2025-07-30 08:26:00,015: INFO: main]: >>>>>> stage Data Validation stage started <<<<<<
[2025-07-30 08:26:00,016: INFO: common]: yaml file: config/config.yaml loaded successfully
[2025-07-30 08:26:00,016: INFO: common]: yaml file: params.yaml loaded successfully
[2025-07-30 08:26:00,017: INFO: common]: yaml file: schema.yaml loaded successfully
[2025-07-30 08:26:00,017: INFO: common]: created directory at: artifacts
[2025-07-30 08:26:00,017: INFO: common]: created directory at: artifacts/data_validation
[2025-07-30 08:26:00,022: INFO: data_validation]: Data validation status: True
[2025-07-30 08:26:00,022: INFO: main]: >>>>>> stage Data Validation stage completed <<<<<<

x==========x
[2025-07-30 08:26:00,022: INFO: main]: >>>>>> stage Data Transformation stage started <<<<<<
[2025-07-30 08:26:00,023: INFO: common]: yaml file: config/config.yaml loaded successfully
[2025-07-30 08:26:00,024: INFO: common]: yaml file: params.yaml loaded successfully
[2025-07-30 08:26:00,024: INFO: common]: yaml file: schema.yaml loaded successfully
[2025-07-30 08:26:00,025: INFO: common]: created directory at: artifacts
[2025-07-30 08:26:00,025: INFO: common]: created directory at: artifacts/data_transformation
[2025-07-30 08:26:00,025: ERROR: stage_03_data_transformation]: DataTransformationConfig.__init__() got an unexpected keyword argument 'data_file'
Traceback (most recent call last):
  File "/Users/saiaakash/Documents/mlops/DS_main/src/data_science/pipeline/stage_03_data_transformation.py", line 17, in main
    data_transformation_config = config.get_data_transformation_config()
  File "/Users/saiaakash/Documents/mlops/DS_main/src/data_science/config/configuration.py", line 54, in get_data_transformation_config
    data_transformation_config = DataTransformationConfig(
TypeError: DataTransformationConfig.__init__() got an unexpected keyword argument 'data_file'
[2025-07-30 08:26:00,025: ERROR: main]: DataTransformationConfig.__init__() got an unexpected keyword argument 'data_file'
Traceback (most recent call last):
  File "/Users/saiaakash/Documents/mlops/DS_main/main.py", line 12, in run_stage
    pipeline.main()
  File "/Users/saiaakash/Documents/mlops/DS_main/src/data_science/pipeline/stage_03_data_transformation.py", line 24, in main
    raise e
  File "/Users/saiaakash/Documents/mlops/DS_main/src/data_science/pipeline/stage_03_data_transformation.py", line 17, in main
    data_transformation_config = config.get_data_transformation_config()
  File "/Users/saiaakash/Documents/mlops/DS_main/src/data_science/config/configuration.py", line 54, in get_data_transformation_config
    data_transformation_config = DataTransformationConfig(
TypeError: DataTransformationConfig.__init__() got an unexpected keyword argument 'data_file'
[2025-07-30 08:28:40,033: INFO: main]: >>>>>> stage Data Ingestion stage started <<<<<<
[2025-07-30 08:28:40,034: INFO: common]: yaml file: config/config.yaml loaded successfully
[2025-07-30 08:28:40,035: INFO: common]: yaml file: params.yaml loaded successfully
[2025-07-30 08:28:40,036: INFO: common]: yaml file: schema.yaml loaded successfully
[2025-07-30 08:28:40,036: INFO: common]: created directory at: artifacts
[2025-07-30 08:28:40,036: INFO: common]: created directory at: artifacts/data_ingestion
[2025-07-30 08:28:40,036: INFO: data_ingestion]: File already exists of size: 23329
[2025-07-30 08:28:40,038: INFO: main]: >>>>>> stage Data Ingestion stage completed <<<<<<

x==========x
[2025-07-30 08:28:40,038: INFO: main]: >>>>>> stage Data Validation stage started <<<<<<
[2025-07-30 08:28:40,038: INFO: common]: yaml file: config/config.yaml loaded successfully
[2025-07-30 08:28:40,039: INFO: common]: yaml file: params.yaml loaded successfully
[2025-07-30 08:28:40,039: INFO: common]: yaml file: schema.yaml loaded successfully
[2025-07-30 08:28:40,040: INFO: common]: created directory at: artifacts
[2025-07-30 08:28:40,040: INFO: common]: created directory at: artifacts/data_validation
[2025-07-30 08:28:40,046: INFO: data_validation]: Data validation status: True
[2025-07-30 08:28:40,046: INFO: main]: >>>>>> stage Data Validation stage completed <<<<<<

x==========x
[2025-07-30 08:28:40,046: INFO: main]: >>>>>> stage Data Transformation stage started <<<<<<
[2025-07-30 08:28:40,047: INFO: common]: yaml file: config/config.yaml loaded successfully
[2025-07-30 08:28:40,047: INFO: common]: yaml file: params.yaml loaded successfully
[2025-07-30 08:28:40,048: INFO: common]: yaml file: schema.yaml loaded successfully
[2025-07-30 08:28:40,048: INFO: common]: created directory at: artifacts
[2025-07-30 08:28:40,048: INFO: common]: created directory at: artifacts/data_transformation
[2025-07-30 08:28:40,048: ERROR: stage_03_data_transformation]: "'Box' object has no attribute 'data_file'"
Traceback (most recent call last):
  File "box/box.py", line 594, in box.box.Box.__getitem__
KeyError: 'data_file'

The above exception was the direct cause of the following exception:

Traceback (most recent call last):
  File "box/box.py", line 633, in box.box.Box.__getattr__
  File "box/box.py", line 621, in box.box.Box.__getitem__
box.exceptions.BoxKeyError: "'data_file'"

During handling of the above exception, another exception occurred:

Traceback (most recent call last):
  File "box/box.py", line 635, in box.box.Box.__getattr__
AttributeError: 'Box' object has no attribute 'data_file'

The above exception was the direct cause of the following exception:

Traceback (most recent call last):
  File "/Users/saiaakash/Documents/mlops/DS_main/src/data_science/pipeline/stage_03_data_transformation.py", line 17, in main
    data_transformation_config = config.get_data_transformation_config()
  File "/Users/saiaakash/Documents/mlops/DS_main/src/data_science/config/configuration.py", line 56, in get_data_transformation_config
    data_file=config.data_file
  File "box/box.py", line 649, in box.box.Box.__getattr__
box.exceptions.BoxKeyError: "'Box' object has no attribute 'data_file'"
[2025-07-30 08:28:40,049: ERROR: main]: "'Box' object has no attribute 'data_file'"
Traceback (most recent call last):
  File "box/box.py", line 594, in box.box.Box.__getitem__
KeyError: 'data_file'

The above exception was the direct cause of the following exception:

Traceback (most recent call last):
  File "box/box.py", line 633, in box.box.Box.__getattr__
  File "box/box.py", line 621, in box.box.Box.__getitem__
box.exceptions.BoxKeyError: "'data_file'"

During handling of the above exception, another exception occurred:

Traceback (most recent call last):
  File "box/box.py", line 635, in box.box.Box.__getattr__
AttributeError: 'Box' object has no attribute 'data_file'

The above exception was the direct cause of the following exception:

Traceback (most recent call last):
  File "/Users/saiaakash/Documents/mlops/DS_main/main.py", line 12, in run_stage
    pipeline.main()
  File "/Users/saiaakash/Documents/mlops/DS_main/src/data_science/pipeline/stage_03_data_transformation.py", line 24, in main
    raise e
  File "/Users/saiaakash/Documents/mlops/DS_main/src/data_science/pipeline/stage_03_data_transformation.py", line 17, in main
    data_transformation_config = config.get_data_transformation_config()
  File "/Users/saiaakash/Documents/mlops/DS_main/src/data_science/config/configuration.py", line 56, in get_data_transformation_config
    data_file=config.data_file
  File "box/box.py", line 649, in box.box.Box.__getattr__
box.exceptions.BoxKeyError: "'Box' object has no attribute 'data_file'"
[2025-07-30 08:30:06,000: INFO: main]: >>>>>> stage Data Ingestion stage started <<<<<<
[2025-07-30 08:30:06,001: INFO: common]: yaml file: config/config.yaml loaded successfully
[2025-07-30 08:30:06,002: INFO: common]: yaml file: params.yaml loaded successfully
[2025-07-30 08:30:06,003: INFO: common]: yaml file: schema.yaml loaded successfully
[2025-07-30 08:30:06,003: INFO: common]: created directory at: artifacts
[2025-07-30 08:30:06,003: INFO: common]: created directory at: artifacts/data_ingestion
[2025-07-30 08:30:06,003: INFO: data_ingestion]: File already exists of size: 23329
[2025-07-30 08:30:06,005: INFO: main]: >>>>>> stage Data Ingestion stage completed <<<<<<

x==========x
[2025-07-30 08:30:06,005: INFO: main]: >>>>>> stage Data Validation stage started <<<<<<
[2025-07-30 08:30:06,006: INFO: common]: yaml file: config/config.yaml loaded successfully
[2025-07-30 08:30:06,007: INFO: common]: yaml file: params.yaml loaded successfully
[2025-07-30 08:30:06,008: INFO: common]: yaml file: schema.yaml loaded successfully
[2025-07-30 08:30:06,008: INFO: common]: created directory at: artifacts
[2025-07-30 08:30:06,008: INFO: common]: created directory at: artifacts/data_validation
[2025-07-30 08:30:06,012: INFO: data_validation]: Data validation status: True
[2025-07-30 08:30:06,012: INFO: main]: >>>>>> stage Data Validation stage completed <<<<<<

x==========x
[2025-07-30 08:30:06,013: INFO: main]: >>>>>> stage Data Transformation stage started <<<<<<
[2025-07-30 08:30:06,013: INFO: common]: yaml file: config/config.yaml loaded successfully
[2025-07-30 08:30:06,014: INFO: common]: yaml file: params.yaml loaded successfully
[2025-07-30 08:30:06,014: INFO: common]: yaml file: schema.yaml loaded successfully
[2025-07-30 08:30:06,015: INFO: common]: created directory at: artifacts
[2025-07-30 08:30:06,015: INFO: common]: created directory at: artifacts/data_transformation
[2025-07-30 08:30:06,025: INFO: data_transformation]: Splited data into training and test sets
[2025-07-30 08:30:06,025: INFO: data_transformation]: (1279, 12)
[2025-07-30 08:30:06,025: INFO: data_transformation]: (320, 12)
[2025-07-30 08:30:06,026: INFO: main]: >>>>>> stage Data Transformation stage completed <<<<<<

x==========x
[2025-07-30 08:54:08,408: INFO: main]: >>>>>> stage Data Ingestion stage started <<<<<<
[2025-07-30 08:54:08,411: INFO: common]: yaml file: config/config.yaml loaded successfully
[2025-07-30 08:54:08,412: INFO: common]: yaml file: params.yaml loaded successfully
[2025-07-30 08:54:08,413: INFO: common]: yaml file: schema.yaml loaded successfully
[2025-07-30 08:54:08,413: INFO: common]: created directory at: artifacts
[2025-07-30 08:54:08,413: INFO: common]: created directory at: artifacts/data_ingestion
[2025-07-30 08:54:08,413: INFO: data_ingestion]: File already exists of size: 23329
[2025-07-30 08:54:08,415: INFO: main]: >>>>>> stage Data Ingestion stage completed <<<<<<

x==========x
[2025-07-30 08:54:08,415: INFO: main]: >>>>>> stage Data Validation stage started <<<<<<
[2025-07-30 08:54:08,416: INFO: common]: yaml file: config/config.yaml loaded successfully
[2025-07-30 08:54:08,416: INFO: common]: yaml file: params.yaml loaded successfully
[2025-07-30 08:54:08,417: INFO: common]: yaml file: schema.yaml loaded successfully
[2025-07-30 08:54:08,418: INFO: common]: created directory at: artifacts
[2025-07-30 08:54:08,418: INFO: common]: created directory at: artifacts/data_validation
[2025-07-30 08:54:08,425: INFO: data_validation]: Data validation status: True
[2025-07-30 08:54:08,425: INFO: main]: >>>>>> stage Data Validation stage completed <<<<<<

x==========x
[2025-07-30 08:54:08,425: INFO: main]: >>>>>> stage Data Transformation stage started <<<<<<
[2025-07-30 08:54:08,427: INFO: common]: yaml file: config/config.yaml loaded successfully
[2025-07-30 08:54:08,427: INFO: common]: yaml file: params.yaml loaded successfully
[2025-07-30 08:54:08,428: INFO: common]: yaml file: schema.yaml loaded successfully
[2025-07-30 08:54:08,428: INFO: common]: created directory at: artifacts
[2025-07-30 08:54:08,428: INFO: common]: created directory at: artifacts/data_validation
[2025-07-30 08:54:08,428: INFO: common]: created directory at: artifacts/data_transformation
[2025-07-30 08:54:08,442: INFO: data_transformation]: Splited data into training and test sets
[2025-07-30 08:54:08,442: INFO: data_transformation]: (1279, 12)
[2025-07-30 08:54:08,443: INFO: data_transformation]: (320, 12)
[2025-07-30 08:54:08,443: INFO: main]: >>>>>> stage Data Transformation stage completed <<<<<<

x==========x
[2025-07-30 08:54:08,443: INFO: main]: >>>>>> stage Model Trainer stage started <<<<<<
[2025-07-30 08:54:08,444: INFO: common]: yaml file: config/config.yaml loaded successfully
[2025-07-30 08:54:08,444: INFO: common]: yaml file: params.yaml loaded successfully
[2025-07-30 08:54:08,445: INFO: common]: yaml file: schema.yaml loaded successfully
[2025-07-30 08:54:08,445: INFO: common]: created directory at: artifacts
[2025-07-30 08:54:08,445: INFO: common]: created directory at: artifacts/model_trainer
[2025-07-30 08:54:08,454: INFO: model_trainer]: Model saved to model.joblib in artifacts/model_trainer
[2025-07-30 08:54:08,455: INFO: main]: >>>>>> stage Model Trainer stage completed <<<<<<

x==========x
