[2025-07-30 08:08:19,655: INFO: main]: >>>>>> stage Data Ingestion stage started <<<<<<
[2025-07-30 08:08:19,657: INFO: common]: yaml file: config/config.yaml loaded successfully
[2025-07-30 08:08:19,658: INFO: common]: yaml file: params.yaml loaded successfully
[2025-07-30 08:08:19,659: INFO: common]: yaml file: schema.yaml loaded successfully
[2025-07-30 08:08:19,660: INFO: common]: created directory at: artifacts
[2025-07-30 08:08:19,660: INFO: common]: created directory at: artifacts/data_ingestion
[2025-07-30 08:08:19,660: INFO: data_ingestion]: File already exists of size: 23329
[2025-07-30 08:08:19,662: INFO: main]: >>>>>> stage Data Ingestion stage completed <<<<<<

x==========x
[2025-07-30 08:08:19,662: INFO: main]: >>>>>> stage Data Validation stage started <<<<<<
[2025-07-30 08:08:19,663: INFO: common]: yaml file: config/config.yaml loaded successfully
[2025-07-30 08:08:19,663: INFO: common]: yaml file: params.yaml loaded successfully
[2025-07-30 08:08:19,664: INFO: common]: yaml file: schema.yaml loaded successfully
[2025-07-30 08:08:19,664: INFO: common]: created directory at: artifacts
[2025-07-30 08:08:19,664: INFO: common]: created directory at: artifacts/data_validation
[2025-07-30 08:08:19,672: INFO: data_validation]: Data validation status: True
[2025-07-30 08:08:19,672: INFO: main]: >>>>>> stage Data Validation stage completed <<<<<<

x==========x
[2025-07-30 08:11:38,564: INFO: main]: >>>>>> stage Data Ingestion stage started <<<<<<
[2025-07-30 08:11:38,565: INFO: common]: yaml file: config/config.yaml loaded successfully
[2025-07-30 08:11:38,567: INFO: common]: yaml file: params.yaml loaded successfully
[2025-07-30 08:11:38,567: INFO: common]: yaml file: schema.yaml loaded successfully
[2025-07-30 08:11:38,568: INFO: common]: created directory at: artifacts
[2025-07-30 08:11:38,568: INFO: common]: created directory at: artifacts/data_ingestion
[2025-07-30 08:11:38,568: INFO: data_ingestion]: File already exists of size: 23329
[2025-07-30 08:11:38,569: INFO: main]: >>>>>> stage Data Ingestion stage completed <<<<<<

x==========x
[2025-07-30 08:11:38,569: INFO: main]: >>>>>> stage Data Validation stage started <<<<<<
[2025-07-30 08:11:38,570: INFO: common]: yaml file: config/config.yaml loaded successfully
[2025-07-30 08:11:38,570: INFO: common]: yaml file: params.yaml loaded successfully
[2025-07-30 08:11:38,571: INFO: common]: yaml file: schema.yaml loaded successfully
[2025-07-30 08:11:38,571: INFO: common]: created directory at: artifacts
[2025-07-30 08:11:38,571: INFO: common]: created directory at: artifacts/data_validation
[2025-07-30 08:11:38,576: INFO: data_validation]: Data validation status: True
[2025-07-30 08:11:38,577: INFO: main]: >>>>>> stage Data Validation stage completed <<<<<<

x==========x
[2025-07-30 08:11:38,577: INFO: main]: >>>>>> stage Data Transformation stage started <<<<<<
[2025-07-30 08:11:38,577: INFO: common]: yaml file: config/config.yaml loaded successfully
[2025-07-30 08:11:38,578: INFO: common]: yaml file: params.yaml loaded successfully
[2025-07-30 08:11:38,578: INFO: common]: yaml file: schema.yaml loaded successfully
[2025-07-30 08:11:38,578: INFO: common]: created directory at: artifacts
[2025-07-30 08:11:38,579: INFO: common]: created directory at: artifacts/data_transformation
[2025-07-30 08:11:38,579: ERROR: stage_03_data_transformation]: "'ConfigBox' object has no attribute 'data_path'"
Traceback (most recent call last):
  File "box/box.py", line 594, in box.box.Box.__getitem__
KeyError: 'data_path'

The above exception was the direct cause of the following exception:

Traceback (most recent call last):
  File "box/box.py", line 633, in box.box.Box.__getattr__
  File "box/box.py", line 621, in box.box.Box.__getitem__
box.exceptions.BoxKeyError: "'data_path'"

During handling of the above exception, another exception occurred:

Traceback (most recent call last):
  File "box/box.py", line 635, in box.box.Box.__getattr__
AttributeError: 'ConfigBox' object has no attribute 'data_path'

The above exception was the direct cause of the following exception:

Traceback (most recent call last):
  File "box/config_box.py", line 29, in box.config_box.ConfigBox.__getattr__
  File "box/box.py", line 649, in box.box.Box.__getattr__
box.exceptions.BoxKeyError: "'ConfigBox' object has no attribute 'data_path'"

During handling of the above exception, another exception occurred:

Traceback (most recent call last):
  File "box/box.py", line 594, in box.box.Box.__getitem__
KeyError: 'data_path'

The above exception was the direct cause of the following exception:

Traceback (most recent call last):
  File "box/box.py", line 633, in box.box.Box.__getattr__
  File "box/box.py", line 621, in box.box.Box.__getitem__
box.exceptions.BoxKeyError: "'data_path'"

During handling of the above exception, another exception occurred:

Traceback (most recent call last):
  File "box/box.py", line 635, in box.box.Box.__getattr__
AttributeError: 'ConfigBox' object has no attribute 'data_path'

The above exception was the direct cause of the following exception:

Traceback (most recent call last):
  File "/Users/saiaakash/Documents/mlops/DS_main/src/data_science/pipeline/stage_03_data_transformation.py", line 17, in main
    data_transformation_config = config.get_data_transformation_config()
  File "/Users/saiaakash/Documents/mlops/DS_main/src/data_science/config/configuration.py", line 56, in get_data_transformation_config
    data_path=config.data_path
  File "box/config_box.py", line 31, in box.config_box.ConfigBox.__getattr__
  File "box/box.py", line 649, in box.box.Box.__getattr__
box.exceptions.BoxKeyError: "'ConfigBox' object has no attribute 'data_path'"
[2025-07-30 08:11:38,579: ERROR: main]: "'ConfigBox' object has no attribute 'data_path'"
Traceback (most recent call last):
  File "box/box.py", line 594, in box.box.Box.__getitem__
KeyError: 'data_path'

The above exception was the direct cause of the following exception:

Traceback (most recent call last):
  File "box/box.py", line 633, in box.box.Box.__getattr__
  File "box/box.py", line 621, in box.box.Box.__getitem__
box.exceptions.BoxKeyError: "'data_path'"

During handling of the above exception, another exception occurred:

Traceback (most recent call last):
  File "box/box.py", line 635, in box.box.Box.__getattr__
AttributeError: 'ConfigBox' object has no attribute 'data_path'

The above exception was the direct cause of the following exception:

Traceback (most recent call last):
  File "box/config_box.py", line 29, in box.config_box.ConfigBox.__getattr__
  File "box/box.py", line 649, in box.box.Box.__getattr__
box.exceptions.BoxKeyError: "'ConfigBox' object has no attribute 'data_path'"

During handling of the above exception, another exception occurred:

Traceback (most recent call last):
  File "box/box.py", line 594, in box.box.Box.__getitem__
KeyError: 'data_path'

The above exception was the direct cause of the following exception:

Traceback (most recent call last):
  File "box/box.py", line 633, in box.box.Box.__getattr__
  File "box/box.py", line 621, in box.box.Box.__getitem__
box.exceptions.BoxKeyError: "'data_path'"

During handling of the above exception, another exception occurred:

Traceback (most recent call last):
  File "box/box.py", line 635, in box.box.Box.__getattr__
AttributeError: 'ConfigBox' object has no attribute 'data_path'

The above exception was the direct cause of the following exception:

Traceback (most recent call last):
  File "/Users/saiaakash/Documents/mlops/DS_main/main.py", line 12, in run_stage
    pipeline.main()
  File "/Users/saiaakash/Documents/mlops/DS_main/src/data_science/pipeline/stage_03_data_transformation.py", line 24, in main
    raise e
  File "/Users/saiaakash/Documents/mlops/DS_main/src/data_science/pipeline/stage_03_data_transformation.py", line 17, in main
    data_transformation_config = config.get_data_transformation_config()
  File "/Users/saiaakash/Documents/mlops/DS_main/src/data_science/config/configuration.py", line 56, in get_data_transformation_config
    data_path=config.data_path
  File "box/config_box.py", line 31, in box.config_box.ConfigBox.__getattr__
  File "box/box.py", line 649, in box.box.Box.__getattr__
box.exceptions.BoxKeyError: "'ConfigBox' object has no attribute 'data_path'"
[2025-07-30 08:14:09,408: INFO: main]: >>>>>> stage Data Ingestion stage started <<<<<<
[2025-07-30 08:14:09,411: INFO: common]: yaml file: config/config.yaml loaded successfully
[2025-07-30 08:14:09,412: INFO: common]: yaml file: params.yaml loaded successfully
[2025-07-30 08:14:09,413: INFO: common]: yaml file: schema.yaml loaded successfully
[2025-07-30 08:14:09,413: INFO: common]: created directory at: artifacts
[2025-07-30 08:14:09,413: INFO: common]: created directory at: artifacts/data_ingestion
[2025-07-30 08:14:09,413: INFO: data_ingestion]: File already exists of size: 23329
[2025-07-30 08:14:09,415: INFO: main]: >>>>>> stage Data Ingestion stage completed <<<<<<

x==========x
[2025-07-30 08:14:09,415: INFO: main]: >>>>>> stage Data Validation stage started <<<<<<
[2025-07-30 08:14:09,416: INFO: common]: yaml file: config/config.yaml loaded successfully
[2025-07-30 08:14:09,416: INFO: common]: yaml file: params.yaml loaded successfully
[2025-07-30 08:14:09,417: INFO: common]: yaml file: schema.yaml loaded successfully
[2025-07-30 08:14:09,417: INFO: common]: created directory at: artifacts
[2025-07-30 08:14:09,417: INFO: common]: created directory at: artifacts/data_validation
[2025-07-30 08:14:09,425: INFO: data_validation]: Data validation status: True
[2025-07-30 08:14:09,426: INFO: main]: >>>>>> stage Data Validation stage completed <<<<<<

x==========x
[2025-07-30 08:14:09,426: INFO: main]: >>>>>> stage Data Transformation stage started <<<<<<
[2025-07-30 08:14:09,426: INFO: common]: yaml file: config/config.yaml loaded successfully
[2025-07-30 08:14:09,427: INFO: common]: yaml file: params.yaml loaded successfully
[2025-07-30 08:14:09,427: INFO: common]: yaml file: schema.yaml loaded successfully
[2025-07-30 08:14:09,428: INFO: common]: created directory at: artifacts
[2025-07-30 08:14:09,428: INFO: common]: created directory at: artifacts/data_transformation
[2025-07-30 08:14:09,428: ERROR: stage_03_data_transformation]: "'ConfigBox' object has no attribute 'data_path'"
Traceback (most recent call last):
  File "box/box.py", line 594, in box.box.Box.__getitem__
KeyError: 'data_path'

The above exception was the direct cause of the following exception:

Traceback (most recent call last):
  File "box/box.py", line 633, in box.box.Box.__getattr__
  File "box/box.py", line 621, in box.box.Box.__getitem__
box.exceptions.BoxKeyError: "'data_path'"

During handling of the above exception, another exception occurred:

Traceback (most recent call last):
  File "box/box.py", line 635, in box.box.Box.__getattr__
AttributeError: 'ConfigBox' object has no attribute 'data_path'

The above exception was the direct cause of the following exception:

Traceback (most recent call last):
  File "box/config_box.py", line 29, in box.config_box.ConfigBox.__getattr__
  File "box/box.py", line 649, in box.box.Box.__getattr__
box.exceptions.BoxKeyError: "'ConfigBox' object has no attribute 'data_path'"

During handling of the above exception, another exception occurred:

Traceback (most recent call last):
  File "box/box.py", line 594, in box.box.Box.__getitem__
KeyError: 'data_path'

The above exception was the direct cause of the following exception:

Traceback (most recent call last):
  File "box/box.py", line 633, in box.box.Box.__getattr__
  File "box/box.py", line 621, in box.box.Box.__getitem__
box.exceptions.BoxKeyError: "'data_path'"

During handling of the above exception, another exception occurred:

Traceback (most recent call last):
  File "box/box.py", line 635, in box.box.Box.__getattr__
AttributeError: 'ConfigBox' object has no attribute 'data_path'

The above exception was the direct cause of the following exception:

Traceback (most recent call last):
  File "/Users/saiaakash/Documents/mlops/DS_main/src/data_science/pipeline/stage_03_data_transformation.py", line 17, in main
    data_transformation_config = config.get_data_transformation_config()
  File "/Users/saiaakash/Documents/mlops/DS_main/src/data_science/config/configuration.py", line 56, in get_data_transformation_config
    data_path=config.data_path
  File "box/config_box.py", line 31, in box.config_box.ConfigBox.__getattr__
  File "box/box.py", line 649, in box.box.Box.__getattr__
box.exceptions.BoxKeyError: "'ConfigBox' object has no attribute 'data_path'"
[2025-07-30 08:14:09,428: ERROR: main]: "'ConfigBox' object has no attribute 'data_path'"
Traceback (most recent call last):
  File "box/box.py", line 594, in box.box.Box.__getitem__
KeyError: 'data_path'

The above exception was the direct cause of the following exception:

Traceback (most recent call last):
  File "box/box.py", line 633, in box.box.Box.__getattr__
  File "box/box.py", line 621, in box.box.Box.__getitem__
box.exceptions.BoxKeyError: "'data_path'"

During handling of the above exception, another exception occurred:

Traceback (most recent call last):
  File "box/box.py", line 635, in box.box.Box.__getattr__
AttributeError: 'ConfigBox' object has no attribute 'data_path'

The above exception was the direct cause of the following exception:

Traceback (most recent call last):
  File "box/config_box.py", line 29, in box.config_box.ConfigBox.__getattr__
  File "box/box.py", line 649, in box.box.Box.__getattr__
box.exceptions.BoxKeyError: "'ConfigBox' object has no attribute 'data_path'"

During handling of the above exception, another exception occurred:

Traceback (most recent call last):
  File "box/box.py", line 594, in box.box.Box.__getitem__
KeyError: 'data_path'

The above exception was the direct cause of the following exception:

Traceback (most recent call last):
  File "box/box.py", line 633, in box.box.Box.__getattr__
  File "box/box.py", line 621, in box.box.Box.__getitem__
box.exceptions.BoxKeyError: "'data_path'"

During handling of the above exception, another exception occurred:

Traceback (most recent call last):
  File "box/box.py", line 635, in box.box.Box.__getattr__
AttributeError: 'ConfigBox' object has no attribute 'data_path'

The above exception was the direct cause of the following exception:

Traceback (most recent call last):
  File "/Users/saiaakash/Documents/mlops/DS_main/main.py", line 12, in run_stage
    pipeline.main()
  File "/Users/saiaakash/Documents/mlops/DS_main/src/data_science/pipeline/stage_03_data_transformation.py", line 24, in main
    raise e
  File "/Users/saiaakash/Documents/mlops/DS_main/src/data_science/pipeline/stage_03_data_transformation.py", line 17, in main
    data_transformation_config = config.get_data_transformation_config()
  File "/Users/saiaakash/Documents/mlops/DS_main/src/data_science/config/configuration.py", line 56, in get_data_transformation_config
    data_path=config.data_path
  File "box/config_box.py", line 31, in box.config_box.ConfigBox.__getattr__
  File "box/box.py", line 649, in box.box.Box.__getattr__
box.exceptions.BoxKeyError: "'ConfigBox' object has no attribute 'data_path'"
[2025-07-30 08:14:30,381: INFO: main]: >>>>>> stage Data Ingestion stage started <<<<<<
[2025-07-30 08:14:30,382: INFO: common]: yaml file: config/config.yaml loaded successfully
[2025-07-30 08:14:30,384: INFO: common]: yaml file: params.yaml loaded successfully
[2025-07-30 08:14:30,385: INFO: common]: yaml file: schema.yaml loaded successfully
[2025-07-30 08:14:30,385: INFO: common]: created directory at: artifacts
[2025-07-30 08:14:30,385: INFO: common]: created directory at: artifacts/data_ingestion
[2025-07-30 08:14:30,385: INFO: data_ingestion]: File already exists of size: 23329
[2025-07-30 08:14:30,386: INFO: main]: >>>>>> stage Data Ingestion stage completed <<<<<<

x==========x
[2025-07-30 08:14:30,386: INFO: main]: >>>>>> stage Data Validation stage started <<<<<<
[2025-07-30 08:14:30,387: INFO: common]: yaml file: config/config.yaml loaded successfully
[2025-07-30 08:14:30,387: INFO: common]: yaml file: params.yaml loaded successfully
[2025-07-30 08:14:30,388: INFO: common]: yaml file: schema.yaml loaded successfully
[2025-07-30 08:14:30,388: INFO: common]: created directory at: artifacts
[2025-07-30 08:14:30,388: INFO: common]: created directory at: artifacts/data_validation
[2025-07-30 08:14:30,393: INFO: data_validation]: Data validation status: True
[2025-07-30 08:14:30,393: INFO: main]: >>>>>> stage Data Validation stage completed <<<<<<

x==========x
[2025-07-30 08:14:30,393: INFO: main]: >>>>>> stage Data Transformation stage started <<<<<<
[2025-07-30 08:14:30,394: INFO: common]: yaml file: config/config.yaml loaded successfully
[2025-07-30 08:14:30,394: INFO: common]: yaml file: params.yaml loaded successfully
[2025-07-30 08:14:30,395: INFO: common]: yaml file: schema.yaml loaded successfully
[2025-07-30 08:14:30,395: INFO: common]: created directory at: artifacts
[2025-07-30 08:14:30,395: INFO: common]: created directory at: artifacts/data_transformation
[2025-07-30 08:14:30,395: ERROR: stage_03_data_transformation]: "'ConfigBox' object has no attribute 'data_path'"
Traceback (most recent call last):
  File "box/box.py", line 594, in box.box.Box.__getitem__
KeyError: 'data_path'

The above exception was the direct cause of the following exception:

Traceback (most recent call last):
  File "box/box.py", line 633, in box.box.Box.__getattr__
  File "box/box.py", line 621, in box.box.Box.__getitem__
box.exceptions.BoxKeyError: "'data_path'"

During handling of the above exception, another exception occurred:

Traceback (most recent call last):
  File "box/box.py", line 635, in box.box.Box.__getattr__
AttributeError: 'ConfigBox' object has no attribute 'data_path'

The above exception was the direct cause of the following exception:

Traceback (most recent call last):
  File "box/config_box.py", line 29, in box.config_box.ConfigBox.__getattr__
  File "box/box.py", line 649, in box.box.Box.__getattr__
box.exceptions.BoxKeyError: "'ConfigBox' object has no attribute 'data_path'"

During handling of the above exception, another exception occurred:

Traceback (most recent call last):
  File "box/box.py", line 594, in box.box.Box.__getitem__
KeyError: 'data_path'

The above exception was the direct cause of the following exception:

Traceback (most recent call last):
  File "box/box.py", line 633, in box.box.Box.__getattr__
  File "box/box.py", line 621, in box.box.Box.__getitem__
box.exceptions.BoxKeyError: "'data_path'"

During handling of the above exception, another exception occurred:

Traceback (most recent call last):
  File "box/box.py", line 635, in box.box.Box.__getattr__
AttributeError: 'ConfigBox' object has no attribute 'data_path'

The above exception was the direct cause of the following exception:

Traceback (most recent call last):
  File "/Users/saiaakash/Documents/mlops/DS_main/src/data_science/pipeline/stage_03_data_transformation.py", line 17, in main
    data_transformation_config = config.get_data_transformation_config()
  File "/Users/saiaakash/Documents/mlops/DS_main/src/data_science/config/configuration.py", line 56, in get_data_transformation_config
    data_path=config.data_path
  File "box/config_box.py", line 31, in box.config_box.ConfigBox.__getattr__
  File "box/box.py", line 649, in box.box.Box.__getattr__
box.exceptions.BoxKeyError: "'ConfigBox' object has no attribute 'data_path'"
[2025-07-30 08:14:30,395: ERROR: main]: "'ConfigBox' object has no attribute 'data_path'"
Traceback (most recent call last):
  File "box/box.py", line 594, in box.box.Box.__getitem__
KeyError: 'data_path'

The above exception was the direct cause of the following exception:

Traceback (most recent call last):
  File "box/box.py", line 633, in box.box.Box.__getattr__
  File "box/box.py", line 621, in box.box.Box.__getitem__
box.exceptions.BoxKeyError: "'data_path'"

During handling of the above exception, another exception occurred:

Traceback (most recent call last):
  File "box/box.py", line 635, in box.box.Box.__getattr__
AttributeError: 'ConfigBox' object has no attribute 'data_path'

The above exception was the direct cause of the following exception:

Traceback (most recent call last):
  File "box/config_box.py", line 29, in box.config_box.ConfigBox.__getattr__
  File "box/box.py", line 649, in box.box.Box.__getattr__
box.exceptions.BoxKeyError: "'ConfigBox' object has no attribute 'data_path'"

During handling of the above exception, another exception occurred:

Traceback (most recent call last):
  File "box/box.py", line 594, in box.box.Box.__getitem__
KeyError: 'data_path'

The above exception was the direct cause of the following exception:

Traceback (most recent call last):
  File "box/box.py", line 633, in box.box.Box.__getattr__
  File "box/box.py", line 621, in box.box.Box.__getitem__
box.exceptions.BoxKeyError: "'data_path'"

During handling of the above exception, another exception occurred:

Traceback (most recent call last):
  File "box/box.py", line 635, in box.box.Box.__getattr__
AttributeError: 'ConfigBox' object has no attribute 'data_path'

The above exception was the direct cause of the following exception:

Traceback (most recent call last):
  File "/Users/saiaakash/Documents/mlops/DS_main/main.py", line 12, in run_stage
    pipeline.main()
  File "/Users/saiaakash/Documents/mlops/DS_main/src/data_science/pipeline/stage_03_data_transformation.py", line 24, in main
    raise e
  File "/Users/saiaakash/Documents/mlops/DS_main/src/data_science/pipeline/stage_03_data_transformation.py", line 17, in main
    data_transformation_config = config.get_data_transformation_config()
  File "/Users/saiaakash/Documents/mlops/DS_main/src/data_science/config/configuration.py", line 56, in get_data_transformation_config
    data_path=config.data_path
  File "box/config_box.py", line 31, in box.config_box.ConfigBox.__getattr__
  File "box/box.py", line 649, in box.box.Box.__getattr__
box.exceptions.BoxKeyError: "'ConfigBox' object has no attribute 'data_path'"
[2025-07-30 08:15:15,233: INFO: main]: >>>>>> stage Data Ingestion stage started <<<<<<
[2025-07-30 08:15:15,235: INFO: common]: yaml file: config/config.yaml loaded successfully
[2025-07-30 08:15:15,236: INFO: common]: yaml file: params.yaml loaded successfully
[2025-07-30 08:15:15,236: INFO: common]: yaml file: schema.yaml loaded successfully
[2025-07-30 08:15:15,236: INFO: common]: created directory at: artifacts
[2025-07-30 08:15:15,237: INFO: common]: created directory at: artifacts/data_ingestion
[2025-07-30 08:15:15,237: INFO: data_ingestion]: File already exists of size: 23329
[2025-07-30 08:15:15,238: INFO: main]: >>>>>> stage Data Ingestion stage completed <<<<<<

x==========x
[2025-07-30 08:15:15,238: INFO: main]: >>>>>> stage Data Validation stage started <<<<<<
[2025-07-30 08:15:15,238: INFO: common]: yaml file: config/config.yaml loaded successfully
[2025-07-30 08:15:15,239: INFO: common]: yaml file: params.yaml loaded successfully
[2025-07-30 08:15:15,240: INFO: common]: yaml file: schema.yaml loaded successfully
[2025-07-30 08:15:15,240: INFO: common]: created directory at: artifacts
[2025-07-30 08:15:15,240: INFO: common]: created directory at: artifacts/data_validation
[2025-07-30 08:15:15,244: INFO: data_validation]: Data validation status: True
[2025-07-30 08:15:15,244: INFO: main]: >>>>>> stage Data Validation stage completed <<<<<<

x==========x
[2025-07-30 08:15:15,244: INFO: main]: >>>>>> stage Data Transformation stage started <<<<<<
[2025-07-30 08:15:15,245: INFO: common]: yaml file: config/config.yaml loaded successfully
[2025-07-30 08:15:15,245: INFO: common]: yaml file: params.yaml loaded successfully
[2025-07-30 08:15:15,246: INFO: common]: yaml file: schema.yaml loaded successfully
[2025-07-30 08:15:15,246: INFO: common]: created directory at: artifacts
[2025-07-30 08:15:15,246: INFO: common]: created directory at: artifacts/data_transformation
[2025-07-30 08:15:15,246: ERROR: stage_03_data_transformation]: "'ConfigBox' object has no attribute 'data_path'"
Traceback (most recent call last):
  File "box/box.py", line 594, in box.box.Box.__getitem__
KeyError: 'data_path'

The above exception was the direct cause of the following exception:

Traceback (most recent call last):
  File "box/box.py", line 633, in box.box.Box.__getattr__
  File "box/box.py", line 621, in box.box.Box.__getitem__
box.exceptions.BoxKeyError: "'data_path'"

During handling of the above exception, another exception occurred:

Traceback (most recent call last):
  File "box/box.py", line 635, in box.box.Box.__getattr__
AttributeError: 'ConfigBox' object has no attribute 'data_path'

The above exception was the direct cause of the following exception:

Traceback (most recent call last):
  File "box/config_box.py", line 29, in box.config_box.ConfigBox.__getattr__
  File "box/box.py", line 649, in box.box.Box.__getattr__
box.exceptions.BoxKeyError: "'ConfigBox' object has no attribute 'data_path'"

During handling of the above exception, another exception occurred:

Traceback (most recent call last):
  File "box/box.py", line 594, in box.box.Box.__getitem__
KeyError: 'data_path'

The above exception was the direct cause of the following exception:

Traceback (most recent call last):
  File "box/box.py", line 633, in box.box.Box.__getattr__
  File "box/box.py", line 621, in box.box.Box.__getitem__
box.exceptions.BoxKeyError: "'data_path'"

During handling of the above exception, another exception occurred:

Traceback (most recent call last):
  File "box/box.py", line 635, in box.box.Box.__getattr__
AttributeError: 'ConfigBox' object has no attribute 'data_path'

The above exception was the direct cause of the following exception:

Traceback (most recent call last):
  File "/Users/saiaakash/Documents/mlops/DS_main/src/data_science/pipeline/stage_03_data_transformation.py", line 17, in main
    data_transformation_config = config.get_data_transformation_config()
  File "/Users/saiaakash/Documents/mlops/DS_main/src/data_science/config/configuration.py", line 56, in get_data_transformation_config
    data_path=config.data_path
  File "box/config_box.py", line 31, in box.config_box.ConfigBox.__getattr__
  File "box/box.py", line 649, in box.box.Box.__getattr__
box.exceptions.BoxKeyError: "'ConfigBox' object has no attribute 'data_path'"
[2025-07-30 08:15:15,247: ERROR: main]: "'ConfigBox' object has no attribute 'data_path'"
Traceback (most recent call last):
  File "box/box.py", line 594, in box.box.Box.__getitem__
KeyError: 'data_path'

The above exception was the direct cause of the following exception:

Traceback (most recent call last):
  File "box/box.py", line 633, in box.box.Box.__getattr__
  File "box/box.py", line 621, in box.box.Box.__getitem__
box.exceptions.BoxKeyError: "'data_path'"

During handling of the above exception, another exception occurred:

Traceback (most recent call last):
  File "box/box.py", line 635, in box.box.Box.__getattr__
AttributeError: 'ConfigBox' object has no attribute 'data_path'

The above exception was the direct cause of the following exception:

Traceback (most recent call last):
  File "box/config_box.py", line 29, in box.config_box.ConfigBox.__getattr__
  File "box/box.py", line 649, in box.box.Box.__getattr__
box.exceptions.BoxKeyError: "'ConfigBox' object has no attribute 'data_path'"

During handling of the above exception, another exception occurred:

Traceback (most recent call last):
  File "box/box.py", line 594, in box.box.Box.__getitem__
KeyError: 'data_path'

The above exception was the direct cause of the following exception:

Traceback (most recent call last):
  File "box/box.py", line 633, in box.box.Box.__getattr__
  File "box/box.py", line 621, in box.box.Box.__getitem__
box.exceptions.BoxKeyError: "'data_path'"

During handling of the above exception, another exception occurred:

Traceback (most recent call last):
  File "box/box.py", line 635, in box.box.Box.__getattr__
AttributeError: 'ConfigBox' object has no attribute 'data_path'

The above exception was the direct cause of the following exception:

Traceback (most recent call last):
  File "/Users/saiaakash/Documents/mlops/DS_main/main.py", line 12, in run_stage
    pipeline.main()
  File "/Users/saiaakash/Documents/mlops/DS_main/src/data_science/pipeline/stage_03_data_transformation.py", line 24, in main
    raise e
  File "/Users/saiaakash/Documents/mlops/DS_main/src/data_science/pipeline/stage_03_data_transformation.py", line 17, in main
    data_transformation_config = config.get_data_transformation_config()
  File "/Users/saiaakash/Documents/mlops/DS_main/src/data_science/config/configuration.py", line 56, in get_data_transformation_config
    data_path=config.data_path
  File "box/config_box.py", line 31, in box.config_box.ConfigBox.__getattr__
  File "box/box.py", line 649, in box.box.Box.__getattr__
box.exceptions.BoxKeyError: "'ConfigBox' object has no attribute 'data_path'"
[2025-07-30 08:17:33,621: INFO: main]: >>>>>> stage Data Ingestion stage started <<<<<<
[2025-07-30 08:17:33,623: INFO: common]: yaml file: config/config.yaml loaded successfully
[2025-07-30 08:17:33,624: INFO: common]: yaml file: params.yaml loaded successfully
[2025-07-30 08:17:33,625: INFO: common]: yaml file: schema.yaml loaded successfully
[2025-07-30 08:17:33,625: INFO: common]: created directory at: artifacts
[2025-07-30 08:17:33,625: INFO: common]: created directory at: artifacts/data_ingestion
[2025-07-30 08:17:33,625: INFO: data_ingestion]: File already exists of size: 23329
[2025-07-30 08:17:33,626: INFO: main]: >>>>>> stage Data Ingestion stage completed <<<<<<

x==========x
[2025-07-30 08:17:33,626: INFO: main]: >>>>>> stage Data Validation stage started <<<<<<
[2025-07-30 08:17:33,627: INFO: common]: yaml file: config/config.yaml loaded successfully
[2025-07-30 08:17:33,627: INFO: common]: yaml file: params.yaml loaded successfully
[2025-07-30 08:17:33,628: INFO: common]: yaml file: schema.yaml loaded successfully
[2025-07-30 08:17:33,628: INFO: common]: created directory at: artifacts
[2025-07-30 08:17:33,628: INFO: common]: created directory at: artifacts/data_validation
[2025-07-30 08:17:33,634: INFO: data_validation]: Data validation status: True
[2025-07-30 08:17:33,634: INFO: main]: >>>>>> stage Data Validation stage completed <<<<<<

x==========x
[2025-07-30 08:17:33,634: INFO: main]: >>>>>> stage Data Transformation stage started <<<<<<
[2025-07-30 08:17:33,635: INFO: common]: yaml file: config/config.yaml loaded successfully
[2025-07-30 08:17:33,635: INFO: common]: yaml file: params.yaml loaded successfully
[2025-07-30 08:17:33,636: INFO: common]: yaml file: schema.yaml loaded successfully
[2025-07-30 08:17:33,636: INFO: common]: created directory at: artifacts
[2025-07-30 08:17:33,636: INFO: common]: created directory at: artifacts/data_transformation
[2025-07-30 08:17:33,636: ERROR: stage_03_data_transformation]: "'ConfigBox' object has no attribute 'data_path'"
Traceback (most recent call last):
  File "box/box.py", line 594, in box.box.Box.__getitem__
KeyError: 'data_path'

The above exception was the direct cause of the following exception:

Traceback (most recent call last):
  File "box/box.py", line 633, in box.box.Box.__getattr__
  File "box/box.py", line 621, in box.box.Box.__getitem__
box.exceptions.BoxKeyError: "'data_path'"

During handling of the above exception, another exception occurred:

Traceback (most recent call last):
  File "box/box.py", line 635, in box.box.Box.__getattr__
AttributeError: 'ConfigBox' object has no attribute 'data_path'

The above exception was the direct cause of the following exception:

Traceback (most recent call last):
  File "box/config_box.py", line 29, in box.config_box.ConfigBox.__getattr__
  File "box/box.py", line 649, in box.box.Box.__getattr__
box.exceptions.BoxKeyError: "'ConfigBox' object has no attribute 'data_path'"

During handling of the above exception, another exception occurred:

Traceback (most recent call last):
  File "box/box.py", line 594, in box.box.Box.__getitem__
KeyError: 'data_path'

The above exception was the direct cause of the following exception:

Traceback (most recent call last):
  File "box/box.py", line 633, in box.box.Box.__getattr__
  File "box/box.py", line 621, in box.box.Box.__getitem__
box.exceptions.BoxKeyError: "'data_path'"

During handling of the above exception, another exception occurred:

Traceback (most recent call last):
  File "box/box.py", line 635, in box.box.Box.__getattr__
AttributeError: 'ConfigBox' object has no attribute 'data_path'

The above exception was the direct cause of the following exception:

Traceback (most recent call last):
  File "/Users/saiaakash/Documents/mlops/DS_main/src/data_science/pipeline/stage_03_data_transformation.py", line 17, in main
    data_transformation_config = config.get_data_transformation_config()
  File "/Users/saiaakash/Documents/mlops/DS_main/src/data_science/config/configuration.py", line 56, in get_data_transformation_config
    data_path=config.data_path
  File "box/config_box.py", line 31, in box.config_box.ConfigBox.__getattr__
  File "box/box.py", line 649, in box.box.Box.__getattr__
box.exceptions.BoxKeyError: "'ConfigBox' object has no attribute 'data_path'"
[2025-07-30 08:17:33,637: ERROR: main]: "'ConfigBox' object has no attribute 'data_path'"
Traceback (most recent call last):
  File "box/box.py", line 594, in box.box.Box.__getitem__
KeyError: 'data_path'

The above exception was the direct cause of the following exception:

Traceback (most recent call last):
  File "box/box.py", line 633, in box.box.Box.__getattr__
  File "box/box.py", line 621, in box.box.Box.__getitem__
box.exceptions.BoxKeyError: "'data_path'"

During handling of the above exception, another exception occurred:

Traceback (most recent call last):
  File "box/box.py", line 635, in box.box.Box.__getattr__
AttributeError: 'ConfigBox' object has no attribute 'data_path'

The above exception was the direct cause of the following exception:

Traceback (most recent call last):
  File "box/config_box.py", line 29, in box.config_box.ConfigBox.__getattr__
  File "box/box.py", line 649, in box.box.Box.__getattr__
box.exceptions.BoxKeyError: "'ConfigBox' object has no attribute 'data_path'"

During handling of the above exception, another exception occurred:

Traceback (most recent call last):
  File "box/box.py", line 594, in box.box.Box.__getitem__
KeyError: 'data_path'

The above exception was the direct cause of the following exception:

Traceback (most recent call last):
  File "box/box.py", line 633, in box.box.Box.__getattr__
  File "box/box.py", line 621, in box.box.Box.__getitem__
box.exceptions.BoxKeyError: "'data_path'"

During handling of the above exception, another exception occurred:

Traceback (most recent call last):
  File "box/box.py", line 635, in box.box.Box.__getattr__
AttributeError: 'ConfigBox' object has no attribute 'data_path'

The above exception was the direct cause of the following exception:

Traceback (most recent call last):
  File "/Users/saiaakash/Documents/mlops/DS_main/main.py", line 12, in run_stage
    pipeline.main()
  File "/Users/saiaakash/Documents/mlops/DS_main/src/data_science/pipeline/stage_03_data_transformation.py", line 24, in main
    raise e
  File "/Users/saiaakash/Documents/mlops/DS_main/src/data_science/pipeline/stage_03_data_transformation.py", line 17, in main
    data_transformation_config = config.get_data_transformation_config()
  File "/Users/saiaakash/Documents/mlops/DS_main/src/data_science/config/configuration.py", line 56, in get_data_transformation_config
    data_path=config.data_path
  File "box/config_box.py", line 31, in box.config_box.ConfigBox.__getattr__
  File "box/box.py", line 649, in box.box.Box.__getattr__
box.exceptions.BoxKeyError: "'ConfigBox' object has no attribute 'data_path'"
[2025-07-30 08:18:57,177: INFO: main]: >>>>>> stage Data Ingestion stage started <<<<<<
[2025-07-30 08:18:57,178: INFO: common]: yaml file: config/config.yaml loaded successfully
[2025-07-30 08:18:57,179: INFO: common]: yaml file: params.yaml loaded successfully
[2025-07-30 08:18:57,180: INFO: common]: yaml file: schema.yaml loaded successfully
[2025-07-30 08:18:57,180: INFO: common]: created directory at: artifacts
[2025-07-30 08:18:57,180: INFO: common]: created directory at: artifacts/data_ingestion
[2025-07-30 08:18:57,180: INFO: data_ingestion]: File already exists of size: 23329
[2025-07-30 08:18:57,181: INFO: main]: >>>>>> stage Data Ingestion stage completed <<<<<<

x==========x
[2025-07-30 08:18:57,182: INFO: main]: >>>>>> stage Data Validation stage started <<<<<<
[2025-07-30 08:18:57,182: INFO: common]: yaml file: config/config.yaml loaded successfully
[2025-07-30 08:18:57,183: INFO: common]: yaml file: params.yaml loaded successfully
[2025-07-30 08:18:57,183: INFO: common]: yaml file: schema.yaml loaded successfully
[2025-07-30 08:18:57,183: INFO: common]: created directory at: artifacts
[2025-07-30 08:18:57,184: INFO: common]: created directory at: artifacts/data_validation
[2025-07-30 08:18:57,189: INFO: data_validation]: Data validation status: True
[2025-07-30 08:18:57,189: INFO: main]: >>>>>> stage Data Validation stage completed <<<<<<

x==========x
[2025-07-30 08:18:57,189: INFO: main]: >>>>>> stage Data Transformation stage started <<<<<<
[2025-07-30 08:18:57,190: INFO: common]: yaml file: config/config.yaml loaded successfully
[2025-07-30 08:18:57,190: INFO: common]: yaml file: params.yaml loaded successfully
[2025-07-30 08:18:57,191: INFO: common]: yaml file: schema.yaml loaded successfully
[2025-07-30 08:18:57,191: INFO: common]: created directory at: artifacts
[2025-07-30 08:18:57,191: INFO: common]: created directory at: artifacts/data_transformation
[2025-07-30 08:18:57,191: ERROR: stage_03_data_transformation]: DataTransformationConfig.__init__() got an unexpected keyword argument 'data_file'
Traceback (most recent call last):
  File "/Users/saiaakash/Documents/mlops/DS_main/src/data_science/pipeline/stage_03_data_transformation.py", line 17, in main
    data_transformation_config = config.get_data_transformation_config()
  File "/Users/saiaakash/Documents/mlops/DS_main/src/data_science/config/configuration.py", line 54, in get_data_transformation_config
    data_transformation_config = DataTransformationConfig(
TypeError: DataTransformationConfig.__init__() got an unexpected keyword argument 'data_file'
[2025-07-30 08:18:57,191: ERROR: main]: DataTransformationConfig.__init__() got an unexpected keyword argument 'data_file'
Traceback (most recent call last):
  File "/Users/saiaakash/Documents/mlops/DS_main/main.py", line 12, in run_stage
    pipeline.main()
  File "/Users/saiaakash/Documents/mlops/DS_main/src/data_science/pipeline/stage_03_data_transformation.py", line 24, in main
    raise e
  File "/Users/saiaakash/Documents/mlops/DS_main/src/data_science/pipeline/stage_03_data_transformation.py", line 17, in main
    data_transformation_config = config.get_data_transformation_config()
  File "/Users/saiaakash/Documents/mlops/DS_main/src/data_science/config/configuration.py", line 54, in get_data_transformation_config
    data_transformation_config = DataTransformationConfig(
TypeError: DataTransformationConfig.__init__() got an unexpected keyword argument 'data_file'
[2025-07-30 08:26:00,011: INFO: main]: >>>>>> stage Data Ingestion stage started <<<<<<
[2025-07-30 08:26:00,012: INFO: common]: yaml file: config/config.yaml loaded successfully
[2025-07-30 08:26:00,013: INFO: common]: yaml file: params.yaml loaded successfully
[2025-07-30 08:26:00,014: INFO: common]: yaml file: schema.yaml loaded successfully
[2025-07-30 08:26:00,014: INFO: common]: created directory at: artifacts
[2025-07-30 08:26:00,014: INFO: common]: created directory at: artifacts/data_ingestion
[2025-07-30 08:26:00,014: INFO: data_ingestion]: File already exists of size: 23329
[2025-07-30 08:26:00,015: INFO: main]: >>>>>> stage Data Ingestion stage completed <<<<<<

x==========x
[2025-07-30 08:26:00,015: INFO: main]: >>>>>> stage Data Validation stage started <<<<<<
[2025-07-30 08:26:00,016: INFO: common]: yaml file: config/config.yaml loaded successfully
[2025-07-30 08:26:00,016: INFO: common]: yaml file: params.yaml loaded successfully
[2025-07-30 08:26:00,017: INFO: common]: yaml file: schema.yaml loaded successfully
[2025-07-30 08:26:00,017: INFO: common]: created directory at: artifacts
[2025-07-30 08:26:00,017: INFO: common]: created directory at: artifacts/data_validation
[2025-07-30 08:26:00,022: INFO: data_validation]: Data validation status: True
[2025-07-30 08:26:00,022: INFO: main]: >>>>>> stage Data Validation stage completed <<<<<<

x==========x
[2025-07-30 08:26:00,022: INFO: main]: >>>>>> stage Data Transformation stage started <<<<<<
[2025-07-30 08:26:00,023: INFO: common]: yaml file: config/config.yaml loaded successfully
[2025-07-30 08:26:00,024: INFO: common]: yaml file: params.yaml loaded successfully
[2025-07-30 08:26:00,024: INFO: common]: yaml file: schema.yaml loaded successfully
[2025-07-30 08:26:00,025: INFO: common]: created directory at: artifacts
[2025-07-30 08:26:00,025: INFO: common]: created directory at: artifacts/data_transformation
[2025-07-30 08:26:00,025: ERROR: stage_03_data_transformation]: DataTransformationConfig.__init__() got an unexpected keyword argument 'data_file'
Traceback (most recent call last):
  File "/Users/saiaakash/Documents/mlops/DS_main/src/data_science/pipeline/stage_03_data_transformation.py", line 17, in main
    data_transformation_config = config.get_data_transformation_config()
  File "/Users/saiaakash/Documents/mlops/DS_main/src/data_science/config/configuration.py", line 54, in get_data_transformation_config
    data_transformation_config = DataTransformationConfig(
TypeError: DataTransformationConfig.__init__() got an unexpected keyword argument 'data_file'
[2025-07-30 08:26:00,025: ERROR: main]: DataTransformationConfig.__init__() got an unexpected keyword argument 'data_file'
Traceback (most recent call last):
  File "/Users/saiaakash/Documents/mlops/DS_main/main.py", line 12, in run_stage
    pipeline.main()
  File "/Users/saiaakash/Documents/mlops/DS_main/src/data_science/pipeline/stage_03_data_transformation.py", line 24, in main
    raise e
  File "/Users/saiaakash/Documents/mlops/DS_main/src/data_science/pipeline/stage_03_data_transformation.py", line 17, in main
    data_transformation_config = config.get_data_transformation_config()
  File "/Users/saiaakash/Documents/mlops/DS_main/src/data_science/config/configuration.py", line 54, in get_data_transformation_config
    data_transformation_config = DataTransformationConfig(
TypeError: DataTransformationConfig.__init__() got an unexpected keyword argument 'data_file'
[2025-07-30 08:28:40,033: INFO: main]: >>>>>> stage Data Ingestion stage started <<<<<<
[2025-07-30 08:28:40,034: INFO: common]: yaml file: config/config.yaml loaded successfully
[2025-07-30 08:28:40,035: INFO: common]: yaml file: params.yaml loaded successfully
[2025-07-30 08:28:40,036: INFO: common]: yaml file: schema.yaml loaded successfully
[2025-07-30 08:28:40,036: INFO: common]: created directory at: artifacts
[2025-07-30 08:28:40,036: INFO: common]: created directory at: artifacts/data_ingestion
[2025-07-30 08:28:40,036: INFO: data_ingestion]: File already exists of size: 23329
[2025-07-30 08:28:40,038: INFO: main]: >>>>>> stage Data Ingestion stage completed <<<<<<

x==========x
[2025-07-30 08:28:40,038: INFO: main]: >>>>>> stage Data Validation stage started <<<<<<
[2025-07-30 08:28:40,038: INFO: common]: yaml file: config/config.yaml loaded successfully
[2025-07-30 08:28:40,039: INFO: common]: yaml file: params.yaml loaded successfully
[2025-07-30 08:28:40,039: INFO: common]: yaml file: schema.yaml loaded successfully
[2025-07-30 08:28:40,040: INFO: common]: created directory at: artifacts
[2025-07-30 08:28:40,040: INFO: common]: created directory at: artifacts/data_validation
[2025-07-30 08:28:40,046: INFO: data_validation]: Data validation status: True
[2025-07-30 08:28:40,046: INFO: main]: >>>>>> stage Data Validation stage completed <<<<<<

x==========x
[2025-07-30 08:28:40,046: INFO: main]: >>>>>> stage Data Transformation stage started <<<<<<
[2025-07-30 08:28:40,047: INFO: common]: yaml file: config/config.yaml loaded successfully
[2025-07-30 08:28:40,047: INFO: common]: yaml file: params.yaml loaded successfully
[2025-07-30 08:28:40,048: INFO: common]: yaml file: schema.yaml loaded successfully
[2025-07-30 08:28:40,048: INFO: common]: created directory at: artifacts
[2025-07-30 08:28:40,048: INFO: common]: created directory at: artifacts/data_transformation
[2025-07-30 08:28:40,048: ERROR: stage_03_data_transformation]: "'Box' object has no attribute 'data_file'"
Traceback (most recent call last):
  File "box/box.py", line 594, in box.box.Box.__getitem__
KeyError: 'data_file'

The above exception was the direct cause of the following exception:

Traceback (most recent call last):
  File "box/box.py", line 633, in box.box.Box.__getattr__
  File "box/box.py", line 621, in box.box.Box.__getitem__
box.exceptions.BoxKeyError: "'data_file'"

During handling of the above exception, another exception occurred:

Traceback (most recent call last):
  File "box/box.py", line 635, in box.box.Box.__getattr__
AttributeError: 'Box' object has no attribute 'data_file'

The above exception was the direct cause of the following exception:

Traceback (most recent call last):
  File "/Users/saiaakash/Documents/mlops/DS_main/src/data_science/pipeline/stage_03_data_transformation.py", line 17, in main
    data_transformation_config = config.get_data_transformation_config()
  File "/Users/saiaakash/Documents/mlops/DS_main/src/data_science/config/configuration.py", line 56, in get_data_transformation_config
    data_file=config.data_file
  File "box/box.py", line 649, in box.box.Box.__getattr__
box.exceptions.BoxKeyError: "'Box' object has no attribute 'data_file'"
[2025-07-30 08:28:40,049: ERROR: main]: "'Box' object has no attribute 'data_file'"
Traceback (most recent call last):
  File "box/box.py", line 594, in box.box.Box.__getitem__
KeyError: 'data_file'

The above exception was the direct cause of the following exception:

Traceback (most recent call last):
  File "box/box.py", line 633, in box.box.Box.__getattr__
  File "box/box.py", line 621, in box.box.Box.__getitem__
box.exceptions.BoxKeyError: "'data_file'"

During handling of the above exception, another exception occurred:

Traceback (most recent call last):
  File "box/box.py", line 635, in box.box.Box.__getattr__
AttributeError: 'Box' object has no attribute 'data_file'

The above exception was the direct cause of the following exception:

Traceback (most recent call last):
  File "/Users/saiaakash/Documents/mlops/DS_main/main.py", line 12, in run_stage
    pipeline.main()
  File "/Users/saiaakash/Documents/mlops/DS_main/src/data_science/pipeline/stage_03_data_transformation.py", line 24, in main
    raise e
  File "/Users/saiaakash/Documents/mlops/DS_main/src/data_science/pipeline/stage_03_data_transformation.py", line 17, in main
    data_transformation_config = config.get_data_transformation_config()
  File "/Users/saiaakash/Documents/mlops/DS_main/src/data_science/config/configuration.py", line 56, in get_data_transformation_config
    data_file=config.data_file
  File "box/box.py", line 649, in box.box.Box.__getattr__
box.exceptions.BoxKeyError: "'Box' object has no attribute 'data_file'"
[2025-07-30 08:30:06,000: INFO: main]: >>>>>> stage Data Ingestion stage started <<<<<<
[2025-07-30 08:30:06,001: INFO: common]: yaml file: config/config.yaml loaded successfully
[2025-07-30 08:30:06,002: INFO: common]: yaml file: params.yaml loaded successfully
[2025-07-30 08:30:06,003: INFO: common]: yaml file: schema.yaml loaded successfully
[2025-07-30 08:30:06,003: INFO: common]: created directory at: artifacts
[2025-07-30 08:30:06,003: INFO: common]: created directory at: artifacts/data_ingestion
[2025-07-30 08:30:06,003: INFO: data_ingestion]: File already exists of size: 23329
[2025-07-30 08:30:06,005: INFO: main]: >>>>>> stage Data Ingestion stage completed <<<<<<

x==========x
[2025-07-30 08:30:06,005: INFO: main]: >>>>>> stage Data Validation stage started <<<<<<
[2025-07-30 08:30:06,006: INFO: common]: yaml file: config/config.yaml loaded successfully
[2025-07-30 08:30:06,007: INFO: common]: yaml file: params.yaml loaded successfully
[2025-07-30 08:30:06,008: INFO: common]: yaml file: schema.yaml loaded successfully
[2025-07-30 08:30:06,008: INFO: common]: created directory at: artifacts
[2025-07-30 08:30:06,008: INFO: common]: created directory at: artifacts/data_validation
[2025-07-30 08:30:06,012: INFO: data_validation]: Data validation status: True
[2025-07-30 08:30:06,012: INFO: main]: >>>>>> stage Data Validation stage completed <<<<<<

x==========x
[2025-07-30 08:30:06,013: INFO: main]: >>>>>> stage Data Transformation stage started <<<<<<
[2025-07-30 08:30:06,013: INFO: common]: yaml file: config/config.yaml loaded successfully
[2025-07-30 08:30:06,014: INFO: common]: yaml file: params.yaml loaded successfully
[2025-07-30 08:30:06,014: INFO: common]: yaml file: schema.yaml loaded successfully
[2025-07-30 08:30:06,015: INFO: common]: created directory at: artifacts
[2025-07-30 08:30:06,015: INFO: common]: created directory at: artifacts/data_transformation
[2025-07-30 08:30:06,025: INFO: data_transformation]: Splited data into training and test sets
[2025-07-30 08:30:06,025: INFO: data_transformation]: (1279, 12)
[2025-07-30 08:30:06,025: INFO: data_transformation]: (320, 12)
[2025-07-30 08:30:06,026: INFO: main]: >>>>>> stage Data Transformation stage completed <<<<<<

x==========x
[2025-07-30 08:54:08,408: INFO: main]: >>>>>> stage Data Ingestion stage started <<<<<<
[2025-07-30 08:54:08,411: INFO: common]: yaml file: config/config.yaml loaded successfully
[2025-07-30 08:54:08,412: INFO: common]: yaml file: params.yaml loaded successfully
[2025-07-30 08:54:08,413: INFO: common]: yaml file: schema.yaml loaded successfully
[2025-07-30 08:54:08,413: INFO: common]: created directory at: artifacts
[2025-07-30 08:54:08,413: INFO: common]: created directory at: artifacts/data_ingestion
[2025-07-30 08:54:08,413: INFO: data_ingestion]: File already exists of size: 23329
[2025-07-30 08:54:08,415: INFO: main]: >>>>>> stage Data Ingestion stage completed <<<<<<

x==========x
[2025-07-30 08:54:08,415: INFO: main]: >>>>>> stage Data Validation stage started <<<<<<
[2025-07-30 08:54:08,416: INFO: common]: yaml file: config/config.yaml loaded successfully
[2025-07-30 08:54:08,416: INFO: common]: yaml file: params.yaml loaded successfully
[2025-07-30 08:54:08,417: INFO: common]: yaml file: schema.yaml loaded successfully
[2025-07-30 08:54:08,418: INFO: common]: created directory at: artifacts
[2025-07-30 08:54:08,418: INFO: common]: created directory at: artifacts/data_validation
[2025-07-30 08:54:08,425: INFO: data_validation]: Data validation status: True
[2025-07-30 08:54:08,425: INFO: main]: >>>>>> stage Data Validation stage completed <<<<<<

x==========x
[2025-07-30 08:54:08,425: INFO: main]: >>>>>> stage Data Transformation stage started <<<<<<
[2025-07-30 08:54:08,427: INFO: common]: yaml file: config/config.yaml loaded successfully
[2025-07-30 08:54:08,427: INFO: common]: yaml file: params.yaml loaded successfully
[2025-07-30 08:54:08,428: INFO: common]: yaml file: schema.yaml loaded successfully
[2025-07-30 08:54:08,428: INFO: common]: created directory at: artifacts
[2025-07-30 08:54:08,428: INFO: common]: created directory at: artifacts/data_validation
[2025-07-30 08:54:08,428: INFO: common]: created directory at: artifacts/data_transformation
[2025-07-30 08:54:08,442: INFO: data_transformation]: Splited data into training and test sets
[2025-07-30 08:54:08,442: INFO: data_transformation]: (1279, 12)
[2025-07-30 08:54:08,443: INFO: data_transformation]: (320, 12)
[2025-07-30 08:54:08,443: INFO: main]: >>>>>> stage Data Transformation stage completed <<<<<<

x==========x
[2025-07-30 08:54:08,443: INFO: main]: >>>>>> stage Model Trainer stage started <<<<<<
[2025-07-30 08:54:08,444: INFO: common]: yaml file: config/config.yaml loaded successfully
[2025-07-30 08:54:08,444: INFO: common]: yaml file: params.yaml loaded successfully
[2025-07-30 08:54:08,445: INFO: common]: yaml file: schema.yaml loaded successfully
[2025-07-30 08:54:08,445: INFO: common]: created directory at: artifacts
[2025-07-30 08:54:08,445: INFO: common]: created directory at: artifacts/model_trainer
[2025-07-30 08:54:08,454: INFO: model_trainer]: Model saved to model.joblib in artifacts/model_trainer
[2025-07-30 08:54:08,455: INFO: main]: >>>>>> stage Model Trainer stage completed <<<<<<

x==========x
[2025-07-30 09:40:58,144: INFO: main]: >>>>>> stage Data Ingestion stage started <<<<<<
[2025-07-30 09:40:58,146: INFO: common]: yaml file: config/config.yaml loaded successfully
[2025-07-30 09:40:58,148: INFO: common]: yaml file: params.yaml loaded successfully
[2025-07-30 09:40:58,149: INFO: common]: yaml file: schema.yaml loaded successfully
[2025-07-30 09:40:58,149: INFO: common]: created directory at: artifacts
[2025-07-30 09:40:58,149: INFO: common]: created directory at: artifacts/data_ingestion
[2025-07-30 09:40:58,149: INFO: data_ingestion]: File already exists of size: 23329
[2025-07-30 09:40:58,150: INFO: main]: >>>>>> stage Data Ingestion stage completed <<<<<<

x==========x
[2025-07-30 09:40:58,151: INFO: main]: >>>>>> stage Data Validation stage started <<<<<<
[2025-07-30 09:40:58,152: INFO: common]: yaml file: config/config.yaml loaded successfully
[2025-07-30 09:40:58,152: INFO: common]: yaml file: params.yaml loaded successfully
[2025-07-30 09:40:58,153: INFO: common]: yaml file: schema.yaml loaded successfully
[2025-07-30 09:40:58,153: INFO: common]: created directory at: artifacts
[2025-07-30 09:40:58,153: INFO: common]: created directory at: artifacts/data_validation
[2025-07-30 09:40:58,157: INFO: data_validation]: Data validation status: True
[2025-07-30 09:40:58,157: INFO: main]: >>>>>> stage Data Validation stage completed <<<<<<

x==========x
[2025-07-30 09:40:58,157: INFO: main]: >>>>>> stage Data Transformation stage started <<<<<<
[2025-07-30 09:40:58,158: INFO: common]: yaml file: config/config.yaml loaded successfully
[2025-07-30 09:40:58,159: INFO: common]: yaml file: params.yaml loaded successfully
[2025-07-30 09:40:58,159: INFO: common]: yaml file: schema.yaml loaded successfully
[2025-07-30 09:40:58,159: INFO: common]: created directory at: artifacts
[2025-07-30 09:40:58,159: INFO: common]: created directory at: artifacts/data_validation
[2025-07-30 09:40:58,160: INFO: common]: created directory at: artifacts/data_transformation
[2025-07-30 09:40:58,171: INFO: data_transformation]: Splited data into training and test sets
[2025-07-30 09:40:58,171: INFO: data_transformation]: (1279, 12)
[2025-07-30 09:40:58,171: INFO: data_transformation]: (320, 12)
[2025-07-30 09:40:58,172: INFO: main]: >>>>>> stage Data Transformation stage completed <<<<<<

x==========x
[2025-07-30 09:40:58,172: INFO: main]: >>>>>> stage Model Trainer stage started <<<<<<
[2025-07-30 09:40:58,173: INFO: common]: yaml file: config/config.yaml loaded successfully
[2025-07-30 09:40:58,173: INFO: common]: yaml file: params.yaml loaded successfully
[2025-07-30 09:40:58,174: INFO: common]: yaml file: schema.yaml loaded successfully
[2025-07-30 09:40:58,174: INFO: common]: created directory at: artifacts
[2025-07-30 09:40:58,174: INFO: common]: created directory at: artifacts/model_trainer
[2025-07-30 09:40:58,183: INFO: model_trainer]: Model saved to model.joblib in artifacts/model_trainer
[2025-07-30 09:40:58,183: INFO: main]: >>>>>> stage Model Trainer stage completed <<<<<<

x==========x
[2025-07-30 09:40:58,184: INFO: main]: >>>>>> stage Model Evaluation stage started <<<<<<
[2025-07-30 09:40:58,185: INFO: common]: yaml file: config/config.yaml loaded successfully
[2025-07-30 09:40:58,185: INFO: common]: yaml file: params.yaml loaded successfully
[2025-07-30 09:40:58,186: INFO: common]: yaml file: schema.yaml loaded successfully
[2025-07-30 09:40:58,187: INFO: common]: created directory at: artifacts
[2025-07-30 09:40:58,187: INFO: common]: created directory at: artifacts/model_evaluation
[2025-07-30 09:40:58,187: ERROR: main]: name 'ModelEvaluation' is not defined
Traceback (most recent call last):
  File "/Users/saiaakash/Documents/mlops/DS_main/main.py", line 15, in run_stage
    pipeline.main()
  File "/Users/saiaakash/Documents/mlops/DS_main/src/data_science/pipeline/stage_05_model_evaluation.py", line 14, in main
    model_evaluation = ModelEvaluation(config=model_evaluation_config)
NameError: name 'ModelEvaluation' is not defined
[2025-07-30 09:42:55,407: INFO: main]: >>>>>> stage Data Ingestion stage started <<<<<<
[2025-07-30 09:42:55,410: INFO: common]: yaml file: config/config.yaml loaded successfully
[2025-07-30 09:42:55,412: INFO: common]: yaml file: params.yaml loaded successfully
[2025-07-30 09:42:55,412: INFO: common]: yaml file: schema.yaml loaded successfully
[2025-07-30 09:42:55,413: INFO: common]: created directory at: artifacts
[2025-07-30 09:42:55,413: INFO: common]: created directory at: artifacts/data_ingestion
[2025-07-30 09:42:55,413: INFO: data_ingestion]: File already exists of size: 23329
[2025-07-30 09:42:55,414: INFO: main]: >>>>>> stage Data Ingestion stage completed <<<<<<

x==========x
[2025-07-30 09:42:55,414: INFO: main]: >>>>>> stage Data Validation stage started <<<<<<
[2025-07-30 09:42:55,415: INFO: common]: yaml file: config/config.yaml loaded successfully
[2025-07-30 09:42:55,416: INFO: common]: yaml file: params.yaml loaded successfully
[2025-07-30 09:42:55,417: INFO: common]: yaml file: schema.yaml loaded successfully
[2025-07-30 09:42:55,417: INFO: common]: created directory at: artifacts
[2025-07-30 09:42:55,417: INFO: common]: created directory at: artifacts/data_validation
[2025-07-30 09:42:55,424: INFO: data_validation]: Data validation status: True
[2025-07-30 09:42:55,425: INFO: main]: >>>>>> stage Data Validation stage completed <<<<<<

x==========x
[2025-07-30 09:42:55,425: INFO: main]: >>>>>> stage Data Transformation stage started <<<<<<
[2025-07-30 09:42:55,426: INFO: common]: yaml file: config/config.yaml loaded successfully
[2025-07-30 09:42:55,426: INFO: common]: yaml file: params.yaml loaded successfully
[2025-07-30 09:42:55,427: INFO: common]: yaml file: schema.yaml loaded successfully
[2025-07-30 09:42:55,427: INFO: common]: created directory at: artifacts
[2025-07-30 09:42:55,427: INFO: common]: created directory at: artifacts/data_validation
[2025-07-30 09:42:55,427: INFO: common]: created directory at: artifacts/data_transformation
[2025-07-30 09:42:55,439: INFO: data_transformation]: Splited data into training and test sets
[2025-07-30 09:42:55,439: INFO: data_transformation]: (1279, 12)
[2025-07-30 09:42:55,439: INFO: data_transformation]: (320, 12)
[2025-07-30 09:42:55,439: INFO: main]: >>>>>> stage Data Transformation stage completed <<<<<<

x==========x
[2025-07-30 09:42:55,439: INFO: main]: >>>>>> stage Model Trainer stage started <<<<<<
[2025-07-30 09:42:55,441: INFO: common]: yaml file: config/config.yaml loaded successfully
[2025-07-30 09:42:55,441: INFO: common]: yaml file: params.yaml loaded successfully
[2025-07-30 09:42:55,442: INFO: common]: yaml file: schema.yaml loaded successfully
[2025-07-30 09:42:55,442: INFO: common]: created directory at: artifacts
[2025-07-30 09:42:55,442: INFO: common]: created directory at: artifacts/model_trainer
[2025-07-30 09:42:55,450: INFO: model_trainer]: Model saved to model.joblib in artifacts/model_trainer
[2025-07-30 09:42:55,450: INFO: main]: >>>>>> stage Model Trainer stage completed <<<<<<

x==========x
[2025-07-30 09:42:55,450: INFO: main]: >>>>>> stage Model Evaluation stage started <<<<<<
[2025-07-30 09:42:55,451: INFO: common]: yaml file: config/config.yaml loaded successfully
[2025-07-30 09:42:55,451: INFO: common]: yaml file: params.yaml loaded successfully
[2025-07-30 09:42:55,452: INFO: common]: yaml file: schema.yaml loaded successfully
[2025-07-30 09:42:55,452: INFO: common]: created directory at: artifacts
[2025-07-30 09:42:55,452: INFO: common]: created directory at: artifacts/model_evaluation
[2025-07-30 09:42:55,452: ERROR: main]: name 'ModelEvaluation' is not defined
Traceback (most recent call last):
  File "/Users/saiaakash/Documents/mlops/DS_main/main.py", line 15, in run_stage
    pipeline.main()
  File "/Users/saiaakash/Documents/mlops/DS_main/src/data_science/pipeline/stage_05_model_evaluation.py", line 14, in main
    model_evaluation = ModelEvaluation(config=model_evaluation_config)
NameError: name 'ModelEvaluation' is not defined
[2025-07-30 09:43:04,827: INFO: main]: >>>>>> stage Data Ingestion stage started <<<<<<
[2025-07-30 09:43:04,828: INFO: common]: yaml file: config/config.yaml loaded successfully
[2025-07-30 09:43:04,830: INFO: common]: yaml file: params.yaml loaded successfully
[2025-07-30 09:43:04,831: INFO: common]: yaml file: schema.yaml loaded successfully
[2025-07-30 09:43:04,831: INFO: common]: created directory at: artifacts
[2025-07-30 09:43:04,831: INFO: common]: created directory at: artifacts/data_ingestion
[2025-07-30 09:43:04,831: INFO: data_ingestion]: File already exists of size: 23329
[2025-07-30 09:43:04,833: INFO: main]: >>>>>> stage Data Ingestion stage completed <<<<<<

x==========x
[2025-07-30 09:43:04,833: INFO: main]: >>>>>> stage Data Validation stage started <<<<<<
[2025-07-30 09:43:04,834: INFO: common]: yaml file: config/config.yaml loaded successfully
[2025-07-30 09:43:04,834: INFO: common]: yaml file: params.yaml loaded successfully
[2025-07-30 09:43:04,835: INFO: common]: yaml file: schema.yaml loaded successfully
[2025-07-30 09:43:04,835: INFO: common]: created directory at: artifacts
[2025-07-30 09:43:04,835: INFO: common]: created directory at: artifacts/data_validation
[2025-07-30 09:43:04,843: INFO: data_validation]: Data validation status: True
[2025-07-30 09:43:04,843: INFO: main]: >>>>>> stage Data Validation stage completed <<<<<<

x==========x
[2025-07-30 09:43:04,843: INFO: main]: >>>>>> stage Data Transformation stage started <<<<<<
[2025-07-30 09:43:04,844: INFO: common]: yaml file: config/config.yaml loaded successfully
[2025-07-30 09:43:04,845: INFO: common]: yaml file: params.yaml loaded successfully
[2025-07-30 09:43:04,846: INFO: common]: yaml file: schema.yaml loaded successfully
[2025-07-30 09:43:04,846: INFO: common]: created directory at: artifacts
[2025-07-30 09:43:04,846: INFO: common]: created directory at: artifacts/data_validation
[2025-07-30 09:43:04,846: INFO: common]: created directory at: artifacts/data_transformation
[2025-07-30 09:43:04,855: INFO: data_transformation]: Splited data into training and test sets
[2025-07-30 09:43:04,856: INFO: data_transformation]: (1279, 12)
[2025-07-30 09:43:04,856: INFO: data_transformation]: (320, 12)
[2025-07-30 09:43:04,856: INFO: main]: >>>>>> stage Data Transformation stage completed <<<<<<

x==========x
[2025-07-30 09:43:04,856: INFO: main]: >>>>>> stage Model Trainer stage started <<<<<<
[2025-07-30 09:43:04,857: INFO: common]: yaml file: config/config.yaml loaded successfully
[2025-07-30 09:43:04,857: INFO: common]: yaml file: params.yaml loaded successfully
[2025-07-30 09:43:04,858: INFO: common]: yaml file: schema.yaml loaded successfully
[2025-07-30 09:43:04,858: INFO: common]: created directory at: artifacts
[2025-07-30 09:43:04,858: INFO: common]: created directory at: artifacts/model_trainer
[2025-07-30 09:43:04,865: INFO: model_trainer]: Model saved to model.joblib in artifacts/model_trainer
[2025-07-30 09:43:04,865: INFO: main]: >>>>>> stage Model Trainer stage completed <<<<<<

x==========x
[2025-07-30 09:43:04,865: INFO: main]: >>>>>> stage Model Evaluation stage started <<<<<<
[2025-07-30 09:43:04,866: INFO: common]: yaml file: config/config.yaml loaded successfully
[2025-07-30 09:43:04,867: INFO: common]: yaml file: params.yaml loaded successfully
[2025-07-30 09:43:04,867: INFO: common]: yaml file: schema.yaml loaded successfully
[2025-07-30 09:43:04,868: INFO: common]: created directory at: artifacts
[2025-07-30 09:43:04,868: INFO: common]: created directory at: artifacts/model_evaluation
[2025-07-30 09:43:04,868: ERROR: main]: name 'ModelEvaluation' is not defined
Traceback (most recent call last):
  File "/Users/saiaakash/Documents/mlops/DS_main/main.py", line 15, in run_stage
    pipeline.main()
  File "/Users/saiaakash/Documents/mlops/DS_main/src/data_science/pipeline/stage_05_model_evaluation.py", line 14, in main
    model_evaluation = ModelEvaluation(config=model_evaluation_config)
NameError: name 'ModelEvaluation' is not defined
[2025-07-30 09:46:02,497: INFO: main]: >>>>>> stage Data Ingestion stage started <<<<<<
[2025-07-30 09:46:02,500: INFO: common]: yaml file: config/config.yaml loaded successfully
[2025-07-30 09:46:02,501: INFO: common]: yaml file: params.yaml loaded successfully
[2025-07-30 09:46:02,502: INFO: common]: yaml file: schema.yaml loaded successfully
[2025-07-30 09:46:02,502: INFO: common]: created directory at: artifacts
[2025-07-30 09:46:02,502: INFO: common]: created directory at: artifacts/data_ingestion
[2025-07-30 09:46:02,502: INFO: data_ingestion]: File already exists of size: 23329
[2025-07-30 09:46:02,504: INFO: main]: >>>>>> stage Data Ingestion stage completed <<<<<<

x==========x
[2025-07-30 09:46:02,504: INFO: main]: >>>>>> stage Data Validation stage started <<<<<<
[2025-07-30 09:46:02,505: INFO: common]: yaml file: config/config.yaml loaded successfully
[2025-07-30 09:46:02,506: INFO: common]: yaml file: params.yaml loaded successfully
[2025-07-30 09:46:02,506: INFO: common]: yaml file: schema.yaml loaded successfully
[2025-07-30 09:46:02,506: INFO: common]: created directory at: artifacts
[2025-07-30 09:46:02,507: INFO: common]: created directory at: artifacts/data_validation
[2025-07-30 09:46:02,514: INFO: data_validation]: Data validation status: True
[2025-07-30 09:46:02,514: INFO: main]: >>>>>> stage Data Validation stage completed <<<<<<

x==========x
[2025-07-30 09:46:02,514: INFO: main]: >>>>>> stage Data Transformation stage started <<<<<<
[2025-07-30 09:46:02,516: INFO: common]: yaml file: config/config.yaml loaded successfully
[2025-07-30 09:46:02,516: INFO: common]: yaml file: params.yaml loaded successfully
[2025-07-30 09:46:02,517: INFO: common]: yaml file: schema.yaml loaded successfully
[2025-07-30 09:46:02,517: INFO: common]: created directory at: artifacts
[2025-07-30 09:46:02,517: INFO: common]: created directory at: artifacts/data_validation
[2025-07-30 09:46:02,517: INFO: common]: created directory at: artifacts/data_transformation
[2025-07-30 09:46:02,529: INFO: data_transformation]: Splited data into training and test sets
[2025-07-30 09:46:02,529: INFO: data_transformation]: (1279, 12)
[2025-07-30 09:46:02,529: INFO: data_transformation]: (320, 12)
[2025-07-30 09:46:02,529: INFO: main]: >>>>>> stage Data Transformation stage completed <<<<<<

x==========x
[2025-07-30 09:46:02,529: INFO: main]: >>>>>> stage Model Trainer stage started <<<<<<
[2025-07-30 09:46:02,531: INFO: common]: yaml file: config/config.yaml loaded successfully
[2025-07-30 09:46:02,531: INFO: common]: yaml file: params.yaml loaded successfully
[2025-07-30 09:46:02,532: INFO: common]: yaml file: schema.yaml loaded successfully
[2025-07-30 09:46:02,532: INFO: common]: created directory at: artifacts
[2025-07-30 09:46:02,532: INFO: common]: created directory at: artifacts/model_trainer
[2025-07-30 09:46:02,540: INFO: model_trainer]: Model saved to model.joblib in artifacts/model_trainer
[2025-07-30 09:46:02,540: INFO: main]: >>>>>> stage Model Trainer stage completed <<<<<<

x==========x
[2025-07-30 09:46:02,540: INFO: main]: >>>>>> stage Model Evaluation stage started <<<<<<
[2025-07-30 09:46:02,541: INFO: common]: yaml file: config/config.yaml loaded successfully
[2025-07-30 09:46:02,541: INFO: common]: yaml file: params.yaml loaded successfully
[2025-07-30 09:46:02,542: INFO: common]: yaml file: schema.yaml loaded successfully
[2025-07-30 09:46:02,542: INFO: common]: created directory at: artifacts
[2025-07-30 09:46:02,542: INFO: common]: created directory at: artifacts/model_evaluation
[2025-07-30 09:46:05,596: ERROR: main]: name 'save_json' is not defined
Traceback (most recent call last):
  File "/Users/saiaakash/Documents/mlops/DS_main/main.py", line 15, in run_stage
    pipeline.main()
  File "/Users/saiaakash/Documents/mlops/DS_main/src/data_science/pipeline/stage_05_model_evaluation.py", line 15, in main
    model_evaluation.log_into_mlflow()
  File "/Users/saiaakash/Documents/mlops/DS_main/src/data_science/components/model_evaluation.py", line 42, in log_into_mlflow
    save_json(path=Path(self.config.metrics_file_path), data=scores)
NameError: name 'save_json' is not defined
[2025-07-30 09:47:07,491: INFO: main]: >>>>>> stage Data Ingestion stage started <<<<<<
[2025-07-30 09:47:07,495: INFO: common]: yaml file: config/config.yaml loaded successfully
[2025-07-30 09:47:07,496: INFO: common]: yaml file: params.yaml loaded successfully
[2025-07-30 09:47:07,497: INFO: common]: yaml file: schema.yaml loaded successfully
[2025-07-30 09:47:07,497: INFO: common]: created directory at: artifacts
[2025-07-30 09:47:07,497: INFO: common]: created directory at: artifacts/data_ingestion
[2025-07-30 09:47:07,497: INFO: data_ingestion]: File already exists of size: 23329
[2025-07-30 09:47:07,499: INFO: main]: >>>>>> stage Data Ingestion stage completed <<<<<<

x==========x
[2025-07-30 09:47:07,499: INFO: main]: >>>>>> stage Data Validation stage started <<<<<<
[2025-07-30 09:47:07,500: INFO: common]: yaml file: config/config.yaml loaded successfully
[2025-07-30 09:47:07,500: INFO: common]: yaml file: params.yaml loaded successfully
[2025-07-30 09:47:07,501: INFO: common]: yaml file: schema.yaml loaded successfully
[2025-07-30 09:47:07,501: INFO: common]: created directory at: artifacts
[2025-07-30 09:47:07,501: INFO: common]: created directory at: artifacts/data_validation
[2025-07-30 09:47:07,507: INFO: data_validation]: Data validation status: True
[2025-07-30 09:47:07,507: INFO: main]: >>>>>> stage Data Validation stage completed <<<<<<

x==========x
[2025-07-30 09:47:07,507: INFO: main]: >>>>>> stage Data Transformation stage started <<<<<<
[2025-07-30 09:47:07,508: INFO: common]: yaml file: config/config.yaml loaded successfully
[2025-07-30 09:47:07,508: INFO: common]: yaml file: params.yaml loaded successfully
[2025-07-30 09:47:07,509: INFO: common]: yaml file: schema.yaml loaded successfully
[2025-07-30 09:47:07,509: INFO: common]: created directory at: artifacts
[2025-07-30 09:47:07,509: INFO: common]: created directory at: artifacts/data_validation
[2025-07-30 09:47:07,509: INFO: common]: created directory at: artifacts/data_transformation
[2025-07-30 09:47:07,520: INFO: data_transformation]: Splited data into training and test sets
[2025-07-30 09:47:07,520: INFO: data_transformation]: (1279, 12)
[2025-07-30 09:47:07,520: INFO: data_transformation]: (320, 12)
[2025-07-30 09:47:07,520: INFO: main]: >>>>>> stage Data Transformation stage completed <<<<<<

x==========x
[2025-07-30 09:47:07,520: INFO: main]: >>>>>> stage Model Trainer stage started <<<<<<
[2025-07-30 09:47:07,521: INFO: common]: yaml file: config/config.yaml loaded successfully
[2025-07-30 09:47:07,522: INFO: common]: yaml file: params.yaml loaded successfully
[2025-07-30 09:47:07,522: INFO: common]: yaml file: schema.yaml loaded successfully
[2025-07-30 09:47:07,523: INFO: common]: created directory at: artifacts
[2025-07-30 09:47:07,523: INFO: common]: created directory at: artifacts/model_trainer
[2025-07-30 09:47:07,528: INFO: model_trainer]: Model saved to model.joblib in artifacts/model_trainer
[2025-07-30 09:47:07,529: INFO: main]: >>>>>> stage Model Trainer stage completed <<<<<<

x==========x
[2025-07-30 09:47:07,529: INFO: main]: >>>>>> stage Model Evaluation stage started <<<<<<
[2025-07-30 09:47:07,530: INFO: common]: yaml file: config/config.yaml loaded successfully
[2025-07-30 09:47:07,530: INFO: common]: yaml file: params.yaml loaded successfully
[2025-07-30 09:47:07,531: INFO: common]: yaml file: schema.yaml loaded successfully
[2025-07-30 09:47:07,531: INFO: common]: created directory at: artifacts
[2025-07-30 09:47:07,531: INFO: common]: created directory at: artifacts/model_evaluation
[2025-07-30 09:47:08,937: ERROR: main]: name 'Path' is not defined
Traceback (most recent call last):
  File "/Users/saiaakash/Documents/mlops/DS_main/main.py", line 15, in run_stage
    pipeline.main()
  File "/Users/saiaakash/Documents/mlops/DS_main/src/data_science/pipeline/stage_05_model_evaluation.py", line 15, in main
    model_evaluation.log_into_mlflow()
  File "/Users/saiaakash/Documents/mlops/DS_main/src/data_science/components/model_evaluation.py", line 43, in log_into_mlflow
    save_json(path=Path(self.config.metrics_file_path), data=scores)
NameError: name 'Path' is not defined
[2025-07-30 09:47:41,850: INFO: main]: >>>>>> stage Data Ingestion stage started <<<<<<
[2025-07-30 09:47:41,852: INFO: common]: yaml file: config/config.yaml loaded successfully
[2025-07-30 09:47:41,853: INFO: common]: yaml file: params.yaml loaded successfully
[2025-07-30 09:47:41,854: INFO: common]: yaml file: schema.yaml loaded successfully
[2025-07-30 09:47:41,854: INFO: common]: created directory at: artifacts
[2025-07-30 09:47:41,855: INFO: common]: created directory at: artifacts/data_ingestion
[2025-07-30 09:47:41,855: INFO: data_ingestion]: File already exists of size: 23329
[2025-07-30 09:47:41,856: INFO: main]: >>>>>> stage Data Ingestion stage completed <<<<<<

x==========x
[2025-07-30 09:47:41,856: INFO: main]: >>>>>> stage Data Validation stage started <<<<<<
[2025-07-30 09:47:41,857: INFO: common]: yaml file: config/config.yaml loaded successfully
[2025-07-30 09:47:41,858: INFO: common]: yaml file: params.yaml loaded successfully
[2025-07-30 09:47:41,859: INFO: common]: yaml file: schema.yaml loaded successfully
[2025-07-30 09:47:41,859: INFO: common]: created directory at: artifacts
[2025-07-30 09:47:41,859: INFO: common]: created directory at: artifacts/data_validation
[2025-07-30 09:47:41,866: INFO: data_validation]: Data validation status: True
[2025-07-30 09:47:41,866: INFO: main]: >>>>>> stage Data Validation stage completed <<<<<<

x==========x
[2025-07-30 09:47:41,866: INFO: main]: >>>>>> stage Data Transformation stage started <<<<<<
[2025-07-30 09:47:41,867: INFO: common]: yaml file: config/config.yaml loaded successfully
[2025-07-30 09:47:41,867: INFO: common]: yaml file: params.yaml loaded successfully
[2025-07-30 09:47:41,868: INFO: common]: yaml file: schema.yaml loaded successfully
[2025-07-30 09:47:41,868: INFO: common]: created directory at: artifacts
[2025-07-30 09:47:41,868: INFO: common]: created directory at: artifacts/data_validation
[2025-07-30 09:47:41,868: INFO: common]: created directory at: artifacts/data_transformation
[2025-07-30 09:47:41,879: INFO: data_transformation]: Splited data into training and test sets
[2025-07-30 09:47:41,879: INFO: data_transformation]: (1279, 12)
[2025-07-30 09:47:41,879: INFO: data_transformation]: (320, 12)
[2025-07-30 09:47:41,879: INFO: main]: >>>>>> stage Data Transformation stage completed <<<<<<

x==========x
[2025-07-30 09:47:41,879: INFO: main]: >>>>>> stage Model Trainer stage started <<<<<<
[2025-07-30 09:47:41,881: INFO: common]: yaml file: config/config.yaml loaded successfully
[2025-07-30 09:47:41,881: INFO: common]: yaml file: params.yaml loaded successfully
[2025-07-30 09:47:41,882: INFO: common]: yaml file: schema.yaml loaded successfully
[2025-07-30 09:47:41,882: INFO: common]: created directory at: artifacts
[2025-07-30 09:47:41,882: INFO: common]: created directory at: artifacts/model_trainer
[2025-07-30 09:47:41,887: INFO: model_trainer]: Model saved to model.joblib in artifacts/model_trainer
[2025-07-30 09:47:41,887: INFO: main]: >>>>>> stage Model Trainer stage completed <<<<<<

x==========x
[2025-07-30 09:47:41,887: INFO: main]: >>>>>> stage Model Evaluation stage started <<<<<<
[2025-07-30 09:47:41,889: INFO: common]: yaml file: config/config.yaml loaded successfully
[2025-07-30 09:47:41,889: INFO: common]: yaml file: params.yaml loaded successfully
[2025-07-30 09:47:41,890: INFO: common]: yaml file: schema.yaml loaded successfully
[2025-07-30 09:47:41,890: INFO: common]: created directory at: artifacts
[2025-07-30 09:47:41,890: INFO: common]: created directory at: artifacts/model_evaluation
[2025-07-30 09:47:43,443: ERROR: main]: 'ModelEvaluationConfig' object has no attribute 'metrics_file_path'
Traceback (most recent call last):
  File "/Users/saiaakash/Documents/mlops/DS_main/main.py", line 15, in run_stage
    pipeline.main()
  File "/Users/saiaakash/Documents/mlops/DS_main/src/data_science/pipeline/stage_05_model_evaluation.py", line 15, in main
    model_evaluation.log_into_mlflow()
  File "/Users/saiaakash/Documents/mlops/DS_main/src/data_science/components/model_evaluation.py", line 44, in log_into_mlflow
    save_json(path=Path(self.config.metrics_file_path), data=scores)
AttributeError: 'ModelEvaluationConfig' object has no attribute 'metrics_file_path'. Did you mean: 'metrics_file_name'?
[2025-07-30 09:48:22,455: INFO: main]: >>>>>> stage Data Ingestion stage started <<<<<<
[2025-07-30 09:48:22,458: INFO: common]: yaml file: config/config.yaml loaded successfully
[2025-07-30 09:48:22,460: INFO: common]: yaml file: params.yaml loaded successfully
[2025-07-30 09:48:22,461: INFO: common]: yaml file: schema.yaml loaded successfully
[2025-07-30 09:48:22,461: INFO: common]: created directory at: artifacts
[2025-07-30 09:48:22,461: INFO: common]: created directory at: artifacts/data_ingestion
[2025-07-30 09:48:22,461: INFO: data_ingestion]: File already exists of size: 23329
[2025-07-30 09:48:22,462: INFO: main]: >>>>>> stage Data Ingestion stage completed <<<<<<

x==========x
[2025-07-30 09:48:22,462: INFO: main]: >>>>>> stage Data Validation stage started <<<<<<
[2025-07-30 09:48:22,464: INFO: common]: yaml file: config/config.yaml loaded successfully
[2025-07-30 09:48:22,464: INFO: common]: yaml file: params.yaml loaded successfully
[2025-07-30 09:48:22,465: INFO: common]: yaml file: schema.yaml loaded successfully
[2025-07-30 09:48:22,465: INFO: common]: created directory at: artifacts
[2025-07-30 09:48:22,465: INFO: common]: created directory at: artifacts/data_validation
[2025-07-30 09:48:22,469: INFO: data_validation]: Data validation status: True
[2025-07-30 09:48:22,469: INFO: main]: >>>>>> stage Data Validation stage completed <<<<<<

x==========x
[2025-07-30 09:48:22,469: INFO: main]: >>>>>> stage Data Transformation stage started <<<<<<
[2025-07-30 09:48:22,470: INFO: common]: yaml file: config/config.yaml loaded successfully
[2025-07-30 09:48:22,471: INFO: common]: yaml file: params.yaml loaded successfully
[2025-07-30 09:48:22,471: INFO: common]: yaml file: schema.yaml loaded successfully
[2025-07-30 09:48:22,471: INFO: common]: created directory at: artifacts
[2025-07-30 09:48:22,471: INFO: common]: created directory at: artifacts/data_validation
[2025-07-30 09:48:22,471: INFO: common]: created directory at: artifacts/data_transformation
[2025-07-30 09:48:22,481: INFO: data_transformation]: Splited data into training and test sets
[2025-07-30 09:48:22,481: INFO: data_transformation]: (1279, 12)
[2025-07-30 09:48:22,481: INFO: data_transformation]: (320, 12)
[2025-07-30 09:48:22,481: INFO: main]: >>>>>> stage Data Transformation stage completed <<<<<<

x==========x
[2025-07-30 09:48:22,481: INFO: main]: >>>>>> stage Model Trainer stage started <<<<<<
[2025-07-30 09:48:22,483: INFO: common]: yaml file: config/config.yaml loaded successfully
[2025-07-30 09:48:22,483: INFO: common]: yaml file: params.yaml loaded successfully
[2025-07-30 09:48:22,484: INFO: common]: yaml file: schema.yaml loaded successfully
[2025-07-30 09:48:22,484: INFO: common]: created directory at: artifacts
[2025-07-30 09:48:22,484: INFO: common]: created directory at: artifacts/model_trainer
[2025-07-30 09:48:22,491: INFO: model_trainer]: Model saved to model.joblib in artifacts/model_trainer
[2025-07-30 09:48:22,491: INFO: main]: >>>>>> stage Model Trainer stage completed <<<<<<

x==========x
[2025-07-30 09:48:22,491: INFO: main]: >>>>>> stage Model Evaluation stage started <<<<<<
[2025-07-30 09:48:22,492: INFO: common]: yaml file: config/config.yaml loaded successfully
[2025-07-30 09:48:22,492: INFO: common]: yaml file: params.yaml loaded successfully
[2025-07-30 09:48:22,493: INFO: common]: yaml file: schema.yaml loaded successfully
[2025-07-30 09:48:22,493: INFO: common]: created directory at: artifacts
[2025-07-30 09:48:22,493: INFO: common]: created directory at: artifacts/model_evaluation
[2025-07-30 09:48:23,912: ERROR: main]: 'ModelEvaluationConfig' object has no attribute 'metrics_file_path'
Traceback (most recent call last):
  File "/Users/saiaakash/Documents/mlops/DS_main/main.py", line 15, in run_stage
    pipeline.main()
  File "/Users/saiaakash/Documents/mlops/DS_main/src/data_science/pipeline/stage_05_model_evaluation.py", line 15, in main
    model_evaluation.log_into_mlflow()
  File "/Users/saiaakash/Documents/mlops/DS_main/src/data_science/components/model_evaluation.py", line 44, in log_into_mlflow
    save_json(path=Path(self.config.metrics_file_path), data=scores)
AttributeError: 'ModelEvaluationConfig' object has no attribute 'metrics_file_path'. Did you mean: 'metrics_file_name'?
[2025-07-30 09:50:30,383: INFO: main]: >>>>>> stage Data Ingestion stage started <<<<<<
[2025-07-30 09:50:30,386: INFO: common]: yaml file: config/config.yaml loaded successfully
[2025-07-30 09:50:30,387: INFO: common]: yaml file: params.yaml loaded successfully
[2025-07-30 09:50:30,388: INFO: common]: yaml file: schema.yaml loaded successfully
[2025-07-30 09:50:30,388: INFO: common]: created directory at: artifacts
[2025-07-30 09:50:30,388: INFO: common]: created directory at: artifacts/data_ingestion
[2025-07-30 09:50:30,388: INFO: data_ingestion]: File already exists of size: 23329
[2025-07-30 09:50:30,390: INFO: main]: >>>>>> stage Data Ingestion stage completed <<<<<<

x==========x
[2025-07-30 09:50:30,390: INFO: main]: >>>>>> stage Data Validation stage started <<<<<<
[2025-07-30 09:50:30,391: INFO: common]: yaml file: config/config.yaml loaded successfully
[2025-07-30 09:50:30,392: INFO: common]: yaml file: params.yaml loaded successfully
[2025-07-30 09:50:30,392: INFO: common]: yaml file: schema.yaml loaded successfully
[2025-07-30 09:50:30,393: INFO: common]: created directory at: artifacts
[2025-07-30 09:50:30,393: INFO: common]: created directory at: artifacts/data_validation
[2025-07-30 09:50:30,400: INFO: data_validation]: Data validation status: True
[2025-07-30 09:50:30,400: INFO: main]: >>>>>> stage Data Validation stage completed <<<<<<

x==========x
[2025-07-30 09:50:30,400: INFO: main]: >>>>>> stage Data Transformation stage started <<<<<<
[2025-07-30 09:50:30,401: INFO: common]: yaml file: config/config.yaml loaded successfully
[2025-07-30 09:50:30,402: INFO: common]: yaml file: params.yaml loaded successfully
[2025-07-30 09:50:30,403: INFO: common]: yaml file: schema.yaml loaded successfully
[2025-07-30 09:50:30,403: INFO: common]: created directory at: artifacts
[2025-07-30 09:50:30,403: INFO: common]: created directory at: artifacts/data_validation
[2025-07-30 09:50:30,403: INFO: common]: created directory at: artifacts/data_transformation
[2025-07-30 09:50:30,413: INFO: data_transformation]: Splited data into training and test sets
[2025-07-30 09:50:30,413: INFO: data_transformation]: (1279, 12)
[2025-07-30 09:50:30,413: INFO: data_transformation]: (320, 12)
[2025-07-30 09:50:30,413: INFO: main]: >>>>>> stage Data Transformation stage completed <<<<<<

x==========x
[2025-07-30 09:50:30,413: INFO: main]: >>>>>> stage Model Trainer stage started <<<<<<
[2025-07-30 09:50:30,414: INFO: common]: yaml file: config/config.yaml loaded successfully
[2025-07-30 09:50:30,414: INFO: common]: yaml file: params.yaml loaded successfully
[2025-07-30 09:50:30,415: INFO: common]: yaml file: schema.yaml loaded successfully
[2025-07-30 09:50:30,416: INFO: common]: created directory at: artifacts
[2025-07-30 09:50:30,416: INFO: common]: created directory at: artifacts/model_trainer
[2025-07-30 09:50:30,426: INFO: model_trainer]: Model saved to model.joblib in artifacts/model_trainer
[2025-07-30 09:50:30,426: INFO: main]: >>>>>> stage Model Trainer stage completed <<<<<<

x==========x
[2025-07-30 09:50:30,426: INFO: main]: >>>>>> stage Model Evaluation stage started <<<<<<
[2025-07-30 09:50:30,427: INFO: common]: yaml file: config/config.yaml loaded successfully
[2025-07-30 09:50:30,428: INFO: common]: yaml file: params.yaml loaded successfully
[2025-07-30 09:50:30,429: INFO: common]: yaml file: schema.yaml loaded successfully
[2025-07-30 09:50:30,429: INFO: common]: created directory at: artifacts
[2025-07-30 09:50:30,429: INFO: common]: created directory at: artifacts/model_evaluation
[2025-07-30 09:50:31,210: INFO: common]: json file saved at: artifacts/model_evaluation/metrics.json
[2025-07-30 09:50:36,904: ERROR: main]: 'ModelEvaluationConfig' object has no attribute 'model_name'
Traceback (most recent call last):
  File "/Users/saiaakash/Documents/mlops/DS_main/main.py", line 15, in run_stage
    pipeline.main()
  File "/Users/saiaakash/Documents/mlops/DS_main/src/data_science/pipeline/stage_05_model_evaluation.py", line 15, in main
    model_evaluation.log_into_mlflow()
  File "/Users/saiaakash/Documents/mlops/DS_main/src/data_science/components/model_evaluation.py", line 53, in log_into_mlflow
    mlflow.sklearn.log_model(model, "model", registered_model_name=self.config.model_name)
AttributeError: 'ModelEvaluationConfig' object has no attribute 'model_name'. Did you mean: 'model_path'?
[2025-07-30 09:51:51,531: INFO: main]: >>>>>> stage Data Ingestion stage started <<<<<<
[2025-07-30 09:51:51,534: INFO: common]: yaml file: config/config.yaml loaded successfully
[2025-07-30 09:51:51,535: INFO: common]: yaml file: params.yaml loaded successfully
[2025-07-30 09:51:51,536: INFO: common]: yaml file: schema.yaml loaded successfully
[2025-07-30 09:51:51,536: INFO: common]: created directory at: artifacts
[2025-07-30 09:51:51,536: INFO: common]: created directory at: artifacts/data_ingestion
[2025-07-30 09:51:51,536: INFO: data_ingestion]: File already exists of size: 23329
[2025-07-30 09:51:51,538: INFO: main]: >>>>>> stage Data Ingestion stage completed <<<<<<

x==========x
[2025-07-30 09:51:51,538: INFO: main]: >>>>>> stage Data Validation stage started <<<<<<
[2025-07-30 09:51:51,540: INFO: common]: yaml file: config/config.yaml loaded successfully
[2025-07-30 09:51:51,540: INFO: common]: yaml file: params.yaml loaded successfully
[2025-07-30 09:51:51,542: INFO: common]: yaml file: schema.yaml loaded successfully
[2025-07-30 09:51:51,542: INFO: common]: created directory at: artifacts
[2025-07-30 09:51:51,542: INFO: common]: created directory at: artifacts/data_validation
[2025-07-30 09:51:51,547: INFO: data_validation]: Data validation status: True
[2025-07-30 09:51:51,547: INFO: main]: >>>>>> stage Data Validation stage completed <<<<<<

x==========x
[2025-07-30 09:51:51,547: INFO: main]: >>>>>> stage Data Transformation stage started <<<<<<
[2025-07-30 09:51:51,548: INFO: common]: yaml file: config/config.yaml loaded successfully
[2025-07-30 09:51:51,549: INFO: common]: yaml file: params.yaml loaded successfully
[2025-07-30 09:51:51,550: INFO: common]: yaml file: schema.yaml loaded successfully
[2025-07-30 09:51:51,550: INFO: common]: created directory at: artifacts
[2025-07-30 09:51:51,550: INFO: common]: created directory at: artifacts/data_validation
[2025-07-30 09:51:51,550: INFO: common]: created directory at: artifacts/data_transformation
[2025-07-30 09:51:51,560: INFO: data_transformation]: Splited data into training and test sets
[2025-07-30 09:51:51,560: INFO: data_transformation]: (1279, 12)
[2025-07-30 09:51:51,560: INFO: data_transformation]: (320, 12)
[2025-07-30 09:51:51,560: INFO: main]: >>>>>> stage Data Transformation stage completed <<<<<<

x==========x
[2025-07-30 09:51:51,560: INFO: main]: >>>>>> stage Model Trainer stage started <<<<<<
[2025-07-30 09:51:51,561: INFO: common]: yaml file: config/config.yaml loaded successfully
[2025-07-30 09:51:51,561: INFO: common]: yaml file: params.yaml loaded successfully
[2025-07-30 09:51:51,562: INFO: common]: yaml file: schema.yaml loaded successfully
[2025-07-30 09:51:51,562: INFO: common]: created directory at: artifacts
[2025-07-30 09:51:51,562: INFO: common]: created directory at: artifacts/model_trainer
[2025-07-30 09:51:51,569: INFO: model_trainer]: Model saved to model.joblib in artifacts/model_trainer
[2025-07-30 09:51:51,569: INFO: main]: >>>>>> stage Model Trainer stage completed <<<<<<

x==========x
[2025-07-30 09:51:51,569: INFO: main]: >>>>>> stage Model Evaluation stage started <<<<<<
[2025-07-30 09:51:51,570: INFO: common]: yaml file: config/config.yaml loaded successfully
[2025-07-30 09:51:51,570: INFO: common]: yaml file: params.yaml loaded successfully
[2025-07-30 09:51:51,571: INFO: common]: yaml file: schema.yaml loaded successfully
[2025-07-30 09:51:51,571: INFO: common]: created directory at: artifacts
[2025-07-30 09:51:51,571: INFO: common]: created directory at: artifacts/model_evaluation
[2025-07-30 09:51:51,571: ERROR: main]: "'Box' object has no attribute 'registered_model_name'"
Traceback (most recent call last):
  File "box/box.py", line 594, in box.box.Box.__getitem__
KeyError: 'registered_model_name'

The above exception was the direct cause of the following exception:

Traceback (most recent call last):
  File "box/box.py", line 633, in box.box.Box.__getattr__
  File "box/box.py", line 621, in box.box.Box.__getitem__
box.exceptions.BoxKeyError: "'registered_model_name'"

During handling of the above exception, another exception occurred:

Traceback (most recent call last):
  File "box/box.py", line 635, in box.box.Box.__getattr__
AttributeError: 'Box' object has no attribute 'registered_model_name'

The above exception was the direct cause of the following exception:

Traceback (most recent call last):
  File "/Users/saiaakash/Documents/mlops/DS_main/main.py", line 15, in run_stage
    pipeline.main()
  File "/Users/saiaakash/Documents/mlops/DS_main/src/data_science/pipeline/stage_05_model_evaluation.py", line 13, in main
    model_evaluation_config = config.get_model_evaluation_config()
  File "/Users/saiaakash/Documents/mlops/DS_main/src/data_science/config/configuration.py", line 95, in get_model_evaluation_config
    registered_model_name=config.registered_model_name
  File "box/box.py", line 649, in box.box.Box.__getattr__
box.exceptions.BoxKeyError: "'Box' object has no attribute 'registered_model_name'"
[2025-07-30 09:53:24,036: INFO: main]: >>>>>> stage Data Ingestion stage started <<<<<<
[2025-07-30 09:53:24,041: INFO: common]: yaml file: config/config.yaml loaded successfully
[2025-07-30 09:53:24,043: INFO: common]: yaml file: params.yaml loaded successfully
[2025-07-30 09:53:24,044: INFO: common]: yaml file: schema.yaml loaded successfully
[2025-07-30 09:53:24,045: INFO: common]: created directory at: artifacts
[2025-07-30 09:53:24,045: INFO: common]: created directory at: artifacts/data_ingestion
[2025-07-30 09:53:24,045: INFO: data_ingestion]: File already exists of size: 23329
[2025-07-30 09:53:24,050: INFO: main]: >>>>>> stage Data Ingestion stage completed <<<<<<

x==========x
[2025-07-30 09:53:24,051: INFO: main]: >>>>>> stage Data Validation stage started <<<<<<
[2025-07-30 09:53:24,053: INFO: common]: yaml file: config/config.yaml loaded successfully
[2025-07-30 09:53:24,054: INFO: common]: yaml file: params.yaml loaded successfully
[2025-07-30 09:53:24,055: INFO: common]: yaml file: schema.yaml loaded successfully
[2025-07-30 09:53:24,056: INFO: common]: created directory at: artifacts
[2025-07-30 09:53:24,056: INFO: common]: created directory at: artifacts/data_validation
[2025-07-30 09:53:24,064: INFO: data_validation]: Data validation status: True
[2025-07-30 09:53:24,064: INFO: main]: >>>>>> stage Data Validation stage completed <<<<<<

x==========x
[2025-07-30 09:53:24,064: INFO: main]: >>>>>> stage Data Transformation stage started <<<<<<
[2025-07-30 09:53:24,067: INFO: common]: yaml file: config/config.yaml loaded successfully
[2025-07-30 09:53:24,068: INFO: common]: yaml file: params.yaml loaded successfully
[2025-07-30 09:53:24,068: INFO: common]: yaml file: schema.yaml loaded successfully
[2025-07-30 09:53:24,069: INFO: common]: created directory at: artifacts
[2025-07-30 09:53:24,069: INFO: common]: created directory at: artifacts/data_validation
[2025-07-30 09:53:24,069: INFO: common]: created directory at: artifacts/data_transformation
[2025-07-30 09:53:24,082: INFO: data_transformation]: Splited data into training and test sets
[2025-07-30 09:53:24,083: INFO: data_transformation]: (1279, 12)
[2025-07-30 09:53:24,083: INFO: data_transformation]: (320, 12)
[2025-07-30 09:53:24,083: INFO: main]: >>>>>> stage Data Transformation stage completed <<<<<<

x==========x
[2025-07-30 09:53:24,083: INFO: main]: >>>>>> stage Model Trainer stage started <<<<<<
[2025-07-30 09:53:24,084: INFO: common]: yaml file: config/config.yaml loaded successfully
[2025-07-30 09:53:24,085: INFO: common]: yaml file: params.yaml loaded successfully
[2025-07-30 09:53:24,086: INFO: common]: yaml file: schema.yaml loaded successfully
[2025-07-30 09:53:24,086: INFO: common]: created directory at: artifacts
[2025-07-30 09:53:24,086: INFO: common]: created directory at: artifacts/model_trainer
[2025-07-30 09:53:24,098: INFO: model_trainer]: Model saved to model.joblib in artifacts/model_trainer
[2025-07-30 09:53:24,098: INFO: main]: >>>>>> stage Model Trainer stage completed <<<<<<

x==========x
[2025-07-30 09:53:24,098: INFO: main]: >>>>>> stage Model Evaluation stage started <<<<<<
[2025-07-30 09:53:24,100: INFO: common]: yaml file: config/config.yaml loaded successfully
[2025-07-30 09:53:24,100: INFO: common]: yaml file: params.yaml loaded successfully
[2025-07-30 09:53:24,101: INFO: common]: yaml file: schema.yaml loaded successfully
[2025-07-30 09:53:24,101: INFO: common]: created directory at: artifacts
[2025-07-30 09:53:24,101: INFO: common]: created directory at: artifacts/model_evaluation
[2025-07-30 09:53:24,905: ERROR: main]: API request to endpoint /api/2.0/mlflow/runs/create failed with error code 403 != 200. Response body: ''
Traceback (most recent call last):
  File "/Users/saiaakash/Documents/mlops/DS_main/main.py", line 15, in run_stage
    pipeline.main()
  File "/Users/saiaakash/Documents/mlops/DS_main/src/data_science/pipeline/stage_05_model_evaluation.py", line 15, in main
    model_evaluation.log_into_mlflow() # This method handles the full evaluation and logging process
  File "/Users/saiaakash/Documents/mlops/DS_main/src/data_science/components/model_evaluation.py", line 36, in log_into_mlflow
    with mlflow.start_run():
  File "/opt/anaconda3/envs/mlpipe/lib/python3.10/site-packages/mlflow/tracking/fluent.py", line 474, in start_run
    active_run_obj = client.create_run(
  File "/opt/anaconda3/envs/mlpipe/lib/python3.10/site-packages/mlflow/tracking/client.py", line 435, in create_run
    return self._tracking_client.create_run(experiment_id, start_time, tags, run_name)
  File "/opt/anaconda3/envs/mlpipe/lib/python3.10/site-packages/mlflow/tracking/_tracking_service/client.py", line 161, in create_run
    return self.store.create_run(
  File "/opt/anaconda3/envs/mlpipe/lib/python3.10/site-packages/mlflow/store/tracking/rest_store.py", line 272, in create_run
    response_proto = self._call_endpoint(CreateRun, req_body)
  File "/opt/anaconda3/envs/mlpipe/lib/python3.10/site-packages/mlflow/store/tracking/rest_store.py", line 135, in _call_endpoint
    return call_endpoint(
  File "/opt/anaconda3/envs/mlpipe/lib/python3.10/site-packages/mlflow/utils/rest_utils.py", line 594, in call_endpoint
    response = verify_rest_response(response, endpoint)
  File "/opt/anaconda3/envs/mlpipe/lib/python3.10/site-packages/mlflow/utils/rest_utils.py", line 314, in verify_rest_response
    raise MlflowException(
mlflow.exceptions.MlflowException: API request to endpoint /api/2.0/mlflow/runs/create failed with error code 403 != 200. Response body: ''
[2025-07-30 09:55:03,845: INFO: main]: >>>>>> stage Data Ingestion stage started <<<<<<
[2025-07-30 09:55:03,848: INFO: common]: yaml file: config/config.yaml loaded successfully
[2025-07-30 09:55:03,849: INFO: common]: yaml file: params.yaml loaded successfully
[2025-07-30 09:55:03,850: INFO: common]: yaml file: schema.yaml loaded successfully
[2025-07-30 09:55:03,850: INFO: common]: created directory at: artifacts
[2025-07-30 09:55:03,850: INFO: common]: created directory at: artifacts/data_ingestion
[2025-07-30 09:55:03,850: INFO: data_ingestion]: File already exists of size: 23329
[2025-07-30 09:55:03,852: INFO: main]: >>>>>> stage Data Ingestion stage completed <<<<<<

x==========x
[2025-07-30 09:55:03,852: INFO: main]: >>>>>> stage Data Validation stage started <<<<<<
[2025-07-30 09:55:03,853: INFO: common]: yaml file: config/config.yaml loaded successfully
[2025-07-30 09:55:03,854: INFO: common]: yaml file: params.yaml loaded successfully
[2025-07-30 09:55:03,854: INFO: common]: yaml file: schema.yaml loaded successfully
[2025-07-30 09:55:03,854: INFO: common]: created directory at: artifacts
[2025-07-30 09:55:03,855: INFO: common]: created directory at: artifacts/data_validation
[2025-07-30 09:55:03,861: INFO: data_validation]: Data validation status: True
[2025-07-30 09:55:03,861: INFO: main]: >>>>>> stage Data Validation stage completed <<<<<<

x==========x
[2025-07-30 09:55:03,861: INFO: main]: >>>>>> stage Data Transformation stage started <<<<<<
[2025-07-30 09:55:03,862: INFO: common]: yaml file: config/config.yaml loaded successfully
[2025-07-30 09:55:03,863: INFO: common]: yaml file: params.yaml loaded successfully
[2025-07-30 09:55:03,863: INFO: common]: yaml file: schema.yaml loaded successfully
[2025-07-30 09:55:03,864: INFO: common]: created directory at: artifacts
[2025-07-30 09:55:03,864: INFO: common]: created directory at: artifacts/data_validation
[2025-07-30 09:55:03,864: INFO: common]: created directory at: artifacts/data_transformation
[2025-07-30 09:55:03,874: INFO: data_transformation]: Splited data into training and test sets
[2025-07-30 09:55:03,874: INFO: data_transformation]: (1279, 12)
[2025-07-30 09:55:03,874: INFO: data_transformation]: (320, 12)
[2025-07-30 09:55:03,874: INFO: main]: >>>>>> stage Data Transformation stage completed <<<<<<

x==========x
[2025-07-30 09:55:03,874: INFO: main]: >>>>>> stage Model Trainer stage started <<<<<<
[2025-07-30 09:55:03,876: INFO: common]: yaml file: config/config.yaml loaded successfully
[2025-07-30 09:55:03,876: INFO: common]: yaml file: params.yaml loaded successfully
[2025-07-30 09:55:03,877: INFO: common]: yaml file: schema.yaml loaded successfully
[2025-07-30 09:55:03,877: INFO: common]: created directory at: artifacts
[2025-07-30 09:55:03,877: INFO: common]: created directory at: artifacts/model_trainer
[2025-07-30 09:55:03,884: INFO: model_trainer]: Model saved to model.joblib in artifacts/model_trainer
[2025-07-30 09:55:03,884: INFO: main]: >>>>>> stage Model Trainer stage completed <<<<<<

x==========x
[2025-07-30 09:55:03,884: INFO: main]: >>>>>> stage Model Evaluation stage started <<<<<<
[2025-07-30 09:55:03,885: INFO: common]: yaml file: config/config.yaml loaded successfully
[2025-07-30 09:55:03,885: INFO: common]: yaml file: params.yaml loaded successfully
[2025-07-30 09:55:03,886: INFO: common]: yaml file: schema.yaml loaded successfully
[2025-07-30 09:55:03,886: INFO: common]: created directory at: artifacts
[2025-07-30 09:55:03,886: INFO: common]: created directory at: artifacts/model_evaluation
[2025-07-30 09:55:04,672: INFO: common]: json file saved at: artifacts/model_evaluation/metrics.json
[2025-07-30 09:55:09,982: ERROR: main]: INTERNAL_ERROR: Response: {'error': 'unsupported endpoint, please contact support@dagshub.com'}
Traceback (most recent call last):
  File "/Users/saiaakash/Documents/mlops/DS_main/main.py", line 15, in run_stage
    pipeline.main()
  File "/Users/saiaakash/Documents/mlops/DS_main/src/data_science/pipeline/stage_05_model_evaluation.py", line 15, in main
    model_evaluation.log_into_mlflow() # This method handles the full evaluation and logging process
  File "/Users/saiaakash/Documents/mlops/DS_main/src/data_science/components/model_evaluation.py", line 52, in log_into_mlflow
    mlflow.sklearn.log_model(model, "model", registered_model_name=self.config.registered_model_name)
  File "/opt/anaconda3/envs/mlpipe/lib/python3.10/site-packages/mlflow/sklearn/__init__.py", line 426, in log_model
    return Model.log(
  File "/opt/anaconda3/envs/mlpipe/lib/python3.10/site-packages/mlflow/models/model.py", line 1161, in log
    model = mlflow.initialize_logged_model(
  File "/opt/anaconda3/envs/mlpipe/lib/python3.10/site-packages/mlflow/tracking/fluent.py", line 2130, in initialize_logged_model
    model = _create_logged_model(
  File "/opt/anaconda3/envs/mlpipe/lib/python3.10/site-packages/mlflow/tracking/fluent.py", line 2257, in _create_logged_model
    return MlflowClient().create_logged_model(
  File "/opt/anaconda3/envs/mlpipe/lib/python3.10/site-packages/mlflow/tracking/client.py", line 5369, in create_logged_model
    return self._tracking_client.create_logged_model(
  File "/opt/anaconda3/envs/mlpipe/lib/python3.10/site-packages/mlflow/tracking/_tracking_service/client.py", line 824, in create_logged_model
    return self.store.create_logged_model(
  File "/opt/anaconda3/envs/mlpipe/lib/python3.10/site-packages/mlflow/store/tracking/rest_store.py", line 936, in create_logged_model
    response_proto = self._call_endpoint(CreateLoggedModel, req_body)
  File "/opt/anaconda3/envs/mlpipe/lib/python3.10/site-packages/mlflow/store/tracking/rest_store.py", line 135, in _call_endpoint
    return call_endpoint(
  File "/opt/anaconda3/envs/mlpipe/lib/python3.10/site-packages/mlflow/utils/rest_utils.py", line 594, in call_endpoint
    response = verify_rest_response(response, endpoint)
  File "/opt/anaconda3/envs/mlpipe/lib/python3.10/site-packages/mlflow/utils/rest_utils.py", line 308, in verify_rest_response
    raise RestException(json.loads(response.text))
mlflow.exceptions.RestException: INTERNAL_ERROR: Response: {'error': 'unsupported endpoint, please contact support@dagshub.com'}
[2025-07-30 09:56:34,895: INFO: main]: >>>>>> stage Data Ingestion stage started <<<<<<
[2025-07-30 09:56:34,899: INFO: common]: yaml file: config/config.yaml loaded successfully
[2025-07-30 09:56:34,900: INFO: common]: yaml file: params.yaml loaded successfully
[2025-07-30 09:56:34,901: INFO: common]: yaml file: schema.yaml loaded successfully
[2025-07-30 09:56:34,902: INFO: common]: created directory at: artifacts
[2025-07-30 09:56:34,902: INFO: common]: created directory at: artifacts/data_ingestion
[2025-07-30 09:56:34,902: INFO: data_ingestion]: File already exists of size: 23329
[2025-07-30 09:56:34,903: INFO: main]: >>>>>> stage Data Ingestion stage completed <<<<<<

x==========x
[2025-07-30 09:56:34,903: INFO: main]: >>>>>> stage Data Validation stage started <<<<<<
[2025-07-30 09:56:34,905: INFO: common]: yaml file: config/config.yaml loaded successfully
[2025-07-30 09:56:34,905: INFO: common]: yaml file: params.yaml loaded successfully
[2025-07-30 09:56:34,906: INFO: common]: yaml file: schema.yaml loaded successfully
[2025-07-30 09:56:34,906: INFO: common]: created directory at: artifacts
[2025-07-30 09:56:34,906: INFO: common]: created directory at: artifacts/data_validation
[2025-07-30 09:56:34,911: INFO: data_validation]: Data validation status: True
[2025-07-30 09:56:34,911: INFO: main]: >>>>>> stage Data Validation stage completed <<<<<<

x==========x
[2025-07-30 09:56:34,911: INFO: main]: >>>>>> stage Data Transformation stage started <<<<<<
[2025-07-30 09:56:34,913: INFO: common]: yaml file: config/config.yaml loaded successfully
[2025-07-30 09:56:34,913: INFO: common]: yaml file: params.yaml loaded successfully
[2025-07-30 09:56:34,914: INFO: common]: yaml file: schema.yaml loaded successfully
[2025-07-30 09:56:34,914: INFO: common]: created directory at: artifacts
[2025-07-30 09:56:34,914: INFO: common]: created directory at: artifacts/data_validation
[2025-07-30 09:56:34,914: INFO: common]: created directory at: artifacts/data_transformation
[2025-07-30 09:56:34,925: INFO: data_transformation]: Splited data into training and test sets
[2025-07-30 09:56:34,925: INFO: data_transformation]: (1279, 12)
[2025-07-30 09:56:34,925: INFO: data_transformation]: (320, 12)
[2025-07-30 09:56:34,925: INFO: main]: >>>>>> stage Data Transformation stage completed <<<<<<

x==========x
[2025-07-30 09:56:34,925: INFO: main]: >>>>>> stage Model Trainer stage started <<<<<<
[2025-07-30 09:56:34,927: INFO: common]: yaml file: config/config.yaml loaded successfully
[2025-07-30 09:56:34,927: INFO: common]: yaml file: params.yaml loaded successfully
[2025-07-30 09:56:34,928: INFO: common]: yaml file: schema.yaml loaded successfully
[2025-07-30 09:56:34,928: INFO: common]: created directory at: artifacts
[2025-07-30 09:56:34,928: INFO: common]: created directory at: artifacts/model_trainer
[2025-07-30 09:56:34,937: INFO: model_trainer]: Model saved to model.joblib in artifacts/model_trainer
[2025-07-30 09:56:34,937: INFO: main]: >>>>>> stage Model Trainer stage completed <<<<<<

x==========x
[2025-07-30 09:56:34,937: INFO: main]: >>>>>> stage Model Evaluation stage started <<<<<<
[2025-07-30 09:56:34,939: INFO: common]: yaml file: config/config.yaml loaded successfully
[2025-07-30 09:56:34,939: INFO: common]: yaml file: params.yaml loaded successfully
[2025-07-30 09:56:34,940: INFO: common]: yaml file: schema.yaml loaded successfully
[2025-07-30 09:56:34,940: INFO: common]: created directory at: artifacts
[2025-07-30 09:56:34,940: INFO: common]: created directory at: artifacts/model_evaluation
[2025-07-30 09:56:35,253: INFO: common]: json file saved at: artifacts/model_evaluation/metrics.json
[2025-07-30 09:56:37,612: INFO: main]: >>>>>> stage Model Evaluation stage completed <<<<<<

x==========x
[2025-07-30 09:57:33,683: INFO: main]: >>>>>> stage Data Ingestion stage started <<<<<<
[2025-07-30 09:57:33,685: INFO: common]: yaml file: config/config.yaml loaded successfully
[2025-07-30 09:57:33,687: INFO: common]: yaml file: params.yaml loaded successfully
[2025-07-30 09:57:33,688: INFO: common]: yaml file: schema.yaml loaded successfully
[2025-07-30 09:57:33,688: INFO: common]: created directory at: artifacts
[2025-07-30 09:57:33,688: INFO: common]: created directory at: artifacts/data_ingestion
[2025-07-30 09:57:33,688: INFO: data_ingestion]: File already exists of size: 23329
[2025-07-30 09:57:33,690: INFO: main]: >>>>>> stage Data Ingestion stage completed <<<<<<

x==========x
[2025-07-30 09:57:33,691: INFO: main]: >>>>>> stage Data Validation stage started <<<<<<
[2025-07-30 09:57:33,692: INFO: common]: yaml file: config/config.yaml loaded successfully
[2025-07-30 09:57:33,692: INFO: common]: yaml file: params.yaml loaded successfully
[2025-07-30 09:57:33,693: INFO: common]: yaml file: schema.yaml loaded successfully
[2025-07-30 09:57:33,694: INFO: common]: created directory at: artifacts
[2025-07-30 09:57:33,694: INFO: common]: created directory at: artifacts/data_validation
[2025-07-30 09:57:33,701: INFO: data_validation]: Data validation status: True
[2025-07-30 09:57:33,701: INFO: main]: >>>>>> stage Data Validation stage completed <<<<<<

x==========x
[2025-07-30 09:57:33,701: INFO: main]: >>>>>> stage Data Transformation stage started <<<<<<
[2025-07-30 09:57:33,702: INFO: common]: yaml file: config/config.yaml loaded successfully
[2025-07-30 09:57:33,703: INFO: common]: yaml file: params.yaml loaded successfully
[2025-07-30 09:57:33,703: INFO: common]: yaml file: schema.yaml loaded successfully
[2025-07-30 09:57:33,703: INFO: common]: created directory at: artifacts
[2025-07-30 09:57:33,704: INFO: common]: created directory at: artifacts/data_validation
[2025-07-30 09:57:33,704: INFO: common]: created directory at: artifacts/data_transformation
[2025-07-30 09:57:33,715: INFO: data_transformation]: Splited data into training and test sets
[2025-07-30 09:57:33,715: INFO: data_transformation]: (1279, 12)
[2025-07-30 09:57:33,715: INFO: data_transformation]: (320, 12)
[2025-07-30 09:57:33,715: INFO: main]: >>>>>> stage Data Transformation stage completed <<<<<<

x==========x
[2025-07-30 09:57:33,715: INFO: main]: >>>>>> stage Model Trainer stage started <<<<<<
[2025-07-30 09:57:33,716: INFO: common]: yaml file: config/config.yaml loaded successfully
[2025-07-30 09:57:33,717: INFO: common]: yaml file: params.yaml loaded successfully
[2025-07-30 09:57:33,718: INFO: common]: yaml file: schema.yaml loaded successfully
[2025-07-30 09:57:33,718: INFO: common]: created directory at: artifacts
[2025-07-30 09:57:33,718: INFO: common]: created directory at: artifacts/model_trainer
[2025-07-30 09:57:33,726: INFO: model_trainer]: Model saved to model.joblib in artifacts/model_trainer
[2025-07-30 09:57:33,726: INFO: main]: >>>>>> stage Model Trainer stage completed <<<<<<

x==========x
[2025-07-30 09:57:33,726: INFO: main]: >>>>>> stage Model Evaluation stage started <<<<<<
[2025-07-30 09:57:33,727: INFO: common]: yaml file: config/config.yaml loaded successfully
[2025-07-30 09:57:33,728: INFO: common]: yaml file: params.yaml loaded successfully
[2025-07-30 09:57:33,729: INFO: common]: yaml file: schema.yaml loaded successfully
[2025-07-30 09:57:33,729: INFO: common]: created directory at: artifacts
[2025-07-30 09:57:33,729: INFO: common]: created directory at: artifacts/model_evaluation
[2025-07-30 09:57:34,042: INFO: common]: json file saved at: artifacts/model_evaluation/metrics.json
[2025-07-30 09:57:36,237: INFO: main]: >>>>>> stage Model Evaluation stage completed <<<<<<

x==========x
[2025-07-30 09:58:42,576: INFO: main]: >>>>>> stage Data Ingestion stage started <<<<<<
[2025-07-30 09:58:42,579: INFO: common]: yaml file: config/config.yaml loaded successfully
[2025-07-30 09:58:42,580: INFO: common]: yaml file: params.yaml loaded successfully
[2025-07-30 09:58:42,581: INFO: common]: yaml file: schema.yaml loaded successfully
[2025-07-30 09:58:42,582: INFO: common]: created directory at: artifacts
[2025-07-30 09:58:42,582: INFO: common]: created directory at: artifacts/data_ingestion
[2025-07-30 09:58:42,582: INFO: data_ingestion]: File already exists of size: 23329
[2025-07-30 09:58:42,584: INFO: main]: >>>>>> stage Data Ingestion stage completed <<<<<<

x==========x
[2025-07-30 09:58:42,584: INFO: main]: >>>>>> stage Data Validation stage started <<<<<<
[2025-07-30 09:58:42,585: INFO: common]: yaml file: config/config.yaml loaded successfully
[2025-07-30 09:58:42,585: INFO: common]: yaml file: params.yaml loaded successfully
[2025-07-30 09:58:42,586: INFO: common]: yaml file: schema.yaml loaded successfully
[2025-07-30 09:58:42,586: INFO: common]: created directory at: artifacts
[2025-07-30 09:58:42,586: INFO: common]: created directory at: artifacts/data_validation
[2025-07-30 09:58:42,592: INFO: data_validation]: Data validation status: True
[2025-07-30 09:58:42,592: INFO: main]: >>>>>> stage Data Validation stage completed <<<<<<

x==========x
[2025-07-30 09:58:42,592: INFO: main]: >>>>>> stage Data Transformation stage started <<<<<<
[2025-07-30 09:58:42,593: INFO: common]: yaml file: config/config.yaml loaded successfully
[2025-07-30 09:58:42,594: INFO: common]: yaml file: params.yaml loaded successfully
[2025-07-30 09:58:42,594: INFO: common]: yaml file: schema.yaml loaded successfully
[2025-07-30 09:58:42,594: INFO: common]: created directory at: artifacts
[2025-07-30 09:58:42,595: INFO: common]: created directory at: artifacts/data_validation
[2025-07-30 09:58:42,595: INFO: common]: created directory at: artifacts/data_transformation
[2025-07-30 09:58:42,605: INFO: data_transformation]: Splited data into training and test sets
[2025-07-30 09:58:42,605: INFO: data_transformation]: (1279, 12)
[2025-07-30 09:58:42,605: INFO: data_transformation]: (320, 12)
[2025-07-30 09:58:42,605: INFO: main]: >>>>>> stage Data Transformation stage completed <<<<<<

x==========x
[2025-07-30 09:58:42,605: INFO: main]: >>>>>> stage Model Trainer stage started <<<<<<
[2025-07-30 09:58:42,607: INFO: common]: yaml file: config/config.yaml loaded successfully
[2025-07-30 09:58:42,607: INFO: common]: yaml file: params.yaml loaded successfully
[2025-07-30 09:58:42,608: INFO: common]: yaml file: schema.yaml loaded successfully
[2025-07-30 09:58:42,608: INFO: common]: created directory at: artifacts
[2025-07-30 09:58:42,608: INFO: common]: created directory at: artifacts/model_trainer
[2025-07-30 09:58:42,616: INFO: model_trainer]: Model saved to model.joblib in artifacts/model_trainer
[2025-07-30 09:58:42,616: INFO: main]: >>>>>> stage Model Trainer stage completed <<<<<<

x==========x
[2025-07-30 09:58:42,616: INFO: main]: >>>>>> stage Model Evaluation stage started <<<<<<
[2025-07-30 09:58:42,618: INFO: common]: yaml file: config/config.yaml loaded successfully
[2025-07-30 09:58:42,618: INFO: common]: yaml file: params.yaml loaded successfully
[2025-07-30 09:58:42,619: INFO: common]: yaml file: schema.yaml loaded successfully
[2025-07-30 09:58:42,619: INFO: common]: created directory at: artifacts
[2025-07-30 09:58:42,619: INFO: common]: created directory at: artifacts/model_evaluation
[2025-07-30 09:58:42,936: INFO: common]: json file saved at: artifacts/model_evaluation/metrics.json
[2025-07-30 09:58:45,030: INFO: main]: >>>>>> stage Model Evaluation stage completed <<<<<<

x==========x
[2025-07-30 09:58:49,676: INFO: main]: >>>>>> stage Data Ingestion stage started <<<<<<
[2025-07-30 09:58:49,678: INFO: common]: yaml file: config/config.yaml loaded successfully
[2025-07-30 09:58:49,678: INFO: common]: yaml file: params.yaml loaded successfully
[2025-07-30 09:58:49,679: INFO: common]: yaml file: schema.yaml loaded successfully
[2025-07-30 09:58:49,679: INFO: common]: created directory at: artifacts
[2025-07-30 09:58:49,679: INFO: common]: created directory at: artifacts/data_ingestion
[2025-07-30 09:58:49,679: INFO: data_ingestion]: File already exists of size: 23329
[2025-07-30 09:58:49,680: INFO: main]: >>>>>> stage Data Ingestion stage completed <<<<<<

x==========x
[2025-07-30 09:58:49,680: INFO: main]: >>>>>> stage Data Validation stage started <<<<<<
[2025-07-30 09:58:49,682: INFO: common]: yaml file: config/config.yaml loaded successfully
[2025-07-30 09:58:49,682: INFO: common]: yaml file: params.yaml loaded successfully
[2025-07-30 09:58:49,683: INFO: common]: yaml file: schema.yaml loaded successfully
[2025-07-30 09:58:49,683: INFO: common]: created directory at: artifacts
[2025-07-30 09:58:49,683: INFO: common]: created directory at: artifacts/data_validation
[2025-07-30 09:58:49,686: INFO: data_validation]: Data validation status: True
[2025-07-30 09:58:49,687: INFO: main]: >>>>>> stage Data Validation stage completed <<<<<<

x==========x
[2025-07-30 09:58:49,687: INFO: main]: >>>>>> stage Data Transformation stage started <<<<<<
[2025-07-30 09:58:49,688: INFO: common]: yaml file: config/config.yaml loaded successfully
[2025-07-30 09:58:49,689: INFO: common]: yaml file: params.yaml loaded successfully
[2025-07-30 09:58:49,690: INFO: common]: yaml file: schema.yaml loaded successfully
[2025-07-30 09:58:49,690: INFO: common]: created directory at: artifacts
[2025-07-30 09:58:49,690: INFO: common]: created directory at: artifacts/data_validation
[2025-07-30 09:58:49,690: INFO: common]: created directory at: artifacts/data_transformation
[2025-07-30 09:58:49,699: INFO: data_transformation]: Splited data into training and test sets
[2025-07-30 09:58:49,700: INFO: data_transformation]: (1279, 12)
[2025-07-30 09:58:49,700: INFO: data_transformation]: (320, 12)
[2025-07-30 09:58:49,700: INFO: main]: >>>>>> stage Data Transformation stage completed <<<<<<

x==========x
[2025-07-30 09:58:49,700: INFO: main]: >>>>>> stage Model Trainer stage started <<<<<<
[2025-07-30 09:58:49,701: INFO: common]: yaml file: config/config.yaml loaded successfully
[2025-07-30 09:58:49,701: INFO: common]: yaml file: params.yaml loaded successfully
[2025-07-30 09:58:49,702: INFO: common]: yaml file: schema.yaml loaded successfully
[2025-07-30 09:58:49,702: INFO: common]: created directory at: artifacts
[2025-07-30 09:58:49,703: INFO: common]: created directory at: artifacts/model_trainer
[2025-07-30 09:58:49,706: INFO: model_trainer]: Model saved to model.joblib in artifacts/model_trainer
[2025-07-30 09:58:49,706: INFO: main]: >>>>>> stage Model Trainer stage completed <<<<<<

x==========x
[2025-07-30 09:58:49,706: INFO: main]: >>>>>> stage Model Evaluation stage started <<<<<<
[2025-07-30 09:58:49,708: INFO: common]: yaml file: config/config.yaml loaded successfully
[2025-07-30 09:58:49,708: INFO: common]: yaml file: params.yaml loaded successfully
[2025-07-30 09:58:49,709: INFO: common]: yaml file: schema.yaml loaded successfully
[2025-07-30 09:58:49,709: INFO: common]: created directory at: artifacts
[2025-07-30 09:58:49,709: INFO: common]: created directory at: artifacts/model_evaluation
[2025-07-30 09:58:49,709: ERROR: main]: ModelEvaluationConfig.__init__() missing 1 required positional argument: 'mlflow_uri'
Traceback (most recent call last):
  File "/Users/saiaakash/Documents/mlops/DS_main/main.py", line 15, in run_stage
    pipeline.main()
  File "/Users/saiaakash/Documents/mlops/DS_main/src/data_science/pipeline/stage_05_model_evaluation.py", line 13, in main
    model_evaluation_config = config.get_model_evaluation_config()
  File "/Users/saiaakash/Documents/mlops/DS_main/src/data_science/config/configuration.py", line 87, in get_model_evaluation_config
    model_evaluation_config = ModelEvaluationConfig(
TypeError: ModelEvaluationConfig.__init__() missing 1 required positional argument: 'mlflow_uri'
[2025-07-30 10:00:07,797: INFO: main]: >>>>>> stage Data Ingestion stage started <<<<<<
[2025-07-30 10:00:07,801: INFO: common]: yaml file: config/config.yaml loaded successfully
[2025-07-30 10:00:07,802: INFO: common]: yaml file: params.yaml loaded successfully
[2025-07-30 10:00:07,803: INFO: common]: yaml file: schema.yaml loaded successfully
[2025-07-30 10:00:07,803: INFO: common]: created directory at: artifacts
[2025-07-30 10:00:07,803: INFO: common]: created directory at: artifacts/data_ingestion
[2025-07-30 10:00:07,803: INFO: data_ingestion]: File already exists of size: 23329
[2025-07-30 10:00:07,805: INFO: main]: >>>>>> stage Data Ingestion stage completed <<<<<<

x==========x
[2025-07-30 10:00:07,805: INFO: main]: >>>>>> stage Data Validation stage started <<<<<<
[2025-07-30 10:00:07,806: INFO: common]: yaml file: config/config.yaml loaded successfully
[2025-07-30 10:00:07,807: INFO: common]: yaml file: params.yaml loaded successfully
[2025-07-30 10:00:07,807: INFO: common]: yaml file: schema.yaml loaded successfully
[2025-07-30 10:00:07,807: INFO: common]: created directory at: artifacts
[2025-07-30 10:00:07,807: INFO: common]: created directory at: artifacts/data_validation
[2025-07-30 10:00:07,813: INFO: data_validation]: Data validation status: True
[2025-07-30 10:00:07,813: INFO: main]: >>>>>> stage Data Validation stage completed <<<<<<

x==========x
[2025-07-30 10:00:07,813: INFO: main]: >>>>>> stage Data Transformation stage started <<<<<<
[2025-07-30 10:00:07,814: INFO: common]: yaml file: config/config.yaml loaded successfully
[2025-07-30 10:00:07,814: INFO: common]: yaml file: params.yaml loaded successfully
[2025-07-30 10:00:07,815: INFO: common]: yaml file: schema.yaml loaded successfully
[2025-07-30 10:00:07,815: INFO: common]: created directory at: artifacts
[2025-07-30 10:00:07,815: INFO: common]: created directory at: artifacts/data_validation
[2025-07-30 10:00:07,815: INFO: common]: created directory at: artifacts/data_transformation
[2025-07-30 10:00:07,827: INFO: data_transformation]: Splited data into training and test sets
[2025-07-30 10:00:07,827: INFO: data_transformation]: (1279, 12)
[2025-07-30 10:00:07,827: INFO: data_transformation]: (320, 12)
[2025-07-30 10:00:07,827: INFO: main]: >>>>>> stage Data Transformation stage completed <<<<<<

x==========x
[2025-07-30 10:00:07,827: INFO: main]: >>>>>> stage Model Trainer stage started <<<<<<
[2025-07-30 10:00:07,829: INFO: common]: yaml file: config/config.yaml loaded successfully
[2025-07-30 10:00:07,829: INFO: common]: yaml file: params.yaml loaded successfully
[2025-07-30 10:00:07,830: INFO: common]: yaml file: schema.yaml loaded successfully
[2025-07-30 10:00:07,830: INFO: common]: created directory at: artifacts
[2025-07-30 10:00:07,830: INFO: common]: created directory at: artifacts/model_trainer
[2025-07-30 10:00:07,838: INFO: model_trainer]: Model saved to model.joblib in artifacts/model_trainer
[2025-07-30 10:00:07,838: INFO: main]: >>>>>> stage Model Trainer stage completed <<<<<<

x==========x
[2025-07-30 10:00:07,838: INFO: main]: >>>>>> stage Model Evaluation stage started <<<<<<
[2025-07-30 10:00:07,839: INFO: common]: yaml file: config/config.yaml loaded successfully
[2025-07-30 10:00:07,840: INFO: common]: yaml file: params.yaml loaded successfully
[2025-07-30 10:00:07,840: INFO: common]: yaml file: schema.yaml loaded successfully
[2025-07-30 10:00:07,840: INFO: common]: created directory at: artifacts
[2025-07-30 10:00:07,840: INFO: common]: created directory at: artifacts/model_evaluation
[2025-07-30 10:00:07,840: ERROR: main]: ModelEvaluationConfig.__init__() missing 1 required positional argument: 'mlflow_uri'
Traceback (most recent call last):
  File "/Users/saiaakash/Documents/mlops/DS_main/main.py", line 15, in run_stage
    pipeline.main()
  File "/Users/saiaakash/Documents/mlops/DS_main/src/data_science/pipeline/stage_05_model_evaluation.py", line 13, in main
    model_evaluation_config = config.get_model_evaluation_config()
  File "/Users/saiaakash/Documents/mlops/DS_main/src/data_science/config/configuration.py", line 87, in get_model_evaluation_config
    model_evaluation_config = ModelEvaluationConfig(
TypeError: ModelEvaluationConfig.__init__() missing 1 required positional argument: 'mlflow_uri'
[2025-07-30 10:01:26,369: INFO: main]: >>>>>> stage Data Ingestion stage started <<<<<<
[2025-07-30 10:01:26,373: INFO: common]: yaml file: config/config.yaml loaded successfully
[2025-07-30 10:01:26,375: INFO: common]: yaml file: params.yaml loaded successfully
[2025-07-30 10:01:26,376: INFO: common]: yaml file: schema.yaml loaded successfully
[2025-07-30 10:01:26,376: INFO: common]: created directory at: artifacts
[2025-07-30 10:01:26,376: INFO: common]: created directory at: artifacts/data_ingestion
[2025-07-30 10:01:26,376: INFO: data_ingestion]: File already exists of size: 23329
[2025-07-30 10:01:26,377: INFO: main]: >>>>>> stage Data Ingestion stage completed <<<<<<

x==========x
[2025-07-30 10:01:26,377: INFO: main]: >>>>>> stage Data Validation stage started <<<<<<
[2025-07-30 10:01:26,379: INFO: common]: yaml file: config/config.yaml loaded successfully
[2025-07-30 10:01:26,379: INFO: common]: yaml file: params.yaml loaded successfully
[2025-07-30 10:01:26,380: INFO: common]: yaml file: schema.yaml loaded successfully
[2025-07-30 10:01:26,380: INFO: common]: created directory at: artifacts
[2025-07-30 10:01:26,380: INFO: common]: created directory at: artifacts/data_validation
[2025-07-30 10:01:26,385: INFO: data_validation]: Data validation status: True
[2025-07-30 10:01:26,385: INFO: main]: >>>>>> stage Data Validation stage completed <<<<<<

x==========x
[2025-07-30 10:01:26,385: INFO: main]: >>>>>> stage Data Transformation stage started <<<<<<
[2025-07-30 10:01:26,387: INFO: common]: yaml file: config/config.yaml loaded successfully
[2025-07-30 10:01:26,387: INFO: common]: yaml file: params.yaml loaded successfully
[2025-07-30 10:01:26,388: INFO: common]: yaml file: schema.yaml loaded successfully
[2025-07-30 10:01:26,388: INFO: common]: created directory at: artifacts
[2025-07-30 10:01:26,388: INFO: common]: created directory at: artifacts/data_validation
[2025-07-30 10:01:26,388: INFO: common]: created directory at: artifacts/data_transformation
[2025-07-30 10:01:26,398: INFO: data_transformation]: Splited data into training and test sets
[2025-07-30 10:01:26,398: INFO: data_transformation]: (1279, 12)
[2025-07-30 10:01:26,398: INFO: data_transformation]: (320, 12)
[2025-07-30 10:01:26,398: INFO: main]: >>>>>> stage Data Transformation stage completed <<<<<<

x==========x
[2025-07-30 10:01:26,398: INFO: main]: >>>>>> stage Model Trainer stage started <<<<<<
[2025-07-30 10:01:26,399: INFO: common]: yaml file: config/config.yaml loaded successfully
[2025-07-30 10:01:26,399: INFO: common]: yaml file: params.yaml loaded successfully
[2025-07-30 10:01:26,400: INFO: common]: yaml file: schema.yaml loaded successfully
[2025-07-30 10:01:26,401: INFO: common]: created directory at: artifacts
[2025-07-30 10:01:26,401: INFO: common]: created directory at: artifacts/model_trainer
[2025-07-30 10:01:26,406: INFO: model_trainer]: Model saved to model.joblib in artifacts/model_trainer
[2025-07-30 10:01:26,406: INFO: main]: >>>>>> stage Model Trainer stage completed <<<<<<

x==========x
[2025-07-30 10:01:26,406: INFO: main]: >>>>>> stage Model Evaluation stage started <<<<<<
[2025-07-30 10:01:26,407: INFO: common]: yaml file: config/config.yaml loaded successfully
[2025-07-30 10:01:26,407: INFO: common]: yaml file: params.yaml loaded successfully
[2025-07-30 10:01:26,408: INFO: common]: yaml file: schema.yaml loaded successfully
[2025-07-30 10:01:26,408: INFO: common]: created directory at: artifacts
[2025-07-30 10:01:26,408: INFO: common]: created directory at: artifacts/model_evaluation
[2025-07-30 10:01:26,408: ERROR: main]: ModelEvaluationConfig.__init__() missing 1 required positional argument: 'mlflow_uri'
Traceback (most recent call last):
  File "/Users/saiaakash/Documents/mlops/DS_main/main.py", line 15, in run_stage
    pipeline.main()
  File "/Users/saiaakash/Documents/mlops/DS_main/src/data_science/pipeline/stage_05_model_evaluation.py", line 13, in main
    model_evaluation_config = config.get_model_evaluation_config()
  File "/Users/saiaakash/Documents/mlops/DS_main/src/data_science/config/configuration.py", line 87, in get_model_evaluation_config
    model_evaluation_config = ModelEvaluationConfig(
TypeError: ModelEvaluationConfig.__init__() missing 1 required positional argument: 'mlflow_uri'
[2025-07-30 10:04:23,298: INFO: main]: >>>>>> stage Data Ingestion stage started <<<<<<
[2025-07-30 10:04:23,302: INFO: common]: yaml file: config/config.yaml loaded successfully
[2025-07-30 10:04:23,304: INFO: common]: yaml file: params.yaml loaded successfully
[2025-07-30 10:04:23,305: INFO: common]: yaml file: schema.yaml loaded successfully
[2025-07-30 10:04:23,305: INFO: common]: created directory at: artifacts
[2025-07-30 10:04:23,305: INFO: common]: created directory at: artifacts/data_ingestion
[2025-07-30 10:04:23,305: INFO: data_ingestion]: File already exists of size: 23329
[2025-07-30 10:04:23,307: INFO: main]: >>>>>> stage Data Ingestion stage completed <<<<<<

x==========x
[2025-07-30 10:04:23,307: INFO: main]: >>>>>> stage Data Validation stage started <<<<<<
[2025-07-30 10:04:23,308: INFO: common]: yaml file: config/config.yaml loaded successfully
[2025-07-30 10:04:23,309: INFO: common]: yaml file: params.yaml loaded successfully
[2025-07-30 10:04:23,310: INFO: common]: yaml file: schema.yaml loaded successfully
[2025-07-30 10:04:23,310: INFO: common]: created directory at: artifacts
[2025-07-30 10:04:23,310: INFO: common]: created directory at: artifacts/data_validation
[2025-07-30 10:04:23,317: INFO: data_validation]: Data validation status: True
[2025-07-30 10:04:23,317: INFO: main]: >>>>>> stage Data Validation stage completed <<<<<<

x==========x
[2025-07-30 10:04:23,317: INFO: main]: >>>>>> stage Data Transformation stage started <<<<<<
[2025-07-30 10:04:23,319: INFO: common]: yaml file: config/config.yaml loaded successfully
[2025-07-30 10:04:23,320: INFO: common]: yaml file: params.yaml loaded successfully
[2025-07-30 10:04:23,323: INFO: common]: yaml file: schema.yaml loaded successfully
[2025-07-30 10:04:23,324: INFO: common]: created directory at: artifacts
[2025-07-30 10:04:23,324: INFO: common]: created directory at: artifacts/data_validation
[2025-07-30 10:04:23,324: INFO: common]: created directory at: artifacts/data_transformation
[2025-07-30 10:04:23,406: INFO: data_transformation]: Splited data into training and test sets
[2025-07-30 10:04:23,406: INFO: data_transformation]: (1279, 12)
[2025-07-30 10:04:23,406: INFO: data_transformation]: (320, 12)
[2025-07-30 10:04:23,407: INFO: main]: >>>>>> stage Data Transformation stage completed <<<<<<

x==========x
[2025-07-30 10:04:23,407: INFO: main]: >>>>>> stage Model Trainer stage started <<<<<<
[2025-07-30 10:04:23,421: INFO: common]: yaml file: config/config.yaml loaded successfully
[2025-07-30 10:04:23,421: INFO: common]: yaml file: params.yaml loaded successfully
[2025-07-30 10:04:23,422: INFO: common]: yaml file: schema.yaml loaded successfully
[2025-07-30 10:04:23,423: INFO: common]: created directory at: artifacts
[2025-07-30 10:04:23,423: INFO: common]: created directory at: artifacts/model_trainer
[2025-07-30 10:04:23,431: INFO: model_trainer]: Model saved to model.joblib in artifacts/model_trainer
[2025-07-30 10:04:23,431: INFO: main]: >>>>>> stage Model Trainer stage completed <<<<<<

x==========x
[2025-07-30 10:04:23,431: INFO: main]: >>>>>> stage Model Evaluation stage started <<<<<<
[2025-07-30 10:04:23,432: INFO: common]: yaml file: config/config.yaml loaded successfully
[2025-07-30 10:04:23,433: INFO: common]: yaml file: params.yaml loaded successfully
[2025-07-30 10:04:23,434: INFO: common]: yaml file: schema.yaml loaded successfully
[2025-07-30 10:04:23,434: INFO: common]: created directory at: artifacts
[2025-07-30 10:04:23,435: INFO: common]: created directory at: artifacts/model_evaluation
[2025-07-30 10:04:23,435: ERROR: main]: ModelEvaluationConfig.__init__() missing 1 required positional argument: 'mlflow_uri'
Traceback (most recent call last):
  File "/Users/saiaakash/Documents/mlops/DS_main/main.py", line 15, in run_stage
    pipeline.main()
  File "/Users/saiaakash/Documents/mlops/DS_main/src/data_science/pipeline/stage_05_model_evaluation.py", line 13, in main
    model_evaluation_config = config.get_model_evaluation_config()
  File "/Users/saiaakash/Documents/mlops/DS_main/src/data_science/config/configuration.py", line 87, in get_model_evaluation_config
    model_evaluation_config = ModelEvaluationConfig(
TypeError: ModelEvaluationConfig.__init__() missing 1 required positional argument: 'mlflow_uri'
[2025-07-30 10:06:04,241: INFO: main]: >>>>>> stage Data Ingestion stage started <<<<<<
[2025-07-30 10:06:04,244: INFO: common]: yaml file: config/config.yaml loaded successfully
[2025-07-30 10:06:04,246: INFO: common]: yaml file: params.yaml loaded successfully
[2025-07-30 10:06:04,247: INFO: common]: yaml file: schema.yaml loaded successfully
[2025-07-30 10:06:04,247: INFO: common]: created directory at: artifacts
[2025-07-30 10:06:04,247: INFO: common]: created directory at: artifacts/data_ingestion
[2025-07-30 10:06:04,247: INFO: data_ingestion]: File already exists of size: 23329
[2025-07-30 10:06:04,249: INFO: main]: >>>>>> stage Data Ingestion stage completed <<<<<<

x==========x
[2025-07-30 10:06:04,249: INFO: main]: >>>>>> stage Data Validation stage started <<<<<<
[2025-07-30 10:06:04,251: INFO: common]: yaml file: config/config.yaml loaded successfully
[2025-07-30 10:06:04,251: INFO: common]: yaml file: params.yaml loaded successfully
[2025-07-30 10:06:04,252: INFO: common]: yaml file: schema.yaml loaded successfully
[2025-07-30 10:06:04,252: INFO: common]: created directory at: artifacts
[2025-07-30 10:06:04,252: INFO: common]: created directory at: artifacts/data_validation
[2025-07-30 10:06:04,257: INFO: data_validation]: Data validation status: True
[2025-07-30 10:06:04,257: INFO: main]: >>>>>> stage Data Validation stage completed <<<<<<

x==========x
[2025-07-30 10:06:04,257: INFO: main]: >>>>>> stage Data Transformation stage started <<<<<<
[2025-07-30 10:06:04,259: INFO: common]: yaml file: config/config.yaml loaded successfully
[2025-07-30 10:06:04,259: INFO: common]: yaml file: params.yaml loaded successfully
[2025-07-30 10:06:04,260: INFO: common]: yaml file: schema.yaml loaded successfully
[2025-07-30 10:06:04,260: INFO: common]: created directory at: artifacts
[2025-07-30 10:06:04,260: INFO: common]: created directory at: artifacts/data_validation
[2025-07-30 10:06:04,260: INFO: common]: created directory at: artifacts/data_transformation
[2025-07-30 10:06:04,271: INFO: data_transformation]: Splited data into training and test sets
[2025-07-30 10:06:04,271: INFO: data_transformation]: (1279, 12)
[2025-07-30 10:06:04,271: INFO: data_transformation]: (320, 12)
[2025-07-30 10:06:04,271: INFO: main]: >>>>>> stage Data Transformation stage completed <<<<<<

x==========x
[2025-07-30 10:06:04,271: INFO: main]: >>>>>> stage Model Trainer stage started <<<<<<
[2025-07-30 10:06:04,272: INFO: common]: yaml file: config/config.yaml loaded successfully
[2025-07-30 10:06:04,273: INFO: common]: yaml file: params.yaml loaded successfully
[2025-07-30 10:06:04,273: INFO: common]: yaml file: schema.yaml loaded successfully
[2025-07-30 10:06:04,273: INFO: common]: created directory at: artifacts
[2025-07-30 10:06:04,273: INFO: common]: created directory at: artifacts/model_trainer
[2025-07-30 10:06:04,283: INFO: model_trainer]: Model saved to model.joblib in artifacts/model_trainer
[2025-07-30 10:06:04,284: INFO: main]: >>>>>> stage Model Trainer stage completed <<<<<<

x==========x
[2025-07-30 10:06:04,284: INFO: main]: >>>>>> stage Model Evaluation stage started <<<<<<
[2025-07-30 10:06:04,285: INFO: common]: yaml file: config/config.yaml loaded successfully
[2025-07-30 10:06:04,285: INFO: common]: yaml file: params.yaml loaded successfully
[2025-07-30 10:06:04,286: INFO: common]: yaml file: schema.yaml loaded successfully
[2025-07-30 10:06:04,286: INFO: common]: created directory at: artifacts
[2025-07-30 10:06:04,286: INFO: common]: created directory at: artifacts/model_evaluation
[2025-07-30 10:06:05,026: INFO: common]: json file saved at: artifacts/model_evaluation/metrics.json
[2025-07-30 10:06:09,810: ERROR: main]: INTERNAL_ERROR: Response: {'error': 'unsupported endpoint, please contact support@dagshub.com'}
Traceback (most recent call last):
  File "/Users/saiaakash/Documents/mlops/DS_main/main.py", line 15, in run_stage
    pipeline.main()
  File "/Users/saiaakash/Documents/mlops/DS_main/src/data_science/pipeline/stage_05_model_evaluation.py", line 15, in main
    model_evaluation.log_into_mlflow() # This method handles the full evaluation and logging process
  File "/Users/saiaakash/Documents/mlops/DS_main/src/data_science/components/model_evaluation.py", line 52, in log_into_mlflow
    mlflow.sklearn.log_model(model, "model", registered_model_name=self.config.registered_model_name)
  File "/opt/anaconda3/envs/mlpipe/lib/python3.10/site-packages/mlflow/sklearn/__init__.py", line 426, in log_model
    return Model.log(
  File "/opt/anaconda3/envs/mlpipe/lib/python3.10/site-packages/mlflow/models/model.py", line 1161, in log
    model = mlflow.initialize_logged_model(
  File "/opt/anaconda3/envs/mlpipe/lib/python3.10/site-packages/mlflow/tracking/fluent.py", line 2130, in initialize_logged_model
    model = _create_logged_model(
  File "/opt/anaconda3/envs/mlpipe/lib/python3.10/site-packages/mlflow/tracking/fluent.py", line 2257, in _create_logged_model
    return MlflowClient().create_logged_model(
  File "/opt/anaconda3/envs/mlpipe/lib/python3.10/site-packages/mlflow/tracking/client.py", line 5369, in create_logged_model
    return self._tracking_client.create_logged_model(
  File "/opt/anaconda3/envs/mlpipe/lib/python3.10/site-packages/mlflow/tracking/_tracking_service/client.py", line 824, in create_logged_model
    return self.store.create_logged_model(
  File "/opt/anaconda3/envs/mlpipe/lib/python3.10/site-packages/mlflow/store/tracking/rest_store.py", line 936, in create_logged_model
    response_proto = self._call_endpoint(CreateLoggedModel, req_body)
  File "/opt/anaconda3/envs/mlpipe/lib/python3.10/site-packages/mlflow/store/tracking/rest_store.py", line 135, in _call_endpoint
    return call_endpoint(
  File "/opt/anaconda3/envs/mlpipe/lib/python3.10/site-packages/mlflow/utils/rest_utils.py", line 594, in call_endpoint
    response = verify_rest_response(response, endpoint)
  File "/opt/anaconda3/envs/mlpipe/lib/python3.10/site-packages/mlflow/utils/rest_utils.py", line 308, in verify_rest_response
    raise RestException(json.loads(response.text))
mlflow.exceptions.RestException: INTERNAL_ERROR: Response: {'error': 'unsupported endpoint, please contact support@dagshub.com'}
[2025-07-30 10:10:02,540: INFO: main]: >>>>>> stage Data Ingestion stage started <<<<<<
[2025-07-30 10:10:02,542: INFO: common]: yaml file: config/config.yaml loaded successfully
[2025-07-30 10:10:02,543: INFO: common]: yaml file: params.yaml loaded successfully
[2025-07-30 10:10:02,544: INFO: common]: yaml file: schema.yaml loaded successfully
[2025-07-30 10:10:02,544: INFO: common]: created directory at: artifacts
[2025-07-30 10:10:02,544: INFO: common]: created directory at: artifacts/data_ingestion
[2025-07-30 10:10:02,544: INFO: data_ingestion]: File already exists of size: 23329
[2025-07-30 10:10:02,546: INFO: main]: >>>>>> stage Data Ingestion stage completed <<<<<<

x==========x
[2025-07-30 10:10:02,546: INFO: main]: >>>>>> stage Data Validation stage started <<<<<<
[2025-07-30 10:10:02,547: INFO: common]: yaml file: config/config.yaml loaded successfully
[2025-07-30 10:10:02,548: INFO: common]: yaml file: params.yaml loaded successfully
[2025-07-30 10:10:02,548: INFO: common]: yaml file: schema.yaml loaded successfully
[2025-07-30 10:10:02,549: INFO: common]: created directory at: artifacts
[2025-07-30 10:10:02,549: INFO: common]: created directory at: artifacts/data_validation
[2025-07-30 10:10:02,554: INFO: data_validation]: Data validation status: True
[2025-07-30 10:10:02,554: INFO: main]: >>>>>> stage Data Validation stage completed <<<<<<

x==========x
[2025-07-30 10:10:02,554: INFO: main]: >>>>>> stage Data Transformation stage started <<<<<<
[2025-07-30 10:10:02,556: INFO: common]: yaml file: config/config.yaml loaded successfully
[2025-07-30 10:10:02,556: INFO: common]: yaml file: params.yaml loaded successfully
[2025-07-30 10:10:02,557: INFO: common]: yaml file: schema.yaml loaded successfully
[2025-07-30 10:10:02,557: INFO: common]: created directory at: artifacts
[2025-07-30 10:10:02,557: INFO: common]: created directory at: artifacts/data_validation
[2025-07-30 10:10:02,557: INFO: common]: created directory at: artifacts/data_transformation
[2025-07-30 10:10:02,567: INFO: data_transformation]: Splited data into training and test sets
[2025-07-30 10:10:02,567: INFO: data_transformation]: (1279, 12)
[2025-07-30 10:10:02,567: INFO: data_transformation]: (320, 12)
[2025-07-30 10:10:02,568: INFO: main]: >>>>>> stage Data Transformation stage completed <<<<<<

x==========x
[2025-07-30 10:10:02,568: INFO: main]: >>>>>> stage Model Trainer stage started <<<<<<
[2025-07-30 10:10:02,570: INFO: common]: yaml file: config/config.yaml loaded successfully
[2025-07-30 10:10:02,570: INFO: common]: yaml file: params.yaml loaded successfully
[2025-07-30 10:10:02,571: INFO: common]: yaml file: schema.yaml loaded successfully
[2025-07-30 10:10:02,571: INFO: common]: created directory at: artifacts
[2025-07-30 10:10:02,571: INFO: common]: created directory at: artifacts/model_trainer
[2025-07-30 10:10:02,579: INFO: model_trainer]: Model saved to model.joblib in artifacts/model_trainer
[2025-07-30 10:10:02,579: INFO: main]: >>>>>> stage Model Trainer stage completed <<<<<<

x==========x
[2025-07-30 10:10:02,579: INFO: main]: >>>>>> stage Model Evaluation stage started <<<<<<
[2025-07-30 10:10:02,581: INFO: common]: yaml file: config/config.yaml loaded successfully
[2025-07-30 10:10:02,581: INFO: common]: yaml file: params.yaml loaded successfully
[2025-07-30 10:10:02,582: INFO: common]: yaml file: schema.yaml loaded successfully
[2025-07-30 10:10:02,582: INFO: common]: created directory at: artifacts
[2025-07-30 10:10:02,582: INFO: common]: created directory at: artifacts/model_evaluation
[2025-07-30 10:10:03,316: INFO: common]: json file saved at: artifacts/model_evaluation/metrics.json
[2025-07-30 10:10:03,316: INFO: model_evaluation]: Metrics saved to artifacts/model_evaluation/metrics.json
[2025-07-30 10:10:08,177: ERROR: main]: INTERNAL_ERROR: Response: {'error': 'unsupported endpoint, please contact support@dagshub.com'}
Traceback (most recent call last):
  File "/Users/saiaakash/Documents/mlops/DS_main/main.py", line 15, in run_stage
    pipeline.main()
  File "/Users/saiaakash/Documents/mlops/DS_main/src/data_science/pipeline/stage_05_model_evaluation.py", line 15, in main
    model_evaluation.log_into_mlflow() # This method handles the full evaluation and logging process
  File "/Users/saiaakash/Documents/mlops/DS_main/src/data_science/components/model_evaluation.py", line 61, in log_into_mlflow
    mlflow.sklearn.log_model(
  File "/opt/anaconda3/envs/mlpipe/lib/python3.10/site-packages/mlflow/sklearn/__init__.py", line 426, in log_model
    return Model.log(
  File "/opt/anaconda3/envs/mlpipe/lib/python3.10/site-packages/mlflow/models/model.py", line 1161, in log
    model = mlflow.initialize_logged_model(
  File "/opt/anaconda3/envs/mlpipe/lib/python3.10/site-packages/mlflow/tracking/fluent.py", line 2130, in initialize_logged_model
    model = _create_logged_model(
  File "/opt/anaconda3/envs/mlpipe/lib/python3.10/site-packages/mlflow/tracking/fluent.py", line 2257, in _create_logged_model
    return MlflowClient().create_logged_model(
  File "/opt/anaconda3/envs/mlpipe/lib/python3.10/site-packages/mlflow/tracking/client.py", line 5369, in create_logged_model
    return self._tracking_client.create_logged_model(
  File "/opt/anaconda3/envs/mlpipe/lib/python3.10/site-packages/mlflow/tracking/_tracking_service/client.py", line 824, in create_logged_model
    return self.store.create_logged_model(
  File "/opt/anaconda3/envs/mlpipe/lib/python3.10/site-packages/mlflow/store/tracking/rest_store.py", line 936, in create_logged_model
    response_proto = self._call_endpoint(CreateLoggedModel, req_body)
  File "/opt/anaconda3/envs/mlpipe/lib/python3.10/site-packages/mlflow/store/tracking/rest_store.py", line 135, in _call_endpoint
    return call_endpoint(
  File "/opt/anaconda3/envs/mlpipe/lib/python3.10/site-packages/mlflow/utils/rest_utils.py", line 594, in call_endpoint
    response = verify_rest_response(response, endpoint)
  File "/opt/anaconda3/envs/mlpipe/lib/python3.10/site-packages/mlflow/utils/rest_utils.py", line 308, in verify_rest_response
    raise RestException(json.loads(response.text))
mlflow.exceptions.RestException: INTERNAL_ERROR: Response: {'error': 'unsupported endpoint, please contact support@dagshub.com'}
[2025-07-30 10:10:59,076: INFO: main]: >>>>>> stage Data Ingestion stage started <<<<<<
[2025-07-30 10:10:59,079: INFO: common]: yaml file: config/config.yaml loaded successfully
[2025-07-30 10:10:59,080: INFO: common]: yaml file: params.yaml loaded successfully
[2025-07-30 10:10:59,081: INFO: common]: yaml file: schema.yaml loaded successfully
[2025-07-30 10:10:59,081: INFO: common]: created directory at: artifacts
[2025-07-30 10:10:59,081: INFO: common]: created directory at: artifacts/data_ingestion
[2025-07-30 10:10:59,081: INFO: data_ingestion]: File already exists of size: 23329
[2025-07-30 10:10:59,083: INFO: main]: >>>>>> stage Data Ingestion stage completed <<<<<<

x==========x
[2025-07-30 10:10:59,083: INFO: main]: >>>>>> stage Data Validation stage started <<<<<<
[2025-07-30 10:10:59,084: INFO: common]: yaml file: config/config.yaml loaded successfully
[2025-07-30 10:10:59,085: INFO: common]: yaml file: params.yaml loaded successfully
[2025-07-30 10:10:59,086: INFO: common]: yaml file: schema.yaml loaded successfully
[2025-07-30 10:10:59,086: INFO: common]: created directory at: artifacts
[2025-07-30 10:10:59,086: INFO: common]: created directory at: artifacts/data_validation
[2025-07-30 10:10:59,092: INFO: data_validation]: Data validation status: True
[2025-07-30 10:10:59,092: INFO: main]: >>>>>> stage Data Validation stage completed <<<<<<

x==========x
[2025-07-30 10:10:59,092: INFO: main]: >>>>>> stage Data Transformation stage started <<<<<<
[2025-07-30 10:10:59,094: INFO: common]: yaml file: config/config.yaml loaded successfully
[2025-07-30 10:10:59,094: INFO: common]: yaml file: params.yaml loaded successfully
[2025-07-30 10:10:59,095: INFO: common]: yaml file: schema.yaml loaded successfully
[2025-07-30 10:10:59,095: INFO: common]: created directory at: artifacts
[2025-07-30 10:10:59,095: INFO: common]: created directory at: artifacts/data_validation
[2025-07-30 10:10:59,095: INFO: common]: created directory at: artifacts/data_transformation
[2025-07-30 10:10:59,106: INFO: data_transformation]: Splited data into training and test sets
[2025-07-30 10:10:59,106: INFO: data_transformation]: (1279, 12)
[2025-07-30 10:10:59,106: INFO: data_transformation]: (320, 12)
[2025-07-30 10:10:59,107: INFO: main]: >>>>>> stage Data Transformation stage completed <<<<<<

x==========x
[2025-07-30 10:10:59,107: INFO: main]: >>>>>> stage Model Trainer stage started <<<<<<
[2025-07-30 10:10:59,108: INFO: common]: yaml file: config/config.yaml loaded successfully
[2025-07-30 10:10:59,108: INFO: common]: yaml file: params.yaml loaded successfully
[2025-07-30 10:10:59,109: INFO: common]: yaml file: schema.yaml loaded successfully
[2025-07-30 10:10:59,109: INFO: common]: created directory at: artifacts
[2025-07-30 10:10:59,109: INFO: common]: created directory at: artifacts/model_trainer
[2025-07-30 10:10:59,116: INFO: model_trainer]: Model saved to model.joblib in artifacts/model_trainer
[2025-07-30 10:10:59,116: INFO: main]: >>>>>> stage Model Trainer stage completed <<<<<<

x==========x
[2025-07-30 10:10:59,116: INFO: main]: >>>>>> stage Model Evaluation stage started <<<<<<
[2025-07-30 10:10:59,118: INFO: common]: yaml file: config/config.yaml loaded successfully
[2025-07-30 10:10:59,118: INFO: common]: yaml file: params.yaml loaded successfully
[2025-07-30 10:10:59,119: INFO: common]: yaml file: schema.yaml loaded successfully
[2025-07-30 10:10:59,119: INFO: common]: created directory at: artifacts
[2025-07-30 10:10:59,119: INFO: common]: created directory at: artifacts/model_evaluation
[2025-07-30 10:10:59,896: INFO: common]: json file saved at: artifacts/model_evaluation/metrics.json
[2025-07-30 10:10:59,896: INFO: model_evaluation]: Metrics saved to artifacts/model_evaluation/metrics.json
[2025-07-30 10:11:05,115: ERROR: main]: INTERNAL_ERROR: Response: {'error': 'unsupported endpoint, please contact support@dagshub.com'}
Traceback (most recent call last):
  File "/Users/saiaakash/Documents/mlops/DS_main/main.py", line 15, in run_stage
    pipeline.main()
  File "/Users/saiaakash/Documents/mlops/DS_main/src/data_science/pipeline/stage_05_model_evaluation.py", line 15, in main
    model_evaluation.log_into_mlflow() # This method handles the full evaluation and logging process
  File "/Users/saiaakash/Documents/mlops/DS_main/src/data_science/components/model_evaluation.py", line 62, in log_into_mlflow
    mlflow.sklearn.log_model(
  File "/opt/anaconda3/envs/mlpipe/lib/python3.10/site-packages/mlflow/sklearn/__init__.py", line 426, in log_model
    return Model.log(
  File "/opt/anaconda3/envs/mlpipe/lib/python3.10/site-packages/mlflow/models/model.py", line 1161, in log
    model = mlflow.initialize_logged_model(
  File "/opt/anaconda3/envs/mlpipe/lib/python3.10/site-packages/mlflow/tracking/fluent.py", line 2130, in initialize_logged_model
    model = _create_logged_model(
  File "/opt/anaconda3/envs/mlpipe/lib/python3.10/site-packages/mlflow/tracking/fluent.py", line 2257, in _create_logged_model
    return MlflowClient().create_logged_model(
  File "/opt/anaconda3/envs/mlpipe/lib/python3.10/site-packages/mlflow/tracking/client.py", line 5369, in create_logged_model
    return self._tracking_client.create_logged_model(
  File "/opt/anaconda3/envs/mlpipe/lib/python3.10/site-packages/mlflow/tracking/_tracking_service/client.py", line 824, in create_logged_model
    return self.store.create_logged_model(
  File "/opt/anaconda3/envs/mlpipe/lib/python3.10/site-packages/mlflow/store/tracking/rest_store.py", line 936, in create_logged_model
    response_proto = self._call_endpoint(CreateLoggedModel, req_body)
  File "/opt/anaconda3/envs/mlpipe/lib/python3.10/site-packages/mlflow/store/tracking/rest_store.py", line 135, in _call_endpoint
    return call_endpoint(
  File "/opt/anaconda3/envs/mlpipe/lib/python3.10/site-packages/mlflow/utils/rest_utils.py", line 594, in call_endpoint
    response = verify_rest_response(response, endpoint)
  File "/opt/anaconda3/envs/mlpipe/lib/python3.10/site-packages/mlflow/utils/rest_utils.py", line 308, in verify_rest_response
    raise RestException(json.loads(response.text))
mlflow.exceptions.RestException: INTERNAL_ERROR: Response: {'error': 'unsupported endpoint, please contact support@dagshub.com'}
[2025-07-30 10:12:08,573: INFO: main]: >>>>>> stage Data Ingestion stage started <<<<<<
[2025-07-30 10:12:08,577: INFO: common]: yaml file: config/config.yaml loaded successfully
[2025-07-30 10:12:08,578: INFO: common]: yaml file: params.yaml loaded successfully
[2025-07-30 10:12:08,579: INFO: common]: yaml file: schema.yaml loaded successfully
[2025-07-30 10:12:08,579: INFO: common]: created directory at: artifacts
[2025-07-30 10:12:08,579: INFO: common]: created directory at: artifacts/data_ingestion
[2025-07-30 10:12:08,579: INFO: data_ingestion]: File already exists of size: 23329
[2025-07-30 10:12:08,581: INFO: main]: >>>>>> stage Data Ingestion stage completed <<<<<<

x==========x
[2025-07-30 10:12:08,581: INFO: main]: >>>>>> stage Data Validation stage started <<<<<<
[2025-07-30 10:12:08,582: INFO: common]: yaml file: config/config.yaml loaded successfully
[2025-07-30 10:12:08,582: INFO: common]: yaml file: params.yaml loaded successfully
[2025-07-30 10:12:08,583: INFO: common]: yaml file: schema.yaml loaded successfully
[2025-07-30 10:12:08,583: INFO: common]: created directory at: artifacts
[2025-07-30 10:12:08,583: INFO: common]: created directory at: artifacts/data_validation
[2025-07-30 10:12:08,589: INFO: data_validation]: Data validation status: True
[2025-07-30 10:12:08,589: INFO: main]: >>>>>> stage Data Validation stage completed <<<<<<

x==========x
[2025-07-30 10:12:08,589: INFO: main]: >>>>>> stage Data Transformation stage started <<<<<<
[2025-07-30 10:12:08,590: INFO: common]: yaml file: config/config.yaml loaded successfully
[2025-07-30 10:12:08,591: INFO: common]: yaml file: params.yaml loaded successfully
[2025-07-30 10:12:08,591: INFO: common]: yaml file: schema.yaml loaded successfully
[2025-07-30 10:12:08,591: INFO: common]: created directory at: artifacts
[2025-07-30 10:12:08,592: INFO: common]: created directory at: artifacts/data_validation
[2025-07-30 10:12:08,592: INFO: common]: created directory at: artifacts/data_transformation
[2025-07-30 10:12:08,602: INFO: data_transformation]: Splited data into training and test sets
[2025-07-30 10:12:08,602: INFO: data_transformation]: (1279, 12)
[2025-07-30 10:12:08,602: INFO: data_transformation]: (320, 12)
[2025-07-30 10:12:08,602: INFO: main]: >>>>>> stage Data Transformation stage completed <<<<<<

x==========x
[2025-07-30 10:12:08,602: INFO: main]: >>>>>> stage Model Trainer stage started <<<<<<
[2025-07-30 10:12:08,604: INFO: common]: yaml file: config/config.yaml loaded successfully
[2025-07-30 10:12:08,604: INFO: common]: yaml file: params.yaml loaded successfully
[2025-07-30 10:12:08,605: INFO: common]: yaml file: schema.yaml loaded successfully
[2025-07-30 10:12:08,605: INFO: common]: created directory at: artifacts
[2025-07-30 10:12:08,605: INFO: common]: created directory at: artifacts/model_trainer
[2025-07-30 10:12:08,612: INFO: model_trainer]: Model saved to model.joblib in artifacts/model_trainer
[2025-07-30 10:12:08,612: INFO: main]: >>>>>> stage Model Trainer stage completed <<<<<<

x==========x
[2025-07-30 10:12:08,612: INFO: main]: >>>>>> stage Model Evaluation stage started <<<<<<
[2025-07-30 10:12:08,613: INFO: common]: yaml file: config/config.yaml loaded successfully
[2025-07-30 10:12:08,613: INFO: common]: yaml file: params.yaml loaded successfully
[2025-07-30 10:12:08,614: INFO: common]: yaml file: schema.yaml loaded successfully
[2025-07-30 10:12:08,614: INFO: common]: created directory at: artifacts
[2025-07-30 10:12:08,614: INFO: common]: created directory at: artifacts/model_evaluation
[2025-07-30 10:12:09,393: INFO: common]: json file saved at: artifacts/model_evaluation/metrics.json
[2025-07-30 10:12:09,393: INFO: model_evaluation]: Metrics saved to artifacts/model_evaluation/metrics.json
[2025-07-30 10:12:14,638: ERROR: main]: INTERNAL_ERROR: Response: {'error': 'unsupported endpoint, please contact support@dagshub.com'}
Traceback (most recent call last):
  File "/Users/saiaakash/Documents/mlops/DS_main/main.py", line 15, in run_stage
    pipeline.main()
  File "/Users/saiaakash/Documents/mlops/DS_main/src/data_science/pipeline/stage_05_model_evaluation.py", line 15, in main
    model_evaluation.log_into_mlflow() # This method handles the full evaluation and logging process
  File "/Users/saiaakash/Documents/mlops/DS_main/src/data_science/components/model_evaluation.py", line 62, in log_into_mlflow
    mlflow.sklearn.log_model(
  File "/opt/anaconda3/envs/mlpipe/lib/python3.10/site-packages/mlflow/sklearn/__init__.py", line 426, in log_model
    return Model.log(
  File "/opt/anaconda3/envs/mlpipe/lib/python3.10/site-packages/mlflow/models/model.py", line 1161, in log
    model = mlflow.initialize_logged_model(
  File "/opt/anaconda3/envs/mlpipe/lib/python3.10/site-packages/mlflow/tracking/fluent.py", line 2130, in initialize_logged_model
    model = _create_logged_model(
  File "/opt/anaconda3/envs/mlpipe/lib/python3.10/site-packages/mlflow/tracking/fluent.py", line 2257, in _create_logged_model
    return MlflowClient().create_logged_model(
  File "/opt/anaconda3/envs/mlpipe/lib/python3.10/site-packages/mlflow/tracking/client.py", line 5369, in create_logged_model
    return self._tracking_client.create_logged_model(
  File "/opt/anaconda3/envs/mlpipe/lib/python3.10/site-packages/mlflow/tracking/_tracking_service/client.py", line 824, in create_logged_model
    return self.store.create_logged_model(
  File "/opt/anaconda3/envs/mlpipe/lib/python3.10/site-packages/mlflow/store/tracking/rest_store.py", line 936, in create_logged_model
    response_proto = self._call_endpoint(CreateLoggedModel, req_body)
  File "/opt/anaconda3/envs/mlpipe/lib/python3.10/site-packages/mlflow/store/tracking/rest_store.py", line 135, in _call_endpoint
    return call_endpoint(
  File "/opt/anaconda3/envs/mlpipe/lib/python3.10/site-packages/mlflow/utils/rest_utils.py", line 594, in call_endpoint
    response = verify_rest_response(response, endpoint)
  File "/opt/anaconda3/envs/mlpipe/lib/python3.10/site-packages/mlflow/utils/rest_utils.py", line 308, in verify_rest_response
    raise RestException(json.loads(response.text))
mlflow.exceptions.RestException: INTERNAL_ERROR: Response: {'error': 'unsupported endpoint, please contact support@dagshub.com'}
[2025-07-30 10:13:57,970: INFO: main]: >>>>>> stage Data Ingestion stage started <<<<<<
[2025-07-30 10:13:57,975: INFO: common]: yaml file: config/config.yaml loaded successfully
[2025-07-30 10:13:57,976: INFO: common]: yaml file: params.yaml loaded successfully
[2025-07-30 10:13:57,977: INFO: common]: yaml file: schema.yaml loaded successfully
[2025-07-30 10:13:57,977: INFO: common]: created directory at: artifacts
[2025-07-30 10:13:57,977: INFO: common]: created directory at: artifacts/data_ingestion
[2025-07-30 10:13:57,977: INFO: data_ingestion]: File already exists of size: 23329
[2025-07-30 10:13:57,978: INFO: main]: >>>>>> stage Data Ingestion stage completed <<<<<<

x==========x
[2025-07-30 10:13:57,978: INFO: main]: >>>>>> stage Data Validation stage started <<<<<<
[2025-07-30 10:13:57,980: INFO: common]: yaml file: config/config.yaml loaded successfully
[2025-07-30 10:13:57,980: INFO: common]: yaml file: params.yaml loaded successfully
[2025-07-30 10:13:57,981: INFO: common]: yaml file: schema.yaml loaded successfully
[2025-07-30 10:13:57,981: INFO: common]: created directory at: artifacts
[2025-07-30 10:13:57,981: INFO: common]: created directory at: artifacts/data_validation
[2025-07-30 10:13:57,987: INFO: data_validation]: Data validation status: True
[2025-07-30 10:13:57,987: INFO: main]: >>>>>> stage Data Validation stage completed <<<<<<

x==========x
[2025-07-30 10:13:57,987: INFO: main]: >>>>>> stage Data Transformation stage started <<<<<<
[2025-07-30 10:13:57,988: INFO: common]: yaml file: config/config.yaml loaded successfully
[2025-07-30 10:13:57,988: INFO: common]: yaml file: params.yaml loaded successfully
[2025-07-30 10:13:57,989: INFO: common]: yaml file: schema.yaml loaded successfully
[2025-07-30 10:13:57,989: INFO: common]: created directory at: artifacts
[2025-07-30 10:13:57,989: INFO: common]: created directory at: artifacts/data_validation
[2025-07-30 10:13:57,989: INFO: common]: created directory at: artifacts/data_transformation
[2025-07-30 10:13:57,999: INFO: data_transformation]: Splited data into training and test sets
[2025-07-30 10:13:57,999: INFO: data_transformation]: (1279, 12)
[2025-07-30 10:13:57,999: INFO: data_transformation]: (320, 12)
[2025-07-30 10:13:57,999: INFO: main]: >>>>>> stage Data Transformation stage completed <<<<<<

x==========x
[2025-07-30 10:13:57,999: INFO: main]: >>>>>> stage Model Trainer stage started <<<<<<
[2025-07-30 10:13:58,000: INFO: common]: yaml file: config/config.yaml loaded successfully
[2025-07-30 10:13:58,001: INFO: common]: yaml file: params.yaml loaded successfully
[2025-07-30 10:13:58,001: INFO: common]: yaml file: schema.yaml loaded successfully
[2025-07-30 10:13:58,001: INFO: common]: created directory at: artifacts
[2025-07-30 10:13:58,001: INFO: common]: created directory at: artifacts/model_trainer
[2025-07-30 10:13:58,007: INFO: model_trainer]: Model saved to model.joblib in artifacts/model_trainer
[2025-07-30 10:13:58,007: INFO: main]: >>>>>> stage Model Trainer stage completed <<<<<<

x==========x
[2025-07-30 10:13:58,007: INFO: main]: >>>>>> stage Model Evaluation stage started <<<<<<
[2025-07-30 10:13:58,008: INFO: common]: yaml file: config/config.yaml loaded successfully
[2025-07-30 10:13:58,008: INFO: common]: yaml file: params.yaml loaded successfully
[2025-07-30 10:13:58,009: INFO: common]: yaml file: schema.yaml loaded successfully
[2025-07-30 10:13:58,009: INFO: common]: created directory at: artifacts
[2025-07-30 10:13:58,009: INFO: common]: created directory at: artifacts/model_evaluation
[2025-07-30 10:13:58,760: INFO: common]: json file saved at: artifacts/model_evaluation/metrics.json
[2025-07-30 10:13:58,760: INFO: model_evaluation]: Metrics saved to artifacts/model_evaluation/metrics.json
[2025-07-30 10:14:04,072: ERROR: main]: INTERNAL_ERROR: Response: {'error': 'unsupported endpoint, please contact support@dagshub.com'}
Traceback (most recent call last):
  File "/Users/saiaakash/Documents/mlops/DS_main/main.py", line 15, in run_stage
    pipeline.main()
  File "/Users/saiaakash/Documents/mlops/DS_main/src/data_science/pipeline/stage_05_model_evaluation.py", line 15, in main
    model_evaluation.log_into_mlflow() # This method handles the full evaluation and logging process
  File "/Users/saiaakash/Documents/mlops/DS_main/src/data_science/components/model_evaluation.py", line 62, in log_into_mlflow
    mlflow.sklearn.log_model(
  File "/opt/anaconda3/envs/mlpipe/lib/python3.10/site-packages/mlflow/sklearn/__init__.py", line 426, in log_model
    return Model.log(
  File "/opt/anaconda3/envs/mlpipe/lib/python3.10/site-packages/mlflow/models/model.py", line 1161, in log
    model = mlflow.initialize_logged_model(
  File "/opt/anaconda3/envs/mlpipe/lib/python3.10/site-packages/mlflow/tracking/fluent.py", line 2130, in initialize_logged_model
    model = _create_logged_model(
  File "/opt/anaconda3/envs/mlpipe/lib/python3.10/site-packages/mlflow/tracking/fluent.py", line 2257, in _create_logged_model
    return MlflowClient().create_logged_model(
  File "/opt/anaconda3/envs/mlpipe/lib/python3.10/site-packages/mlflow/tracking/client.py", line 5369, in create_logged_model
    return self._tracking_client.create_logged_model(
  File "/opt/anaconda3/envs/mlpipe/lib/python3.10/site-packages/mlflow/tracking/_tracking_service/client.py", line 824, in create_logged_model
    return self.store.create_logged_model(
  File "/opt/anaconda3/envs/mlpipe/lib/python3.10/site-packages/mlflow/store/tracking/rest_store.py", line 936, in create_logged_model
    response_proto = self._call_endpoint(CreateLoggedModel, req_body)
  File "/opt/anaconda3/envs/mlpipe/lib/python3.10/site-packages/mlflow/store/tracking/rest_store.py", line 135, in _call_endpoint
    return call_endpoint(
  File "/opt/anaconda3/envs/mlpipe/lib/python3.10/site-packages/mlflow/utils/rest_utils.py", line 594, in call_endpoint
    response = verify_rest_response(response, endpoint)
  File "/opt/anaconda3/envs/mlpipe/lib/python3.10/site-packages/mlflow/utils/rest_utils.py", line 308, in verify_rest_response
    raise RestException(json.loads(response.text))
mlflow.exceptions.RestException: INTERNAL_ERROR: Response: {'error': 'unsupported endpoint, please contact support@dagshub.com'}
[2025-07-30 10:15:33,700: INFO: main]: >>>>>> stage Data Ingestion stage started <<<<<<
[2025-07-30 10:15:33,704: INFO: common]: yaml file: config/config.yaml loaded successfully
[2025-07-30 10:15:33,706: INFO: common]: yaml file: params.yaml loaded successfully
[2025-07-30 10:15:33,707: INFO: common]: yaml file: schema.yaml loaded successfully
[2025-07-30 10:15:33,707: INFO: common]: created directory at: artifacts
[2025-07-30 10:15:33,707: INFO: common]: created directory at: artifacts/data_ingestion
[2025-07-30 10:15:33,707: INFO: data_ingestion]: File already exists of size: 23329
[2025-07-30 10:15:33,708: INFO: main]: >>>>>> stage Data Ingestion stage completed <<<<<<

x==========x
[2025-07-30 10:15:33,708: INFO: main]: >>>>>> stage Data Validation stage started <<<<<<
[2025-07-30 10:15:33,710: INFO: common]: yaml file: config/config.yaml loaded successfully
[2025-07-30 10:15:33,710: INFO: common]: yaml file: params.yaml loaded successfully
[2025-07-30 10:15:33,711: INFO: common]: yaml file: schema.yaml loaded successfully
[2025-07-30 10:15:33,711: INFO: common]: created directory at: artifacts
[2025-07-30 10:15:33,711: INFO: common]: created directory at: artifacts/data_validation
[2025-07-30 10:15:33,715: INFO: data_validation]: Data validation status: True
[2025-07-30 10:15:33,716: INFO: main]: >>>>>> stage Data Validation stage completed <<<<<<

x==========x
[2025-07-30 10:15:33,716: INFO: main]: >>>>>> stage Data Transformation stage started <<<<<<
[2025-07-30 10:15:33,717: INFO: common]: yaml file: config/config.yaml loaded successfully
[2025-07-30 10:15:33,717: INFO: common]: yaml file: params.yaml loaded successfully
[2025-07-30 10:15:33,718: INFO: common]: yaml file: schema.yaml loaded successfully
[2025-07-30 10:15:33,718: INFO: common]: created directory at: artifacts
[2025-07-30 10:15:33,718: INFO: common]: created directory at: artifacts/data_validation
[2025-07-30 10:15:33,718: INFO: common]: created directory at: artifacts/data_transformation
[2025-07-30 10:15:33,729: INFO: data_transformation]: Splited data into training and test sets
[2025-07-30 10:15:33,729: INFO: data_transformation]: (1279, 12)
[2025-07-30 10:15:33,729: INFO: data_transformation]: (320, 12)
[2025-07-30 10:15:33,729: INFO: main]: >>>>>> stage Data Transformation stage completed <<<<<<

x==========x
[2025-07-30 10:15:33,729: INFO: main]: >>>>>> stage Model Trainer stage started <<<<<<
[2025-07-30 10:15:33,730: INFO: common]: yaml file: config/config.yaml loaded successfully
[2025-07-30 10:15:33,730: INFO: common]: yaml file: params.yaml loaded successfully
[2025-07-30 10:15:33,731: INFO: common]: yaml file: schema.yaml loaded successfully
[2025-07-30 10:15:33,731: INFO: common]: created directory at: artifacts
[2025-07-30 10:15:33,731: INFO: common]: created directory at: artifacts/model_trainer
[2025-07-30 10:15:33,735: INFO: model_trainer]: Model saved to model.joblib in artifacts/model_trainer
[2025-07-30 10:15:33,735: INFO: main]: >>>>>> stage Model Trainer stage completed <<<<<<

x==========x
[2025-07-30 10:15:33,735: INFO: main]: >>>>>> stage Model Evaluation stage started <<<<<<
[2025-07-30 10:15:33,737: INFO: common]: yaml file: config/config.yaml loaded successfully
[2025-07-30 10:15:33,737: INFO: common]: yaml file: params.yaml loaded successfully
[2025-07-30 10:15:33,738: INFO: common]: yaml file: schema.yaml loaded successfully
[2025-07-30 10:15:33,738: INFO: common]: created directory at: artifacts
[2025-07-30 10:15:33,739: INFO: common]: created directory at: artifacts/model_evaluation
[2025-07-30 10:15:34,463: ERROR: main]: API request to endpoint /api/2.0/mlflow/runs/create failed with error code 401 != 200. Response body: '=============== ATTENTION! ===============

To use authentication, you must first: 
    Get your default access token from: https://dagshub.com/user/settings/tokens
    OR 
    Set a password: https://dagshub.com/user/settings/password 
=========================================='
Traceback (most recent call last):
  File "/Users/saiaakash/Documents/mlops/DS_main/main.py", line 15, in run_stage
    pipeline.main()
  File "/Users/saiaakash/Documents/mlops/DS_main/src/data_science/pipeline/stage_05_model_evaluation.py", line 15, in main
    model_evaluation.log_into_mlflow() # This method handles the full evaluation and logging process
  File "/Users/saiaakash/Documents/mlops/DS_main/src/data_science/components/model_evaluation.py", line 40, in log_into_mlflow
    with mlflow.start_run():
  File "/opt/anaconda3/envs/mlpipe/lib/python3.10/site-packages/mlflow/tracking/fluent.py", line 474, in start_run
    active_run_obj = client.create_run(
  File "/opt/anaconda3/envs/mlpipe/lib/python3.10/site-packages/mlflow/tracking/client.py", line 435, in create_run
    return self._tracking_client.create_run(experiment_id, start_time, tags, run_name)
  File "/opt/anaconda3/envs/mlpipe/lib/python3.10/site-packages/mlflow/tracking/_tracking_service/client.py", line 161, in create_run
    return self.store.create_run(
  File "/opt/anaconda3/envs/mlpipe/lib/python3.10/site-packages/mlflow/store/tracking/rest_store.py", line 272, in create_run
    response_proto = self._call_endpoint(CreateRun, req_body)
  File "/opt/anaconda3/envs/mlpipe/lib/python3.10/site-packages/mlflow/store/tracking/rest_store.py", line 135, in _call_endpoint
    return call_endpoint(
  File "/opt/anaconda3/envs/mlpipe/lib/python3.10/site-packages/mlflow/utils/rest_utils.py", line 594, in call_endpoint
    response = verify_rest_response(response, endpoint)
  File "/opt/anaconda3/envs/mlpipe/lib/python3.10/site-packages/mlflow/utils/rest_utils.py", line 314, in verify_rest_response
    raise MlflowException(
mlflow.exceptions.MlflowException: API request to endpoint /api/2.0/mlflow/runs/create failed with error code 401 != 200. Response body: '=============== ATTENTION! ===============

To use authentication, you must first: 
    Get your default access token from: https://dagshub.com/user/settings/tokens
    OR 
    Set a password: https://dagshub.com/user/settings/password 
=========================================='
[2025-07-30 10:16:04,143: INFO: main]: >>>>>> stage Data Ingestion stage started <<<<<<
[2025-07-30 10:16:04,145: INFO: common]: yaml file: config/config.yaml loaded successfully
[2025-07-30 10:16:04,147: INFO: common]: yaml file: params.yaml loaded successfully
[2025-07-30 10:16:04,148: INFO: common]: yaml file: schema.yaml loaded successfully
[2025-07-30 10:16:04,148: INFO: common]: created directory at: artifacts
[2025-07-30 10:16:04,148: INFO: common]: created directory at: artifacts/data_ingestion
[2025-07-30 10:16:04,148: INFO: data_ingestion]: File already exists of size: 23329
[2025-07-30 10:16:04,149: INFO: main]: >>>>>> stage Data Ingestion stage completed <<<<<<

x==========x
[2025-07-30 10:16:04,149: INFO: main]: >>>>>> stage Data Validation stage started <<<<<<
[2025-07-30 10:16:04,151: INFO: common]: yaml file: config/config.yaml loaded successfully
[2025-07-30 10:16:04,151: INFO: common]: yaml file: params.yaml loaded successfully
[2025-07-30 10:16:04,152: INFO: common]: yaml file: schema.yaml loaded successfully
[2025-07-30 10:16:04,152: INFO: common]: created directory at: artifacts
[2025-07-30 10:16:04,152: INFO: common]: created directory at: artifacts/data_validation
[2025-07-30 10:16:04,158: INFO: data_validation]: Data validation status: True
[2025-07-30 10:16:04,158: INFO: main]: >>>>>> stage Data Validation stage completed <<<<<<

x==========x
[2025-07-30 10:16:04,158: INFO: main]: >>>>>> stage Data Transformation stage started <<<<<<
[2025-07-30 10:16:04,159: INFO: common]: yaml file: config/config.yaml loaded successfully
[2025-07-30 10:16:04,159: INFO: common]: yaml file: params.yaml loaded successfully
[2025-07-30 10:16:04,160: INFO: common]: yaml file: schema.yaml loaded successfully
[2025-07-30 10:16:04,160: INFO: common]: created directory at: artifacts
[2025-07-30 10:16:04,160: INFO: common]: created directory at: artifacts/data_validation
[2025-07-30 10:16:04,160: INFO: common]: created directory at: artifacts/data_transformation
[2025-07-30 10:16:04,171: INFO: data_transformation]: Splited data into training and test sets
[2025-07-30 10:16:04,171: INFO: data_transformation]: (1279, 12)
[2025-07-30 10:16:04,171: INFO: data_transformation]: (320, 12)
[2025-07-30 10:16:04,171: INFO: main]: >>>>>> stage Data Transformation stage completed <<<<<<

x==========x
[2025-07-30 10:16:04,171: INFO: main]: >>>>>> stage Model Trainer stage started <<<<<<
[2025-07-30 10:16:04,172: INFO: common]: yaml file: config/config.yaml loaded successfully
[2025-07-30 10:16:04,173: INFO: common]: yaml file: params.yaml loaded successfully
[2025-07-30 10:16:04,173: INFO: common]: yaml file: schema.yaml loaded successfully
[2025-07-30 10:16:04,174: INFO: common]: created directory at: artifacts
[2025-07-30 10:16:04,174: INFO: common]: created directory at: artifacts/model_trainer
[2025-07-30 10:16:04,181: INFO: model_trainer]: Model saved to model.joblib in artifacts/model_trainer
[2025-07-30 10:16:04,181: INFO: main]: >>>>>> stage Model Trainer stage completed <<<<<<

x==========x
[2025-07-30 10:16:04,181: INFO: main]: >>>>>> stage Model Evaluation stage started <<<<<<
[2025-07-30 10:16:04,182: INFO: common]: yaml file: config/config.yaml loaded successfully
[2025-07-30 10:16:04,182: INFO: common]: yaml file: params.yaml loaded successfully
[2025-07-30 10:16:04,183: INFO: common]: yaml file: schema.yaml loaded successfully
[2025-07-30 10:16:04,183: INFO: common]: created directory at: artifacts
[2025-07-30 10:16:04,183: INFO: common]: created directory at: artifacts/model_evaluation
[2025-07-30 10:16:04,875: INFO: common]: json file saved at: artifacts/model_evaluation/metrics.json
[2025-07-30 10:16:09,968: ERROR: main]: INTERNAL_ERROR: Response: {'error': 'unsupported endpoint, please contact support@dagshub.com'}
Traceback (most recent call last):
  File "/Users/saiaakash/Documents/mlops/DS_main/main.py", line 15, in run_stage
    pipeline.main()
  File "/Users/saiaakash/Documents/mlops/DS_main/src/data_science/pipeline/stage_05_model_evaluation.py", line 15, in main
    model_evaluation.log_into_mlflow() # This method handles the full evaluation and logging process
  File "/Users/saiaakash/Documents/mlops/DS_main/src/data_science/components/model_evaluation.py", line 52, in log_into_mlflow
    mlflow.sklearn.log_model(
  File "/opt/anaconda3/envs/mlpipe/lib/python3.10/site-packages/mlflow/sklearn/__init__.py", line 426, in log_model
    return Model.log(
  File "/opt/anaconda3/envs/mlpipe/lib/python3.10/site-packages/mlflow/models/model.py", line 1161, in log
    model = mlflow.initialize_logged_model(
  File "/opt/anaconda3/envs/mlpipe/lib/python3.10/site-packages/mlflow/tracking/fluent.py", line 2130, in initialize_logged_model
    model = _create_logged_model(
  File "/opt/anaconda3/envs/mlpipe/lib/python3.10/site-packages/mlflow/tracking/fluent.py", line 2257, in _create_logged_model
    return MlflowClient().create_logged_model(
  File "/opt/anaconda3/envs/mlpipe/lib/python3.10/site-packages/mlflow/tracking/client.py", line 5369, in create_logged_model
    return self._tracking_client.create_logged_model(
  File "/opt/anaconda3/envs/mlpipe/lib/python3.10/site-packages/mlflow/tracking/_tracking_service/client.py", line 824, in create_logged_model
    return self.store.create_logged_model(
  File "/opt/anaconda3/envs/mlpipe/lib/python3.10/site-packages/mlflow/store/tracking/rest_store.py", line 936, in create_logged_model
    response_proto = self._call_endpoint(CreateLoggedModel, req_body)
  File "/opt/anaconda3/envs/mlpipe/lib/python3.10/site-packages/mlflow/store/tracking/rest_store.py", line 135, in _call_endpoint
    return call_endpoint(
  File "/opt/anaconda3/envs/mlpipe/lib/python3.10/site-packages/mlflow/utils/rest_utils.py", line 594, in call_endpoint
    response = verify_rest_response(response, endpoint)
  File "/opt/anaconda3/envs/mlpipe/lib/python3.10/site-packages/mlflow/utils/rest_utils.py", line 308, in verify_rest_response
    raise RestException(json.loads(response.text))
mlflow.exceptions.RestException: INTERNAL_ERROR: Response: {'error': 'unsupported endpoint, please contact support@dagshub.com'}
[2025-07-30 10:19:37,020: INFO: main]: >>>>>> stage Data Ingestion stage started <<<<<<
[2025-07-30 10:19:37,024: INFO: common]: yaml file: config/config.yaml loaded successfully
[2025-07-30 10:19:37,025: INFO: common]: yaml file: params.yaml loaded successfully
[2025-07-30 10:19:37,026: INFO: common]: yaml file: schema.yaml loaded successfully
[2025-07-30 10:19:37,027: INFO: common]: created directory at: artifacts
[2025-07-30 10:19:37,027: INFO: common]: created directory at: artifacts/data_ingestion
[2025-07-30 10:19:37,027: INFO: data_ingestion]: File already exists of size: 23329
[2025-07-30 10:19:37,028: INFO: main]: >>>>>> stage Data Ingestion stage completed <<<<<<

x==========x
[2025-07-30 10:19:37,028: INFO: main]: >>>>>> stage Data Validation stage started <<<<<<
[2025-07-30 10:19:37,030: INFO: common]: yaml file: config/config.yaml loaded successfully
[2025-07-30 10:19:37,030: INFO: common]: yaml file: params.yaml loaded successfully
[2025-07-30 10:19:37,031: INFO: common]: yaml file: schema.yaml loaded successfully
[2025-07-30 10:19:37,031: INFO: common]: created directory at: artifacts
[2025-07-30 10:19:37,031: INFO: common]: created directory at: artifacts/data_validation
[2025-07-30 10:19:37,036: INFO: data_validation]: Data validation status: True
[2025-07-30 10:19:37,036: INFO: main]: >>>>>> stage Data Validation stage completed <<<<<<

x==========x
[2025-07-30 10:19:37,036: INFO: main]: >>>>>> stage Data Transformation stage started <<<<<<
[2025-07-30 10:19:37,038: INFO: common]: yaml file: config/config.yaml loaded successfully
[2025-07-30 10:19:37,038: INFO: common]: yaml file: params.yaml loaded successfully
[2025-07-30 10:19:37,039: INFO: common]: yaml file: schema.yaml loaded successfully
[2025-07-30 10:19:37,039: INFO: common]: created directory at: artifacts
[2025-07-30 10:19:37,039: INFO: common]: created directory at: artifacts/data_validation
[2025-07-30 10:19:37,039: INFO: common]: created directory at: artifacts/data_transformation
[2025-07-30 10:19:37,051: INFO: data_transformation]: Splited data into training and test sets
[2025-07-30 10:19:37,051: INFO: data_transformation]: (1279, 12)
[2025-07-30 10:19:37,051: INFO: data_transformation]: (320, 12)
[2025-07-30 10:19:37,051: INFO: main]: >>>>>> stage Data Transformation stage completed <<<<<<

x==========x
[2025-07-30 10:19:37,051: INFO: main]: >>>>>> stage Model Trainer stage started <<<<<<
[2025-07-30 10:19:37,053: INFO: common]: yaml file: config/config.yaml loaded successfully
[2025-07-30 10:19:37,053: INFO: common]: yaml file: params.yaml loaded successfully
[2025-07-30 10:19:37,054: INFO: common]: yaml file: schema.yaml loaded successfully
[2025-07-30 10:19:37,054: INFO: common]: created directory at: artifacts
[2025-07-30 10:19:37,054: INFO: common]: created directory at: artifacts/model_trainer
[2025-07-30 10:19:37,063: INFO: model_trainer]: Model saved to model.joblib in artifacts/model_trainer
[2025-07-30 10:19:37,063: INFO: main]: >>>>>> stage Model Trainer stage completed <<<<<<

x==========x
[2025-07-30 10:19:37,063: INFO: main]: >>>>>> stage Model Evaluation stage started <<<<<<
[2025-07-30 10:19:37,065: INFO: common]: yaml file: config/config.yaml loaded successfully
[2025-07-30 10:19:37,065: INFO: common]: yaml file: params.yaml loaded successfully
[2025-07-30 10:19:37,066: INFO: common]: yaml file: schema.yaml loaded successfully
[2025-07-30 10:19:37,066: INFO: common]: created directory at: artifacts
[2025-07-30 10:19:37,066: INFO: common]: created directory at: artifacts/model_evaluation
[2025-07-30 10:19:37,819: INFO: common]: json file saved at: artifacts/model_evaluation/metrics.json
[2025-07-30 10:19:43,526: ERROR: main]: INTERNAL_ERROR: Response: {'error': 'unsupported endpoint, please contact support@dagshub.com'}
Traceback (most recent call last):
  File "/Users/saiaakash/Documents/mlops/DS_main/main.py", line 15, in run_stage
    pipeline.main()
  File "/Users/saiaakash/Documents/mlops/DS_main/src/data_science/pipeline/stage_05_model_evaluation.py", line 15, in main
    model_evaluation.log_into_mlflow() # This method handles the full evaluation and logging process
  File "/Users/saiaakash/Documents/mlops/DS_main/src/data_science/components/model_evaluation.py", line 53, in log_into_mlflow
    mlflow.sklearn.log_model(
  File "/opt/anaconda3/envs/mlpipe/lib/python3.10/site-packages/mlflow/sklearn/__init__.py", line 426, in log_model
    return Model.log(
  File "/opt/anaconda3/envs/mlpipe/lib/python3.10/site-packages/mlflow/models/model.py", line 1161, in log
    model = mlflow.initialize_logged_model(
  File "/opt/anaconda3/envs/mlpipe/lib/python3.10/site-packages/mlflow/tracking/fluent.py", line 2130, in initialize_logged_model
    model = _create_logged_model(
  File "/opt/anaconda3/envs/mlpipe/lib/python3.10/site-packages/mlflow/tracking/fluent.py", line 2257, in _create_logged_model
    return MlflowClient().create_logged_model(
  File "/opt/anaconda3/envs/mlpipe/lib/python3.10/site-packages/mlflow/tracking/client.py", line 5369, in create_logged_model
    return self._tracking_client.create_logged_model(
  File "/opt/anaconda3/envs/mlpipe/lib/python3.10/site-packages/mlflow/tracking/_tracking_service/client.py", line 824, in create_logged_model
    return self.store.create_logged_model(
  File "/opt/anaconda3/envs/mlpipe/lib/python3.10/site-packages/mlflow/store/tracking/rest_store.py", line 936, in create_logged_model
    response_proto = self._call_endpoint(CreateLoggedModel, req_body)
  File "/opt/anaconda3/envs/mlpipe/lib/python3.10/site-packages/mlflow/store/tracking/rest_store.py", line 135, in _call_endpoint
    return call_endpoint(
  File "/opt/anaconda3/envs/mlpipe/lib/python3.10/site-packages/mlflow/utils/rest_utils.py", line 594, in call_endpoint
    response = verify_rest_response(response, endpoint)
  File "/opt/anaconda3/envs/mlpipe/lib/python3.10/site-packages/mlflow/utils/rest_utils.py", line 308, in verify_rest_response
    raise RestException(json.loads(response.text))
mlflow.exceptions.RestException: INTERNAL_ERROR: Response: {'error': 'unsupported endpoint, please contact support@dagshub.com'}
[2025-07-30 10:20:52,933: INFO: main]: >>>>>> stage Data Ingestion stage started <<<<<<
[2025-07-30 10:20:52,939: INFO: common]: yaml file: config/config.yaml loaded successfully
[2025-07-30 10:20:52,940: INFO: common]: yaml file: params.yaml loaded successfully
[2025-07-30 10:20:52,941: INFO: common]: yaml file: schema.yaml loaded successfully
[2025-07-30 10:20:52,942: INFO: common]: created directory at: artifacts
[2025-07-30 10:20:52,942: INFO: common]: created directory at: artifacts/data_ingestion
[2025-07-30 10:20:52,942: INFO: data_ingestion]: File already exists of size: 23329
[2025-07-30 10:20:52,943: INFO: main]: >>>>>> stage Data Ingestion stage completed <<<<<<

x==========x
[2025-07-30 10:20:52,943: INFO: main]: >>>>>> stage Data Validation stage started <<<<<<
[2025-07-30 10:20:52,944: INFO: common]: yaml file: config/config.yaml loaded successfully
[2025-07-30 10:20:52,945: INFO: common]: yaml file: params.yaml loaded successfully
[2025-07-30 10:20:52,946: INFO: common]: yaml file: schema.yaml loaded successfully
[2025-07-30 10:20:52,946: INFO: common]: created directory at: artifacts
[2025-07-30 10:20:52,946: INFO: common]: created directory at: artifacts/data_validation
[2025-07-30 10:20:52,951: INFO: data_validation]: Data validation status: True
[2025-07-30 10:20:52,951: INFO: main]: >>>>>> stage Data Validation stage completed <<<<<<

x==========x
[2025-07-30 10:20:52,951: INFO: main]: >>>>>> stage Data Transformation stage started <<<<<<
[2025-07-30 10:20:52,952: INFO: common]: yaml file: config/config.yaml loaded successfully
[2025-07-30 10:20:52,953: INFO: common]: yaml file: params.yaml loaded successfully
[2025-07-30 10:20:52,953: INFO: common]: yaml file: schema.yaml loaded successfully
[2025-07-30 10:20:52,954: INFO: common]: created directory at: artifacts
[2025-07-30 10:20:52,954: INFO: common]: created directory at: artifacts/data_validation
[2025-07-30 10:20:52,954: INFO: common]: created directory at: artifacts/data_transformation
[2025-07-30 10:20:52,963: INFO: data_transformation]: Splited data into training and test sets
[2025-07-30 10:20:52,963: INFO: data_transformation]: (1279, 12)
[2025-07-30 10:20:52,963: INFO: data_transformation]: (320, 12)
[2025-07-30 10:20:52,963: INFO: main]: >>>>>> stage Data Transformation stage completed <<<<<<

x==========x
[2025-07-30 10:20:52,963: INFO: main]: >>>>>> stage Model Trainer stage started <<<<<<
[2025-07-30 10:20:52,965: INFO: common]: yaml file: config/config.yaml loaded successfully
[2025-07-30 10:20:52,965: INFO: common]: yaml file: params.yaml loaded successfully
[2025-07-30 10:20:52,966: INFO: common]: yaml file: schema.yaml loaded successfully
[2025-07-30 10:20:52,966: INFO: common]: created directory at: artifacts
[2025-07-30 10:20:52,966: INFO: common]: created directory at: artifacts/model_trainer
[2025-07-30 10:20:52,972: INFO: model_trainer]: Model saved to model.joblib in artifacts/model_trainer
[2025-07-30 10:20:52,972: INFO: main]: >>>>>> stage Model Trainer stage completed <<<<<<

x==========x
[2025-07-30 10:20:52,972: INFO: main]: >>>>>> stage Model Evaluation stage started <<<<<<
[2025-07-30 10:20:52,973: INFO: common]: yaml file: config/config.yaml loaded successfully
[2025-07-30 10:20:52,974: INFO: common]: yaml file: params.yaml loaded successfully
[2025-07-30 10:20:52,975: INFO: common]: yaml file: schema.yaml loaded successfully
[2025-07-30 10:20:52,975: INFO: common]: created directory at: artifacts
[2025-07-30 10:20:52,975: INFO: common]: created directory at: artifacts/model_evaluation
[2025-07-30 10:20:53,748: INFO: common]: json file saved at: artifacts/model_evaluation/metrics.json
[2025-07-30 10:20:58,346: INFO: model_evaluation]: Model logged as artifact successfully.
[2025-07-30 10:20:58,349: INFO: common]: json file saved at: model_info.json
[2025-07-30 10:20:58,853: INFO: model_evaluation]: Model evaluation and logging completed successfully.
[2025-07-30 10:20:59,582: INFO: main]: >>>>>> stage Model Evaluation stage completed <<<<<<

x==========x
[2025-07-30 10:26:23,663: INFO: main]: >>>>>> stage Data Ingestion stage started <<<<<<
[2025-07-30 10:26:23,666: INFO: common]: yaml file: config/config.yaml loaded successfully
[2025-07-30 10:26:23,667: INFO: common]: yaml file: params.yaml loaded successfully
[2025-07-30 10:26:23,668: INFO: common]: yaml file: schema.yaml loaded successfully
[2025-07-30 10:26:23,668: INFO: common]: created directory at: artifacts
[2025-07-30 10:26:23,668: INFO: common]: created directory at: artifacts/data_ingestion
[2025-07-30 10:26:23,668: INFO: data_ingestion]: File already exists of size: 23329
[2025-07-30 10:26:23,670: INFO: main]: >>>>>> stage Data Ingestion stage completed <<<<<<

x==========x
[2025-07-30 10:26:23,670: INFO: main]: >>>>>> stage Data Validation stage started <<<<<<
[2025-07-30 10:26:23,671: INFO: common]: yaml file: config/config.yaml loaded successfully
[2025-07-30 10:26:23,672: INFO: common]: yaml file: params.yaml loaded successfully
[2025-07-30 10:26:23,673: INFO: common]: yaml file: schema.yaml loaded successfully
[2025-07-30 10:26:23,674: INFO: common]: created directory at: artifacts
[2025-07-30 10:26:23,674: INFO: common]: created directory at: artifacts/data_validation
[2025-07-30 10:26:23,679: INFO: data_validation]: Data validation status: True
[2025-07-30 10:26:23,679: INFO: main]: >>>>>> stage Data Validation stage completed <<<<<<

x==========x
[2025-07-30 10:26:23,680: INFO: main]: >>>>>> stage Data Transformation stage started <<<<<<
[2025-07-30 10:26:23,681: INFO: common]: yaml file: config/config.yaml loaded successfully
[2025-07-30 10:26:23,681: INFO: common]: yaml file: params.yaml loaded successfully
[2025-07-30 10:26:23,682: INFO: common]: yaml file: schema.yaml loaded successfully
[2025-07-30 10:26:23,682: INFO: common]: created directory at: artifacts
[2025-07-30 10:26:23,682: INFO: common]: created directory at: artifacts/data_validation
[2025-07-30 10:26:23,682: INFO: common]: created directory at: artifacts/data_transformation
[2025-07-30 10:26:23,693: INFO: data_transformation]: Splited data into training and test sets
[2025-07-30 10:26:23,693: INFO: data_transformation]: (1279, 12)
[2025-07-30 10:26:23,693: INFO: data_transformation]: (320, 12)
[2025-07-30 10:26:23,693: INFO: main]: >>>>>> stage Data Transformation stage completed <<<<<<

x==========x
[2025-07-30 10:26:23,693: INFO: main]: >>>>>> stage Model Trainer stage started <<<<<<
[2025-07-30 10:26:23,695: INFO: common]: yaml file: config/config.yaml loaded successfully
[2025-07-30 10:26:23,695: INFO: common]: yaml file: params.yaml loaded successfully
[2025-07-30 10:26:23,696: INFO: common]: yaml file: schema.yaml loaded successfully
[2025-07-30 10:26:23,696: INFO: common]: created directory at: artifacts
[2025-07-30 10:26:23,696: INFO: common]: created directory at: artifacts/model_trainer
[2025-07-30 10:26:23,703: INFO: model_trainer]: Model saved to model.joblib in artifacts/model_trainer
[2025-07-30 10:26:23,703: INFO: main]: >>>>>> stage Model Trainer stage completed <<<<<<

x==========x
[2025-07-30 10:26:23,703: INFO: main]: >>>>>> stage Model Evaluation stage started <<<<<<
[2025-07-30 10:26:23,704: INFO: common]: yaml file: config/config.yaml loaded successfully
[2025-07-30 10:26:23,704: INFO: common]: yaml file: params.yaml loaded successfully
[2025-07-30 10:26:23,705: INFO: common]: yaml file: schema.yaml loaded successfully
[2025-07-30 10:26:23,705: INFO: common]: created directory at: artifacts
[2025-07-30 10:26:23,705: INFO: common]: created directory at: artifacts/model_evaluation
[2025-07-30 10:26:24,433: INFO: common]: json file saved at: artifacts/model_evaluation/metrics.json
[2025-07-30 10:26:28,715: INFO: model_evaluation]: Model logged as artifact successfully.
[2025-07-30 10:26:28,716: INFO: common]: json file saved at: model_info.json
[2025-07-30 10:26:29,181: INFO: model_evaluation]: Model evaluation and logging completed successfully.
[2025-07-30 10:26:29,849: INFO: main]: >>>>>> stage Model Evaluation stage completed <<<<<<

x==========x
[2025-07-30 10:26:51,412: INFO: main]: >>>>>> stage Data Ingestion stage started <<<<<<
[2025-07-30 10:26:51,415: INFO: common]: yaml file: config/config.yaml loaded successfully
[2025-07-30 10:26:51,416: INFO: common]: yaml file: params.yaml loaded successfully
[2025-07-30 10:26:51,417: INFO: common]: yaml file: schema.yaml loaded successfully
[2025-07-30 10:26:51,417: INFO: common]: created directory at: artifacts
[2025-07-30 10:26:51,417: INFO: common]: created directory at: artifacts/data_ingestion
[2025-07-30 10:26:51,417: INFO: data_ingestion]: File already exists of size: 23329
[2025-07-30 10:26:51,419: INFO: main]: >>>>>> stage Data Ingestion stage completed <<<<<<

x==========x
[2025-07-30 10:26:51,419: INFO: main]: >>>>>> stage Data Validation stage started <<<<<<
[2025-07-30 10:26:51,421: INFO: common]: yaml file: config/config.yaml loaded successfully
[2025-07-30 10:26:51,421: INFO: common]: yaml file: params.yaml loaded successfully
[2025-07-30 10:26:51,422: INFO: common]: yaml file: schema.yaml loaded successfully
[2025-07-30 10:26:51,422: INFO: common]: created directory at: artifacts
[2025-07-30 10:26:51,422: INFO: common]: created directory at: artifacts/data_validation
[2025-07-30 10:26:51,427: INFO: data_validation]: Data validation status: True
[2025-07-30 10:26:51,427: INFO: main]: >>>>>> stage Data Validation stage completed <<<<<<

x==========x
[2025-07-30 10:26:51,427: INFO: main]: >>>>>> stage Data Transformation stage started <<<<<<
[2025-07-30 10:26:51,429: INFO: common]: yaml file: config/config.yaml loaded successfully
[2025-07-30 10:26:51,429: INFO: common]: yaml file: params.yaml loaded successfully
[2025-07-30 10:26:51,430: INFO: common]: yaml file: schema.yaml loaded successfully
[2025-07-30 10:26:51,430: INFO: common]: created directory at: artifacts
[2025-07-30 10:26:51,430: INFO: common]: created directory at: artifacts/data_validation
[2025-07-30 10:26:51,430: INFO: common]: created directory at: artifacts/data_transformation
[2025-07-30 10:26:51,441: INFO: data_transformation]: Splited data into training and test sets
[2025-07-30 10:26:51,441: INFO: data_transformation]: (1279, 12)
[2025-07-30 10:26:51,441: INFO: data_transformation]: (320, 12)
[2025-07-30 10:26:51,441: INFO: main]: >>>>>> stage Data Transformation stage completed <<<<<<

x==========x
[2025-07-30 10:26:51,441: INFO: main]: >>>>>> stage Model Trainer stage started <<<<<<
[2025-07-30 10:26:51,442: INFO: common]: yaml file: config/config.yaml loaded successfully
[2025-07-30 10:26:51,443: INFO: common]: yaml file: params.yaml loaded successfully
[2025-07-30 10:26:51,443: INFO: common]: yaml file: schema.yaml loaded successfully
[2025-07-30 10:26:51,444: INFO: common]: created directory at: artifacts
[2025-07-30 10:26:51,444: INFO: common]: created directory at: artifacts/model_trainer
[2025-07-30 10:26:51,450: INFO: model_trainer]: Model saved to model.joblib in artifacts/model_trainer
[2025-07-30 10:26:51,450: INFO: main]: >>>>>> stage Model Trainer stage completed <<<<<<

x==========x
[2025-07-30 10:26:51,450: INFO: main]: >>>>>> stage Model Evaluation stage started <<<<<<
[2025-07-30 10:26:51,452: INFO: common]: yaml file: config/config.yaml loaded successfully
[2025-07-30 10:26:51,452: INFO: common]: yaml file: params.yaml loaded successfully
[2025-07-30 10:26:51,453: INFO: common]: yaml file: schema.yaml loaded successfully
[2025-07-30 10:26:51,453: INFO: common]: created directory at: artifacts
[2025-07-30 10:26:51,453: INFO: common]: created directory at: artifacts/model_evaluation
[2025-07-30 10:26:52,192: INFO: common]: json file saved at: artifacts/model_evaluation/metrics.json
[2025-07-30 10:26:56,780: INFO: model_evaluation]: Model logged as artifact successfully.
[2025-07-30 10:26:56,782: INFO: common]: json file saved at: model_info.json
[2025-07-30 10:26:57,324: INFO: model_evaluation]: Model evaluation and logging completed successfully.
[2025-07-30 10:26:58,069: INFO: main]: >>>>>> stage Model Evaluation stage completed <<<<<<

x==========x
[2025-07-30 10:27:30,058: INFO: main]: >>>>>> stage Data Ingestion stage started <<<<<<
[2025-07-30 10:27:30,060: INFO: common]: yaml file: config/config.yaml loaded successfully
[2025-07-30 10:27:30,061: INFO: common]: yaml file: params.yaml loaded successfully
[2025-07-30 10:27:30,062: INFO: common]: yaml file: schema.yaml loaded successfully
[2025-07-30 10:27:30,062: INFO: common]: created directory at: artifacts
[2025-07-30 10:27:30,062: INFO: common]: created directory at: artifacts/data_ingestion
[2025-07-30 10:27:30,062: INFO: data_ingestion]: File already exists of size: 23329
[2025-07-30 10:27:30,063: INFO: main]: >>>>>> stage Data Ingestion stage completed <<<<<<

x==========x
[2025-07-30 10:27:30,064: INFO: main]: >>>>>> stage Data Validation stage started <<<<<<
[2025-07-30 10:27:30,065: INFO: common]: yaml file: config/config.yaml loaded successfully
[2025-07-30 10:27:30,065: INFO: common]: yaml file: params.yaml loaded successfully
[2025-07-30 10:27:30,066: INFO: common]: yaml file: schema.yaml loaded successfully
[2025-07-30 10:27:30,066: INFO: common]: created directory at: artifacts
[2025-07-30 10:27:30,066: INFO: common]: created directory at: artifacts/data_validation
[2025-07-30 10:27:30,071: INFO: data_validation]: Data validation status: True
[2025-07-30 10:27:30,071: INFO: main]: >>>>>> stage Data Validation stage completed <<<<<<

x==========x
[2025-07-30 10:27:30,071: INFO: main]: >>>>>> stage Data Transformation stage started <<<<<<
[2025-07-30 10:27:30,072: INFO: common]: yaml file: config/config.yaml loaded successfully
[2025-07-30 10:27:30,072: INFO: common]: yaml file: params.yaml loaded successfully
[2025-07-30 10:27:30,073: INFO: common]: yaml file: schema.yaml loaded successfully
[2025-07-30 10:27:30,073: INFO: common]: created directory at: artifacts
[2025-07-30 10:27:30,073: INFO: common]: created directory at: artifacts/data_validation
[2025-07-30 10:27:30,073: INFO: common]: created directory at: artifacts/data_transformation
[2025-07-30 10:27:30,084: INFO: data_transformation]: Splited data into training and test sets
[2025-07-30 10:27:30,084: INFO: data_transformation]: (1279, 12)
[2025-07-30 10:27:30,084: INFO: data_transformation]: (320, 12)
[2025-07-30 10:27:30,084: INFO: main]: >>>>>> stage Data Transformation stage completed <<<<<<

x==========x
[2025-07-30 10:27:30,084: INFO: main]: >>>>>> stage Model Trainer stage started <<<<<<
[2025-07-30 10:27:30,085: INFO: common]: yaml file: config/config.yaml loaded successfully
[2025-07-30 10:27:30,086: INFO: common]: yaml file: params.yaml loaded successfully
[2025-07-30 10:27:30,086: INFO: common]: yaml file: schema.yaml loaded successfully
[2025-07-30 10:27:30,086: INFO: common]: created directory at: artifacts
[2025-07-30 10:27:30,087: INFO: common]: created directory at: artifacts/model_trainer
[2025-07-30 10:27:30,090: INFO: model_trainer]: Model saved to model.joblib in artifacts/model_trainer
[2025-07-30 10:27:30,091: INFO: main]: >>>>>> stage Model Trainer stage completed <<<<<<

x==========x
[2025-07-30 10:27:30,091: INFO: main]: >>>>>> stage Model Evaluation stage started <<<<<<
[2025-07-30 10:27:30,092: INFO: common]: yaml file: config/config.yaml loaded successfully
[2025-07-30 10:27:30,092: INFO: common]: yaml file: params.yaml loaded successfully
[2025-07-30 10:27:30,093: INFO: common]: yaml file: schema.yaml loaded successfully
[2025-07-30 10:27:30,093: INFO: common]: created directory at: artifacts
[2025-07-30 10:27:30,093: INFO: common]: created directory at: artifacts/model_evaluation
[2025-07-30 10:27:30,850: INFO: common]: json file saved at: artifacts/model_evaluation/metrics.json
[2025-07-30 10:27:38,032: INFO: model_evaluation]: Model logged as artifact successfully.
[2025-07-30 10:27:38,035: INFO: common]: json file saved at: model_info.json
[2025-07-30 10:27:38,538: INFO: model_evaluation]: Model evaluation and logging completed successfully.
[2025-07-30 10:27:39,264: INFO: main]: >>>>>> stage Model Evaluation stage completed <<<<<<

x==========x
